Workbook

Sheet Модель
A1: КОНТУР / Мой бизнес
A2: Базовый · KZT · 12 месяцев. Потоки — сумма; остатки — на конец М12.
A3: Чистая прибыль | B3: =N34 -> 6022057.7 | D3: Выручка | E3: =N8 -> 12000000 | G3: Деньги на конец | H3: =M42 -> 5912057.7
A4: Показатель | B4: М1 | C4: М2 | D4: М3 | E4: М4 | F4: М5 | G4: М6 | H4: М7 | I4: М8 | J4: М9 | K4: М10 | L4: М11 | M4: М12 | N4: Год / конец | O4: Как считается
A5: Основной продукт · количество | B5: =IF(AND((1>='Вводные'!$B$35),(1<='Вводные'!$B$36)),(('Вводные'!$B$31*'Вводные'!$B$17)*((1+('Вводные'!$B$33/100))^MAX(0,(1-'Вводные'!$B$35)))),0) -> 300 | C5: =IF(AND((2>='Вводные'!$B$35),(2<='Вводные'!$B$36)),(('Вводные'!$B$31*'Вводные'!$B$17)*((1+('Вводные'!$B$33/100))^MAX(0,(2-'Вводные'!$B$35)))),0) -> 312 | D5: =IF(AND((3>='Вводные'!$B$35),(3<='Вводные'!$B$36)),(('Вводные'!$B$31*'Вводные'!$B$17)*((1+('Вводные'!$B$33/100))^MAX(0,(3-'Вводные'!$B$35)))),0) -> 324.48 | E5: =IF(AND((4>='Вводные'!$B$35),(4<='Вводные'!$B$36)),(('Вводные'!$B$31*'Вводные'!$B$17)*((1+('Вводные'!$B$33/100))^MAX(0,(4-'Вводные'!$B$35)))),0) -> 337.4592 | F5: =IF(AND((5>='Вводные'!$B$35),(5<='Вводные'!$B$36)),(('Вводные'!$B$31*'Вводные'!$B$17)*((1+('Вводные'!$B$33/100))^MAX(0,(5-'Вводные'!$B$35)))),0) -> 350.95757 | G5: =IF(AND((6>='Вводные'!$B$35),(6<='Вводные'!$B$36)),(('Вводные'!$B$31*'Вводные'!$B$17)*((1+('Вводные'!$B$33/100))^MAX(0,(6-'Вводные'!$B$35)))),0) -> 364.99587 | H5: =IF(AND((7>='Вводные'!$B$35),(7<='Вводные'!$B$36)),(('Вводные'!$B$31*'Вводные'!$B$17)*((1+('Вводные'!$B$33/100))^MAX(0,(7-'Вводные'!$B$35)))),0) -> 379.59571 | I5: =IF(AND((8>='Вводные'!$B$35),(8<='Вводные'!$B$36)),(('Вводные'!$B$31*'Вводные'!$B$17)*((1+('Вводные'!$B$33/100))^MAX(0,(8-'Вводные'!$B$35)))),0) -> 394.77953 | J5: =IF(AND((9>='Вводные'!$B$35),(9<='Вводные'!$B$36)),(('Вводные'!$B$31*'Вводные'!$B$17)*((1+('Вводные'!$B$33/100))^MAX(0,(9-'Вводные'!$B$35)))),0) -> 410.57072 | K5: =IF(AND((10>='Вводные'!$B$35),(10<='Вводные'!$B$36)),(('Вводные'!$B$31*'Вводные'!$B$17)*((1+('Вводные'!$B$33/100))^MAX(0,(10-'Вводные'!$B$35)))),0) -> 426.99354 | L5: =IF(AND((11>='Вводные'!$B$35),(11<='Вводные'!$B$36)),(('Вводные'!$B$31*'Вводные'!$B$17)*((1+('Вводные'!$B$33/100))^MAX(0,(11-'Вводные'!$B$35)))),0) -> 444.07329 | M5: =IF(AND((12>='Вводные'!$B$35),(12<='Вводные'!$B$36)),(('Вводные'!$B$31*'Вводные'!$B$17)*((1+('Вводные'!$B$33/100))^MAX(0,(12-'Вводные'!$B$35)))),0) -> 461.83622 | N5: =SUM(B5:M5) -> 4507.7416 | O5: Продажи
A6: Основной продукт · выручка | B6: =(B5*'Вводные'!$B$32) -> 2550000 | C6: =(C5*'Вводные'!$B$32) -> 2652000 | D6: =(D5*'Вводные'!$B$32) -> 2758080 | E6: =(E5*'Вводные'!$B$32) -> 2868403.2 | F6: =(F5*'Вводные'!$B$32) -> 2983139.3 | G6: =(G5*'Вводные'!$B$32) -> 3102464.9 | H6: =(H5*'Вводные'!$B$32) -> 3226563.5 | I6: =(I5*'Вводные'!$B$32) -> 3355626 | ... M6: =(M5*'Вводные'!$B$32) -> 3925607.8 | N6: =SUM(B6:M6) -> 38315804 | O6: Продажи
A7: Основной продукт · себестоимость | B7: =(B6*('Вводные'!$B$34/100)) -> 892500 | C7: =(C6*('Вводные'!$B$34/100)) -> 928200 | D7: =(D6*('Вводные'!$B$34/100)) -> 965328 | E7: =(E6*('Вводные'!$B$34/100)) -> 1003941.1 | F7: =(F6*('Вводные'!$B$34/100)) -> 1044098.8 | G7: =(G6*('Вводные'!$B$34/100)) -> 1085862.7 | H7: =(H6*('Вводные'!$B$34/100)) -> 1129297.2 | I7: =(I6*('Вводные'!$B$34/100)) -> 1174469.1 | ... M7: =(M6*('Вводные'!$B$34/100)) -> 1373962.7 | N7: =SUM(B7:M7) -> 13410531 | O7: Продажи
A8: Выручка / оборот | B8: =IF(('Вводные'!$B$4="manual"),('Вводные'!$B$18*'Вводные'!$B$17),B6) -> 1000000 | C8: =IF(('Вводные'!$B$4="manual"),('Вводные'!$B$19*'Вводные'!$B$17),C6) -> 1000000 | D8: =IF(('Вводные'!$B$4="manual"),('Вводные'!$B$20*'Вводные'!$B$17),D6) -> 1000000 | E8: =IF(('Вводные'!$B$4="manual"),('Вводные'!$B$21*'Вводные'!$B$17),E6) -> 1000000 | F8: =IF(('Вводные'!$B$4="manual"),('Вводные'!$B$22*'Вводные'!$B$17),F6) -> 1000000 | G8: =IF(('Вводные'!$B$4="manual"),('Вводные'!$B$23*'Вводные'!$B$17),G6) -> 1000000 | H8: =IF(('Вводные'!$B$4="manual"),('Вводные'!$B$24*'Вводные'!$B$17),H6) -> 1000000 | I8: =IF(('Вводные'!$B$4="manual"),('Вводные'!$B$25*'Вводные'!$B$17),I6) -> 1000000 | J8: =IF(('Вводные'!$B$4="manual"),('Вводные'!$B$26*'Вводные'!$B$17),J6) -> 1000000 | K8: =IF(('Вводные'!$B$4="manual"),('Вводные'!$B$27*'Вводные'!$B$17),K6) -> 1000000 | L8: =IF(('Вводные'!$B$4="manual"),('Вводные'!$B$28*'Вводные'!$B$17),L6) -> 1000000 | M8: =IF(('Вводные'!$B$4="manual"),('Вводные'!$B$29*'Вводные'!$B$17),M6) -> 1000000 | N8: =SUM(B8:M8) -> 12000000 | O8: По продуктам: количество × цена. Вручную: введённый оборот. Сценарий применяется один раз.
A9: Себестоимость продаж | B9: =IF(('Вводные'!$B$4="manual"),(B8*('Вводные'!$B$5/100)),B7) -> 400000 | C9: =IF(('Вводные'!$B$4="manual"),(C8*('Вводные'!$B$5/100)),C7) -> 400000 | D9: =IF(('Вводные'!$B$4="manual"),(D8*('Вводные'!$B$5/100)),D7) -> 400000 | E9: =IF(('Вводные'!$B$4="manual"),(E8*('Вводные'!$B$5/100)),E7) -> 400000 | F9: =IF(('Вводные'!$B$4="manual"),(F8*('Вводные'!$B$5/100)),F7) -> 400000 | G9: =IF(('Вводные'!$B$4="manual"),(G8*('Вводные'!$B$5/100)),G7) -> 400000 | H9: =IF(('Вводные'!$B$4="manual"),(H8*('Вводные'!$B$5/100)),H7) -> 400000 | I9: =IF(('Вводные'!$B$4="manual"),(I8*('Вводные'!$B$5/100)),I7) -> 400000 | ... M9: =IF(('Вводные'!$B$4="manual"),(M8*('Вводные'!$B$5/100)),M7) -> 400000 | N9: =SUM(B9:M9) -> 4800000 | O9: Себестоимость продуктов или доля ручного оборота. Не дублируйте её в прочих расходах.
A10: Валовая прибыль | B10: =(B8-B9) -> 600000 | C10: =(C8-C9) -> 600000 | D10: =(D8-D9) -> 600000 | E10: =(E8-E9) -> 600000 | F10: =(F8-F9) -> 600000 | G10: =(G8-G9) -> 600000 | H10: =(H8-H9) -> 600000 | I10: =(I8-I9) -> 600000 | ... M10: =(M8-M9) -> 600000 | N10: =SUM(B10:M10) -> 7200000 | O10: Выручка − себестоимость.
A11: Оклады и бонусы | B11: =0 -> 0 | C11: =0 -> 0 | D11: =0 -> 0 | E11: =0 -> 0 | F11: =0 -> 0 | G11: =0 -> 0 | H11: =0 -> 0 | I11: =0 -> 0 | ... M11: =0 -> 0 | N11: =SUM(B11:M11) -> 0 | O11: Команда
A12: Начисления работодателя | B12: =0 -> 0 | C12: =0 -> 0 | D12: =0 -> 0 | E12: =0 -> 0 | F12: =0 -> 0 | G12: =0 -> 0 | H12: =0 -> 0 | I12: =0 -> 0 | ... M12: =0 -> 0 | N12: =SUM(B12:M12) -> 0 | O12: Команда
A13: Команда — всего | B13: =(B11+B12) -> 0 | C13: =(C11+C12) -> 0 | D13: =(D11+D12) -> 0 | E13: =(E11+E12) -> 0 | F13: =(F11+F12) -> 0 | G13: =(G11+G12) -> 0 | H13: =(H11+H12) -> 0 | I13: =(I11+I12) -> 0 | ... M13: =(M11+M12) -> 0 | N13: =SUM(B13:M13) -> 0 | O13: Количество × (оклад + бонус) × рост × (1 + начисления). Ставки задаёте вы.
A14: Маркетинг — всего | B14: =0 -> 0 | C14: =0 -> 0 | D14: =0 -> 0 | E14: =0 -> 0 | F14: =0 -> 0 | G14: =0 -> 0 | H14: =0 -> 0 | I14: =0 -> 0 | ... M14: =0 -> 0 | N14: =SUM(B14:M14) -> 0 | O14: Бюджеты каналов + процент от выручки. Продажи из воронки уже должны входить в общий оборот.
A15: Заявки из рекламы, шт. | B15: =0 -> 0 | C15: =0 -> 0 | D15: =0 -> 0 | E15: =0 -> 0 | F15: =0 -> 0 | G15: =0 -> 0 | H15: =0 -> 0 | I15: =0 -> 0 | ... M15: =0 -> 0 | N15: =SUM(B15:M15) -> 0 | O15: Маркетинг
A16: Клиенты из рекламы, шт. | B16: =0 -> 0 | C16: =0 -> 0 | D16: =0 -> 0 | E16: =0 -> 0 | F16: =0 -> 0 | G16: =0 -> 0 | H16: =0 -> 0 | I16: =0 -> 0 | ... M16: =0 -> 0 | N16: =SUM(B16:M16) -> 0 | O16: Маркетинг
A17: Оценка выручки из рекламы | B17: =0 -> 0 | C17: =0 -> 0 | D17: =0 -> 0 | E17: =0 -> 0 | F17: =0 -> 0 | G17: =0 -> 0 | H17: =0 -> 0 | I17: =0 -> 0 | ... M17: =0 -> 0 | N17: =SUM(B17:M17) -> 0 | O17: Клиенты × чек каждого канала. Не прибавляется к обороту, чтобы не считать продажи дважды.
A18: Комиссия | B18: =IF(AND(AND((1>='Вводные'!$B$41),(1<='Вводные'!$B$42)),IF(('Вводные'!$B$38="once"),(1='Вводные'!$B$41),TRUE)),IF(('Вводные'!$B$38="percent"),(B8*('Вводные'!$B$39/100)),('Вводные'!$B$39*((1+('Вводные'!$B$40/100))^MAX(0,(1-'Вводные'!$B$41))))),0) -> 50000 | C18: =IF(AND(AND((2>='Вводные'!$B$41),(2<='Вводные'!$B$42)),IF(('Вводные'!$B$38="once"),(2='Вводные'!$B$41),TRUE)),IF(('Вводные'!$B$38="percent"),(C8*('Вводные'!$B$39/100)),('Вводные'!$B$39*((1+('Вводные'!$B$40/100))^MAX(0,(2-'Вводные'!$B$41))))),0) -> 50000 | D18: =IF(AND(AND((3>='Вводные'!$B$41),(3<='Вводные'!$B$42)),IF(('Вводные'!$B$38="once"),(3='Вводные'!$B$41),TRUE)),IF(('Вводные'!$B$38="percent"),(D8*('Вводные'!$B$39/100)),('Вводные'!$B$39*((1+('Вводные'!$B$40/100))^MAX(0,(3-'Вводные'!$B$41))))),0) -> 50000 | E18: =IF(AND(AND((4>='Вводные'!$B$41),(4<='Вводные'!$B$42)),IF(('Вводные'!$B$38="once"),(4='Вводные'!$B$41),TRUE)),IF(('Вводные'!$B$38="percent"),(E8*('Вводные'!$B$39/100)),('Вводные'!$B$39*((1+('Вводные'!$B$40/100))^MAX(0,(4-'Вводные'!$B$41))))),0) -> 50000 | F18: =IF(AND(AND((5>='Вводные'!$B$41),(5<='Вводные'!$B$42)),IF(('Вводные'!$B$38="once"),(5='Вводные'!$B$41),TRUE)),IF(('Вводные'!$B$38="percent"),(F8*('Вводные'!$B$39/100)),('Вводные'!$B$39*((1+('Вводные'!$B$40/100))^MAX(0,(5-'Вводные'!$B$41))))),0) -> 50000 | G18: =IF(AND(AND((6>='Вводные'!$B$41),(6<='Вводные'!$B$42)),IF(('Вводные'!$B$38="once"),(6='Вводные'!$B$41),TRUE)),IF(('Вводные'!$B$38="percent"),(G8*('Вводные'!$B$39/100)),('Вводные'!$B$39*((1+('Вводные'!$B$40/100))^MAX(0,(6-'Вводные'!$B$41))))),0) -> 50000 | H18: =IF(AND(AND((7>='Вводные'!$B$41),(7<='Вводные'!$B$42)),IF(('Вводные'!$B$38="once"),(7='Вводные'!$B$41),TRUE)),IF(('Вводные'!$B$38="percent"),(H8*('Вводные'!$B$39/100)),('Вводные'!$B$39*((1+('Вводные'!$B$40/100))^MAX(0,(7-'Вводные'!$B$41))))),0) -> 50000 | I18: =IF(AND(AND((8>='Вводные'!$B$41),(8<='Вводные'!$B$42)),IF(('Вводные'!$B$38="once"),(8='Вводные'!$B$41),TRUE)),IF(('Вводные'!$B$38="percent"),(I8*('Вводные'!$B$39/100)),('Вводные'!$B$39*((1+('Вводные'!$B$40/100))^MAX(0,(8-'Вводные'!$B$41))))),0) -> 50000 | J18: =IF(AND(AND((9>='Вводные'!$B$41),(9<='Вводные'!$B$42)),IF(('Вводные'!$B$38="once"),(9='Вводные'!$B$41),TRUE)),IF(('Вводные'!$B$38="percent"),(J8*('Вводные'!$B$39/100)),('Вводные'!$B$39*((1+('Вводные'!$B$40/100))^MAX(0,(9-'Вводные'!$B$41))))),0) -> 50000 | K18: =IF(AND(AND((10>='Вводные'!$B$41),(10<='Вводные'!$B$42)),IF(('Вводные'!$B$38="once"),(10='Вводные'!$B$41),TRUE)),IF(('Вводные'!$B$38="percent"),(K8*('Вводные'!$B$39/100)),('Вводные'!$B$39*((1+('Вводные'!$B$40/100))^MAX(0,(10-'Вводные'!$B$41))))),0) -> 50000 | L18: =IF(AND(AND((11>='Вводные'!$B$41),(11<='Вводные'!$B$42)),IF(('Вводные'!$B$38="once"),(11='Вводные'!$B$41),TRUE)),IF(('Вводные'!$B$38="percent"),(L8*('Вводные'!$B$39/100)),('Вводные'!$B$39*((1+('Вводные'!$B$40/100))^MAX(0,(11-'Вводные'!$B$41))))),0) -> 50000 | M18: =IF(AND(AND((12>='Вводные'!$B$41),(12<='Вводные'!$B$42)),IF(('Вводные'!$B$38="once"),(12='Вводные'!$B$41),TRUE)),IF(('Вводные'!$B$38="percent"),(M8*('Вводные'!$B$39/100)),('Вводные'!$B$39*((1+('Вводные'!$B$40/100))^MAX(0,(12-'Вводные'!$B$41))))),0) -> 50000 | N18: =SUM(B18:M18) -> 600000 | O18: Прочие расходы
A19: Разовый | B19: =IF(AND(AND((1>='Вводные'!$B$47),(1<='Вводные'!$B$48)),IF(('Вводные'!$B$44="once"),(1='Вводные'!$B$47),TRUE)),IF(('Вводные'!$B$44="percent"),(B8*('Вводные'!$B$45/100)),('Вводные'!$B$45*((1+('Вводные'!$B$46/100))^MAX(0,(1-'Вводные'!$B$47))))),0) -> 0 | C19: =IF(AND(AND((2>='Вводные'!$B$47),(2<='Вводные'!$B$48)),IF(('Вводные'!$B$44="once"),(2='Вводные'!$B$47),TRUE)),IF(('Вводные'!$B$44="percent"),(C8*('Вводные'!$B$45/100)),('Вводные'!$B$45*((1+('Вводные'!$B$46/100))^MAX(0,(2-'Вводные'!$B$47))))),0) -> 0 | D19: =IF(AND(AND((3>='Вводные'!$B$47),(3<='Вводные'!$B$48)),IF(('Вводные'!$B$44="once"),(3='Вводные'!$B$47),TRUE)),IF(('Вводные'!$B$44="percent"),(D8*('Вводные'!$B$45/100)),('Вводные'!$B$45*((1+('Вводные'!$B$46/100))^MAX(0,(3-'Вводные'!$B$47))))),0) -> 100000 | E19: =IF(AND(AND((4>='Вводные'!$B$47),(4<='Вводные'!$B$48)),IF(('Вводные'!$B$44="once"),(4='Вводные'!$B$47),TRUE)),IF(('Вводные'!$B$44="percent"),(E8*('Вводные'!$B$45/100)),('Вводные'!$B$45*((1+('Вводные'!$B$46/100))^MAX(0,(4-'Вводные'!$B$47))))),0) -> 0 | F19: =IF(AND(AND((5>='Вводные'!$B$47),(5<='Вводные'!$B$48)),IF(('Вводные'!$B$44="once"),(5='Вводные'!$B$47),TRUE)),IF(('Вводные'!$B$44="percent"),(F8*('Вводные'!$B$45/100)),('Вводные'!$B$45*((1+('Вводные'!$B$46/100))^MAX(0,(5-'Вводные'!$B$47))))),0) -> 0 | G19: =IF(AND(AND((6>='Вводные'!$B$47),(6<='Вводные'!$B$48)),IF(('Вводные'!$B$44="once"),(6='Вводные'!$B$47),TRUE)),IF(('Вводные'!$B$44="percent"),(G8*('Вводные'!$B$45/100)),('Вводные'!$B$45*((1+('Вводные'!$B$46/100))^MAX(0,(6-'Вводные'!$B$47))))),0) -> 0 | H19: =IF(AND(AND((7>='Вводные'!$B$47),(7<='Вводные'!$B$48)),IF(('Вводные'!$B$44="once"),(7='Вводные'!$B$47),TRUE)),IF(('Вводные'!$B$44="percent"),(H8*('Вводные'!$B$45/100)),('Вводные'!$B$45*((1+('Вводные'!$B$46/100))^MAX(0,(7-'Вводные'!$B$47))))),0) -> 0 | I19: =IF(AND(AND((8>='Вводные'!$B$47),(8<='Вводные'!$B$48)),IF(('Вводные'!$B$44="once"),(8='Вводные'!$B$47),TRUE)),IF(('Вводные'!$B$44="percent"),(I8*('Вводные'!$B$45/100)),('Вводные'!$B$45*((1+('Вводные'!$B$46/100))^MAX(0,(8-'Вводные'!$B$47))))),0) -> 0 | J19: =IF(AND(AND((9>='Вводные'!$B$47),(9<='Вводные'!$B$48)),IF(('Вводные'!$B$44="once"),(9='Вводные'!$B$47),TRUE)),IF(('Вводные'!$B$44="percent"),(J8*('Вводные'!$B$45/100)),('Вводные'!$B$45*((1+('Вводные'!$B$46/100))^MAX(0,(9-'Вводные'!$B$47))))),0) -> 0 | K19: =IF(AND(AND((10>='Вводные'!$B$47),(10<='Вводные'!$B$48)),IF(('Вводные'!$B$44="once"),(10='Вводные'!$B$47),TRUE)),IF(('Вводные'!$B$44="percent"),(K8*('Вводные'!$B$45/100)),('Вводные'!$B$45*((1+('Вводные'!$B$46/100))^MAX(0,(10-'Вводные'!$B$47))))),0) -> 0 | L19: =IF(AND(AND((11>='Вводные'!$B$47),(11<='Вводные'!$B$48)),IF(('Вводные'!$B$44="once"),(11='Вводные'!$B$47),TRUE)),IF(('Вводные'!$B$44="percent"),(L8*('Вводные'!$B$45/100)),('Вводные'!$B$45*((1+('Вводные'!$B$46/100))^MAX(0,(11-'Вводные'!$B$47))))),0) -> 0 | M19: =IF(AND(AND((12>='Вводные'!$B$47),(12<='Вводные'!$B$48)),IF(('Вводные'!$B$44="once"),(12='Вводные'!$B$47),TRUE)),IF(('Вводные'!$B$44="percent"),(M8*('Вводные'!$B$45/100)),('Вводные'!$B$45*((1+('Вводные'!$B$46/100))^MAX(0,(12-'Вводные'!$B$47))))),0) -> 0 | N19: =SUM(B19:M19) -> 100000 | O19: Прочие расходы
A20: Прочие расходы — всего | B20: =(B18+B19) -> 50000 | C20: =(C18+C19) -> 50000 | D20: =(D18+D19) -> 150000 | E20: =(E18+E19) -> 50000 | F20: =(F18+F19) -> 50000 | G20: =(G18+G19) -> 50000 | H20: =(H18+H19) -> 50000 | I20: =(I18+I19) -> 50000 | ... M20: =(M18+M19) -> 50000 | N20: =SUM(B20:M20) -> 700000 | O20: Результат
A21: Операционные расходы | B21: =((B13+B14)+B20) -> 50000 | C21: =((C13+C14)+C20) -> 50000 | D21: =((D13+D14)+D20) -> 150000 | E21: =((E13+E14)+E20) -> 50000 | F21: =((F13+F14)+F20) -> 50000 | G21: =((G13+G14)+G20) -> 50000 | H21: =((H13+H14)+H20) -> 50000 | I21: =((I13+I14)+I20) -> 50000 | ... M21: =((M13+M14)+M20) -> 50000 | N21: =SUM(B21:M21) -> 700000 | O21: Команда + маркетинг + прочие расходы.
A22: EBITDA | B22: =(B10-B21) -> 550000 | C22: =(C10-C21) -> 550000 | D22: =(D10-D21) -> 450000 | E22: =(E10-E21) -> 550000 | F22: =(F10-F21) -> 550000 | G22: =(G10-G21) -> 550000 | H22: =(H10-H21) -> 550000 | I22: =(I10-I21) -> 550000 | ... M22: =(M10-M21) -> 550000 | N22: =SUM(B22:M22) -> 6500000 | O22: Валовая прибыль − операционные расходы; до амортизации, процентов и налога.
A23: Станок · покупка | B23: =IF((1='Вводные'!$B$51),'Вводные'!$B$50,0) -> 0 | C23: =IF((2='Вводные'!$B$51),'Вводные'!$B$50,0) -> 120000 | D23: =IF((3='Вводные'!$B$51),'Вводные'!$B$50,0) -> 0 | E23: =IF((4='Вводные'!$B$51),'Вводные'!$B$50,0) -> 0 | F23: =IF((5='Вводные'!$B$51),'Вводные'!$B$50,0) -> 0 | G23: =IF((6='Вводные'!$B$51),'Вводные'!$B$50,0) -> 0 | H23: =IF((7='Вводные'!$B$51),'Вводные'!$B$50,0) -> 0 | I23: =IF((8='Вводные'!$B$51),'Вводные'!$B$50,0) -> 0 | J23: =IF((9='Вводные'!$B$51),'Вводные'!$B$50,0) -> 0 | K23: =IF((10='Вводные'!$B$51),'Вводные'!$B$50,0) -> 0 | L23: =IF((11='Вводные'!$B$51),'Вводные'!$B$50,0) -> 0 | M23: =IF((12='Вводные'!$B$51),'Вводные'!$B$50,0) -> 0 | N23: =SUM(B23:M23) -> 120000 | O23: Вложения
A24: Станок · амортизация | B24: =IF(AND((1>='Вводные'!$B$51),(1<=(('Вводные'!$B$51+'Вводные'!$B$52)-1))),('Вводные'!$B$50/'Вводные'!$B$52),0) -> 0 | C24: =IF(AND((2>='Вводные'!$B$51),(2<=(('Вводные'!$B$51+'Вводные'!$B$52)-1))),('Вводные'!$B$50/'Вводные'!$B$52),0) -> 10000 | D24: =IF(AND((3>='Вводные'!$B$51),(3<=(('Вводные'!$B$51+'Вводные'!$B$52)-1))),('Вводные'!$B$50/'Вводные'!$B$52),0) -> 10000 | E24: =IF(AND((4>='Вводные'!$B$51),(4<=(('Вводные'!$B$51+'Вводные'!$B$52)-1))),('Вводные'!$B$50/'Вводные'!$B$52),0) -> 10000 | F24: =IF(AND((5>='Вводные'!$B$51),(5<=(('Вводные'!$B$51+'Вводные'!$B$52)-1))),('Вводные'!$B$50/'Вводные'!$B$52),0) -> 10000 | G24: =IF(AND((6>='Вводные'!$B$51),(6<=(('Вводные'!$B$51+'Вводные'!$B$52)-1))),('Вводные'!$B$50/'Вводные'!$B$52),0) -> 10000 | H24: =IF(AND((7>='Вводные'!$B$51),(7<=(('Вводные'!$B$51+'Вводные'!$B$52)-1))),('Вводные'!$B$50/'Вводные'!$B$52),0) -> 10000 | I24: =IF(AND((8>='Вводные'!$B$51),(8<=(('Вводные'!$B$51+'Вводные'!$B$52)-1))),('Вводные'!$B$50/'Вводные'!$B$52),0) -> 10000 | J24: =IF(AND((9>='Вводные'!$B$51),(9<=(('Вводные'!$B$51+'Вводные'!$B$52)-1))),('Вводные'!$B$50/'Вводные'!$B$52),0) -> 10000 | K24: =IF(AND((10>='Вводные'!$B$51),(10<=(('Вводные'!$B$51+'Вводные'!$B$52)-1))),('Вводные'!$B$50/'Вводные'!$B$52),0) -> 10000 | L24: =IF(AND((11>='Вводные'!$B$51),(11<=(('Вводные'!$B$51+'Вводные'!$B$52)-1))),('Вводные'!$B$50/'Вводные'!$B$52),0) -> 10000 | M24: =IF(AND((12>='Вводные'!$B$51),(12<=(('Вводные'!$B$51+'Вводные'!$B$52)-1))),('Вводные'!$B$50/'Вводные'!$B$52),0) -> 10000 | N24: =SUM(B24:M24) -> 110000 | O24: Вложения
A25: Покупка активов | B25: =B23 -> 0 | C25: =C23 -> 120000 | D25: =D23 -> 0 | E25: =E23 -> 0 | F25: =F23 -> 0 | G25: =G23 -> 0 | H25: =H23 -> 0 | I25: =I23 -> 0 | ... M25: =M23 -> 0 | N25: =SUM(B25:M25) -> 120000 | O25: Денежный поток
A26: Амортизация | B26: =(IF(AND(('Вводные'!$B$13>0),(1<='Вводные'!$B$13)),('Вводные'!$B$12/MAX(1,'Вводные'!$B$13)),0)+B24) -> 0 | C26: =(IF(AND(('Вводные'!$B$13>0),(2<='Вводные'!$B$13)),('Вводные'!$B$12/MAX(1,'Вводные'!$B$13)),0)+C24) -> 10000 | D26: =(IF(AND(('Вводные'!$B$13>0),(3<='Вводные'!$B$13)),('Вводные'!$B$12/MAX(1,'Вводные'!$B$13)),0)+D24) -> 10000 | E26: =(IF(AND(('Вводные'!$B$13>0),(4<='Вводные'!$B$13)),('Вводные'!$B$12/MAX(1,'Вводные'!$B$13)),0)+E24) -> 10000 | F26: =(IF(AND(('Вводные'!$B$13>0),(5<='Вводные'!$B$13)),('Вводные'!$B$12/MAX(1,'Вводные'!$B$13)),0)+F24) -> 10000 | G26: =(IF(AND(('Вводные'!$B$13>0),(6<='Вводные'!$B$13)),('Вводные'!$B$12/MAX(1,'Вводные'!$B$13)),0)+G24) -> 10000 | H26: =(IF(AND(('Вводные'!$B$13>0),(7<='Вводные'!$B$13)),('Вводные'!$B$12/MAX(1,'Вводные'!$B$13)),0)+H24) -> 10000 | I26: =(IF(AND(('Вводные'!$B$13>0),(8<='Вводные'!$B$13)),('Вводные'!$B$12/MAX(1,'Вводные'!$B$13)),0)+I24) -> 10000 | J26: =(IF(AND(('Вводные'!$B$13>0),(9<='Вводные'!$B$13)),('Вводные'!$B$12/MAX(1,'Вводные'!$B$13)),0)+J24) -> 10000 | K26: =(IF(AND(('Вводные'!$B$13>0),(10<='Вводные'!$B$13)),('Вводные'!$B$12/MAX(1,'Вводные'!$B$13)),0)+K24) -> 10000 | L26: =(IF(AND(('Вводные'!$B$13>0),(11<='Вводные'!$B$13)),('Вводные'!$B$12/MAX(1,'Вводные'!$B$13)),0)+L24) -> 10000 | M26: =(IF(AND(('Вводные'!$B$13>0),(12<='Вводные'!$B$13)),('Вводные'!$B$12/MAX(1,'Вводные'!$B$13)),0)+M24) -> 10000 | N26: =SUM(B26:M26) -> 110000 | O26: Стоимость / срок в месяцах, начиная с месяца покупки. Покупка уменьшает деньги, амортизация — прибыль.
A27: Операционная прибыль (EBIT) | B27: =(B22-B26) -> 550000 | C27: =(C22-C26) -> 540000 | D27: =(D22-D26) -> 440000 | E27: =(E22-E26) -> 540000 | F27: =(F22-F26) -> 540000 | G27: =(G22-G26) -> 540000 | H27: =(H22-H26) -> 540000 | I27: =(I22-I26) -> 540000 | ... M27: =(M22-M26) -> 540000 | N27: =SUM(B27:M27) -> 6390000 | O27: Результат
A28: Кредит на начало месяца | B28: =IF((1<='Вводные'!$B$16),MAX(0,IF(((('Вводные'!$B$15/100)/12)>0),(('Вводные'!$B$14*((1+(('Вводные'!$B$15/100)/12))^0))-(IF(((('Вводные'!$B$15/100)/12)>0),(('Вводные'!$B$14*(('Вводные'!$B$15/100)/12))/(1-((1+(('Вводные'!$B$15/100)/12))^(-1*'Вводные'!$B$16)))),('Вводные'!$B$14/'Вводные'!$B$16))*((((1+(('Вводные'!$B$15/100)/12))^0)-1)/(('Вводные'!$B$15/100)/12)))),('Вводные'!$B$14-(IF(((('Вводные'!$B$15/100)/12)>0),(('Вводные'!$B$14*(('Вводные'!$B$15/100)/12))/(1-((1+(('Вводные'!$B$15/100)/12))^(-1*'Вводные'!$B$16)))),('Вводные'!$B$14/'Вводные'!$B$16))*0)))),0) -> 120000 | C28: =IF((2<='Вводные'!$B$16),MAX(0,IF(((('Вводные'!$B$15/100)/12)>0),(('Вводные'!$B$14*((1+(('Вводные'!$B$15/100)/12))^1))-(IF(((('Вводные'!$B$15/100)/12)>0),(('Вводные'!$B$14*(('Вводные'!$B$15/100)/12))/(1-((1+(('Вводные'!$B$15/100)/12))^(-1*'Вводные'!$B$16)))),('Вводные'!$B$14/'Вводные'!$B$16))*((((1+(('Вводные'!$B$15/100)/12))^1)-1)/(('Вводные'!$B$15/100)/12)))),('Вводные'!$B$14-(IF(((('Вводные'!$B$15/100)/12)>0),(('Вводные'!$B$14*(('Вводные'!$B$15/100)/12))/(1-((1+(('Вводные'!$B$15/100)/12))^(-1*'Вводные'!$B$16)))),('Вводные'!$B$14/'Вводные'!$B$16))*1)))),0) -> 110538.15 | D28: =IF((3<='Вводные'!$B$16),MAX(0,IF(((('Вводные'!$B$15/100)/12)>0),(('Вводные'!$B$14*((1+(('Вводные'!$B$15/100)/12))^2))-(IF(((('Вводные'!$B$15/100)/12)>0),(('Вводные'!$B$14*(('Вводные'!$B$15/100)/12))/(1-((1+(('Вводные'!$B$15/100)/12))^(-1*'Вводные'!$B$16)))),('Вводные'!$B$14/'Вводные'!$B$16))*((((1+(('Вводные'!$B$15/100)/12))^2)-1)/(('Вводные'!$B$15/100)/12)))),('Вводные'!$B$14-(IF(((('Вводные'!$B$15/100)/12)>0),(('Вводные'!$B$14*(('Вводные'!$B$15/100)/12))/(1-((1+(('Вводные'!$B$15/100)/12))^(-1*'Вводные'!$B$16)))),('Вводные'!$B$14/'Вводные'!$B$16))*2)))),0) -> 100981.67 | E28: =IF((4<='Вводные'!$B$16),MAX(0,IF(((('Вводные'!$B$15/100)/12)>0),(('Вводные'!$B$14*((1+(('Вводные'!$B$15/100)/12))^3))-(IF(((('Вводные'!$B$15/100)/12)>0),(('Вводные'!$B$14*(('Вводные'!$B$15/100)/12))/(1-((1+(('Вводные'!$B$15/100)/12))^(-1*'Вводные'!$B$16)))),('Вводные'!$B$14/'Вводные'!$B$16))*((((1+(('Вводные'!$B$15/100)/12))^3)-1)/(('Вводные'!$B$15/100)/12)))),('Вводные'!$B$14-(IF(((('Вводные'!$B$15/100)/12)>0),(('Вводные'!$B$14*(('Вводные'!$B$15/100)/12))/(1-((1+(('Вводные'!$B$15/100)/12))^(-1*'Вводные'!$B$16)))),('Вводные'!$B$14/'Вводные'!$B$16))*3)))),0) -> 91329.634 | F28: =IF((5<='Вводные'!$B$16),MAX(0,IF(((('Вводные'!$B$15/100)/12)>0),(('Вводные'!$B$14*((1+(('Вводные'!$B$15/100)/12))^4))-(IF(((('Вводные'!$B$15/100)/12)>0),(('Вводные'!$B$14*(('Вводные'!$B$15/100)/12))/(1-((1+(('Вводные'!$B$15/100)/12))^(-1*'Вводные'!$B$16)))),('Вводные'!$B$14/'Вводные'!$B$16))*((((1+(('Вводные'!$B$15/100)/12))^4)-1)/(('Вводные'!$B$15/100)/12)))),('Вводные'!$B$14-(IF(((('Вводные'!$B$15/100)/12)>0),(('Вводные'!$B$14*(('Вводные'!$B$15/100)/12))/(1-((1+(('Вводные'!$B$15/100)/12))^(-1*'Вводные'!$B$16)))),('Вводные'!$B$14/'Вводные'!$B$16))*4)))),0) -> 81581.076 | G28: =IF((6<='Вводные'!$B$16),MAX(0,IF(((('Вводные'!$B$15/100)/12)>0),(('Вводные'!$B$14*((1+(('Вводные'!$B$15/100)/12))^5))-(IF(((('Вводные'!$B$15/100)/12)>0),(('Вводные'!$B$14*(('Вводные'!$B$15/100)/12))/(1-((1+(('Вводные'!$B$15/100)/12))^(-1*'Вводные'!$B$16)))),('Вводные'!$B$14/'Вводные'!$B$16))*((((1+(('Вводные'!$B$15/100)/12))^5)-1)/(('Вводные'!$B$15/100)/12)))),('Вводные'!$B$14-(IF(((('Вводные'!$B$15/100)/12)>0),(('Вводные'!$B$14*(('Вводные'!$B$15/100)/12))/(1-((1+(('Вводные'!$B$15/100)/12))^(-1*'Вводные'!$B$16)))),('Вводные'!$B$14/'Вводные'!$B$16))*5)))),0) -> 71735.032 | H28: =IF((7<='Вводные'!$B$16),MAX(0,IF(((('Вводные'!$B$15/100)/12)>0),(('Вводные'!$B$14*((1+(('Вводные'!$B$15/100)/12))^6))-(IF(((('Вводные'!$B$15/100)/12)>0),(('Вводные'!$B$14*(('Вводные'!$B$15/100)/12))/(1-((1+(('Вводные'!$B$15/100)/12))^(-1*'Вводные'!$B$16)))),('Вводные'!$B$14/'Вводные'!$B$16))*((((1+(('Вводные'!$B$15/100)/12))^6)-1)/(('Вводные'!$B$15/100)/12)))),('Вводные'!$B$14-(IF(((('Вводные'!$B$15/100)/12)>0),(('Вводные'!$B$14*(('Вводные'!$B$15/100)/12))/(1-((1+(('Вводные'!$B$15/100)/12))^(-1*'Вводные'!$B$16)))),('Вводные'!$B$14/'Вводные'!$B$16))*6)))),0) -> 61790.528 | I28: =IF((8<='Вводные'!$B$16),MAX(0,IF(((('Вводные'!$B$15/100)/12)>0),(('Вводные'!$B$14*((1+(('Вводные'!$B$15/100)/12))^7))-(IF(((('Вводные'!$B$15/100)/12)>0),(('Вводные'!$B$14*(('Вводные'!$B$15/100)/12))/(1-((1+(('Вводные'!$B$15/100)/12))^(-1*'Вводные'!$B$16)))),('Вводные'!$B$14/'Вводные'!$B$16))*((((1+(('Вводные'!$B$15/100)/12))^7)-1)/(('Вводные'!$B$15/100)/12)))),('Вводные'!$B$14-(IF(((('Вводные'!$B$15/100)/12)>0),(('Вводные'!$B$14*(('Вводные'!$B$15/100)/12))/(1-((1+(('Вводные'!$B$15/100)/12))^(-1*'Вводные'!$B$16)))),('Вводные'!$B$14/'Вводные'!$B$16))*7)))),0) -> 51746.578 | J28: =IF((9<='Вводные'!$B$16),MAX(0,IF(((('Вводные'!$B$15/100)/12)>0),(('Вводные'!$B$14*((1+(('Вводные'!$B$15/100)/12))^8))-(IF(((('Вводные'!$B$15/100)/12)>0),(('Вводные'!$B$14*(('Вводные'!$B$15/100)/12))/(1-((1+(('Вводные'!$B$15/100)/12))^(-1*'Вводные'!$B$16)))),('Вводные'!$B$14/'Вводные'!$B$16))*((((1+(('Вводные'!$B$15/100)/12))^8)-1)/(('Вводные'!$B$15/100)/12)))),('Вводные'!$B$14-(IF(((('Вводные'!$B$15/100)/12)>0),(('Вводные'!$B$14*(('Вводные'!$B$15/100)/12))/(1-((1+(('Вводные'!$B$15/100)/12))^(-1*'Вводные'!$B$16)))),('Вводные'!$B$14/'Вводные'!$B$16))*8)))),0) -> 41602.19 | K28: =IF((10<='Вводные'!$B$16),MAX(0,IF(((('Вводные'!$B$15/100)/12)>0),(('Вводные'!$B$14*((1+(('Вводные'!$B$15/100)/12))^9))-(IF(((('Вводные'!$B$15/100)/12)>0),(('Вводные'!$B$14*(('Вводные'!$B$15/100)/12))/(1-((1+(('Вводные'!$B$15/100)/12))^(-1*'Вводные'!$B$16)))),('Вводные'!$B$14/'Вводные'!$B$16))*((((1+(('Вводные'!$B$15/100)/12))^9)-1)/(('Вводные'!$B$15/100)/12)))),('Вводные'!$B$14-(IF(((('Вводные'!$B$15/100)/12)>0),(('Вводные'!$B$14*(('Вводные'!$B$15/100)/12))/(1-((1+(('Вводные'!$B$15/100)/12))^(-1*'Вводные'!$B$16)))),('Вводные'!$B$14/'Вводные'!$B$16))*9)))),0) -> 31356.357 | L28: =IF((11<='Вводные'!$B$16),MAX(0,IF(((('Вводные'!$B$15/100)/12)>0),(('Вводные'!$B$14*((1+(('Вводные'!$B$15/100)/12))^10))-(IF(((('Вводные'!$B$15/100)/12)>0),(('Вводные'!$B$14*(('Вводные'!$B$15/100)/12))/(1-((1+(('Вводные'!$B$15/100)/12))^(-1*'Вводные'!$B$16)))),('Вводные'!$B$14/'Вводные'!$B$16))*((((1+(('Вводные'!$B$15/100)/12))^10)-1)/(('Вводные'!$B$15/100)/12)))),('Вводные'!$B$14-(IF(((('Вводные'!$B$15/100)/12)>0),(('Вводные'!$B$14*(('Вводные'!$B$15/100)/12))/(1-((1+(('Вводные'!$B$15/100)/12))^(-1*'Вводные'!$B$16)))),('Вводные'!$B$14/'Вводные'!$B$16))*10)))),0) -> 21008.066 | M28: =IF((12<='Вводные'!$B$16),MAX(0,IF(((('Вводные'!$B$15/100)/12)>0),(('Вводные'!$B$14*((1+(('Вводные'!$B$15/100)/12))^11))-(IF(((('Вводные'!$B$15/100)/12)>0),(('Вводные'!$B$14*(('Вводные'!$B$15/100)/12))/(1-((1+(('Вводные'!$B$15/100)/12))^(-1*'Вводные'!$B$16)))),('Вводные'!$B$14/'Вводные'!$B$16))*((((1+(('Вводные'!$B$15/100)/12))^11)-1)/(('Вводные'!$B$15/100)/12)))),('Вводные'!$B$14-(IF(((('Вводные'!$B$15/100)/12)>0),(('Вводные'!$B$14*(('Вводные'!$B$15/100)/12))/(1-((1+(('Вводные'!$B$15/100)/12))^(-1*'Вводные'!$B$16)))),('Вводные'!$B$14/'Вводные'!$B$16))*11)))),0) -> 10556.292 | N28: =M28 -> 10556.292 | O28: Кредит
A29: Проценты по кредиту | B29: =(B28*(('Вводные'!$B$15/100)/12)) -> 1200 | C29: =(C28*(('Вводные'!$B$15/100)/12)) -> 1105.3815 | D29: =(D28*(('Вводные'!$B$15/100)/12)) -> 1009.8167 | E29: =(E28*(('Вводные'!$B$15/100)/12)) -> 913.29634 | F29: =(F28*(('Вводные'!$B$15/100)/12)) -> 815.81076 | G29: =(G28*(('Вводные'!$B$15/100)/12)) -> 717.35032 | H29: =(H28*(('Вводные'!$B$15/100)/12)) -> 617.90528 | I29: =(I28*(('Вводные'!$B$15/100)/12)) -> 517.46578 | ... M29: =(M28*(('Вводные'!$B$15/100)/12)) -> 105.56292 | N29: =SUM(B29:M29) -> 7942.2557 | O29: Результат
A30: Погашение тела кредита | B30: =IF((1<='Вводные'!$B$16),MIN(B28,MAX(0,(IF(((('Вводные'!$B$15/100)/12)>0),(('Вводные'!$B$14*(('Вводные'!$B$15/100)/12))/(1-((1+(('Вводные'!$B$15/100)/12))^(-1*'Вводные'!$B$16)))),('Вводные'!$B$14/'Вводные'!$B$16))-B29))),0) -> 9461.8546 | C30: =IF((2<='Вводные'!$B$16),MIN(C28,MAX(0,(IF(((('Вводные'!$B$15/100)/12)>0),(('Вводные'!$B$14*(('Вводные'!$B$15/100)/12))/(1-((1+(('Вводные'!$B$15/100)/12))^(-1*'Вводные'!$B$16)))),('Вводные'!$B$14/'Вводные'!$B$16))-C29))),0) -> 9556.4732 | D30: =IF((3<='Вводные'!$B$16),MIN(D28,MAX(0,(IF(((('Вводные'!$B$15/100)/12)>0),(('Вводные'!$B$14*(('Вводные'!$B$15/100)/12))/(1-((1+(('Вводные'!$B$15/100)/12))^(-1*'Вводные'!$B$16)))),('Вводные'!$B$14/'Вводные'!$B$16))-D29))),0) -> 9652.0379 | E30: =IF((4<='Вводные'!$B$16),MIN(E28,MAX(0,(IF(((('Вводные'!$B$15/100)/12)>0),(('Вводные'!$B$14*(('Вводные'!$B$15/100)/12))/(1-((1+(('Вводные'!$B$15/100)/12))^(-1*'Вводные'!$B$16)))),('Вводные'!$B$14/'Вводные'!$B$16))-E29))),0) -> 9748.5583 | F30: =IF((5<='Вводные'!$B$16),MIN(F28,MAX(0,(IF(((('Вводные'!$B$15/100)/12)>0),(('Вводные'!$B$14*(('Вводные'!$B$15/100)/12))/(1-((1+(('Вводные'!$B$15/100)/12))^(-1*'Вводные'!$B$16)))),('Вводные'!$B$14/'Вводные'!$B$16))-F29))),0) -> 9846.0439 | G30: =IF((6<='Вводные'!$B$16),MIN(G28,MAX(0,(IF(((('Вводные'!$B$15/100)/12)>0),(('Вводные'!$B$14*(('Вводные'!$B$15/100)/12))/(1-((1+(('Вводные'!$B$15/100)/12))^(-1*'Вводные'!$B$16)))),('Вводные'!$B$14/'Вводные'!$B$16))-G29))),0) -> 9944.5043 | H30: =IF((7<='Вводные'!$B$16),MIN(H28,MAX(0,(IF(((('Вводные'!$B$15/100)/12)>0),(('Вводные'!$B$14*(('Вводные'!$B$15/100)/12))/(1-((1+(('Вводные'!$B$15/100)/12))^(-1*'Вводные'!$B$16)))),('Вводные'!$B$14/'Вводные'!$B$16))-H29))),0) -> 10043.949 | I30: =IF((8<='Вводные'!$B$16),MIN(I28,MAX(0,(IF(((('Вводные'!$B$15/100)/12)>0),(('Вводные'!$B$14*(('Вводные'!$B$15/100)/12))/(1-((1+(('Вводные'!$B$15/100)/12))^(-1*'Вводные'!$B$16)))),('Вводные'!$B$14/'Вводные'!$B$16))-I29))),0) -> 10144.389 | J30: =IF((9<='Вводные'!$B$16),MIN(J28,MAX(0,(IF(((('Вводные'!$B$15/100)/12)>0),(('Вводные'!$B$14*(('Вводные'!$B$15/100)/12))/(1-((1+(('Вводные'!$B$15/100)/12))^(-1*'Вводные'!$B$16)))),('Вводные'!$B$14/'Вводные'!$B$16))-J29))),0) -> 10245.833 | K30: =IF((10<='Вводные'!$B$16),MIN(K28,MAX(0,(IF(((('Вводные'!$B$15/100)/12)>0),(('Вводные'!$B$14*(('Вводные'!$B$15/100)/12))/(1-((1+(('Вводные'!$B$15/100)/12))^(-1*'Вводные'!$B$16)))),('Вводные'!$B$14/'Вводные'!$B$16))-K29))),0) -> 10348.291 | L30: =IF((11<='Вводные'!$B$16),MIN(L28,MAX(0,(IF(((('Вводные'!$B$15/100)/12)>0),(('Вводные'!$B$14*(('Вводные'!$B$15/100)/12))/(1-((1+(('Вводные'!$B$15/100)/12))^(-1*'Вводные'!$B$16)))),('Вводные'!$B$14/'Вводные'!$B$16))-L29))),0) -> 10451.774 | M30: =IF((12<='Вводные'!$B$16),MIN(M28,MAX(0,(IF(((('Вводные'!$B$15/100)/12)>0),(('Вводные'!$B$14*(('Вводные'!$B$15/100)/12))/(1-((1+(('Вводные'!$B$15/100)/12))^(-1*'Вводные'!$B$16)))),('Вводные'!$B$14/'Вводные'!$B$16))-M29))),0) -> 10556.292 | N30: =SUM(B30:M30) -> 120000 | O30: Аннуитетный платёж − проценты. Тело кредита уменьшает деньги, но не прибыль.
A31: Кредит на конец месяца | B31: =MAX(0,(B28-B30)) -> 110538.15 | C31: =MAX(0,(C28-C30)) -> 100981.67 | D31: =MAX(0,(D28-D30)) -> 91329.634 | E31: =MAX(0,(E28-E30)) -> 81581.076 | F31: =MAX(0,(F28-F30)) -> 71735.032 | G31: =MAX(0,(G28-G30)) -> 61790.528 | H31: =MAX(0,(H28-H30)) -> 51746.578 | I31: =MAX(0,(I28-I30)) -> 41602.19 | ... M31: =MAX(0,(M28-M30)) -> 1.6007107e-10 | N31: =M31 -> 1.6007107e-10 | O31: Кредит
A32: Прибыль до налога | B32: =(B27-B29) -> 548800 | C32: =(C27-C29) -> 538894.62 | D32: =(D27-D29) -> 438990.18 | E32: =(E27-E29) -> 539086.7 | F32: =(F27-F29) -> 539184.19 | G32: =(G27-G29) -> 539282.65 | H32: =(H27-H29) -> 539382.09 | I32: =(I27-I29) -> 539482.53 | ... M32: =(M27-M29) -> 539894.44 | N32: =SUM(B32:M32) -> 6382057.7 | O32: Результат
A33: Условный налог | B33: =IF(('Вводные'!$B$6="none"),0,(IF(('Вводные'!$B$6="revenue"),B8,MAX(0,B32))*('Вводные'!$B$7/100))) -> 30000 | C33: =IF(('Вводные'!$B$6="none"),0,(IF(('Вводные'!$B$6="revenue"),C8,MAX(0,C32))*('Вводные'!$B$7/100))) -> 30000 | D33: =IF(('Вводные'!$B$6="none"),0,(IF(('Вводные'!$B$6="revenue"),D8,MAX(0,D32))*('Вводные'!$B$7/100))) -> 30000 | E33: =IF(('Вводные'!$B$6="none"),0,(IF(('Вводные'!$B$6="revenue"),E8,MAX(0,E32))*('Вводные'!$B$7/100))) -> 30000 | F33: =IF(('Вводные'!$B$6="none"),0,(IF(('Вводные'!$B$6="revenue"),F8,MAX(0,F32))*('Вводные'!$B$7/100))) -> 30000 | G33: =IF(('Вводные'!$B$6="none"),0,(IF(('Вводные'!$B$6="revenue"),G8,MAX(0,G32))*('Вводные'!$B$7/100))) -> 30000 | H33: =IF(('Вводные'!$B$6="none"),0,(IF(('Вводные'!$B$6="revenue"),H8,MAX(0,H32))*('Вводные'!$B$7/100))) -> 30000 | I33: =IF(('Вводные'!$B$6="none"),0,(IF(('Вводные'!$B$6="revenue"),I8,MAX(0,I32))*('Вводные'!$B$7/100))) -> 30000 | ... M33: =IF(('Вводные'!$B$6="none"),0,(IF(('Вводные'!$B$6="revenue"),M8,MAX(0,M32))*('Вводные'!$B$7/100))) -> 30000 | N33: =SUM(B33:M33) -> 360000 | O33: Ваша ставка × оборот или положительная прибыль месяца. Без переноса убытков. Оплата в том же месяце.
A34: Чистая прибыль | B34: =(B32-B33) -> 518800 | C34: =(C32-C33) -> 508894.62 | D34: =(D32-D33) -> 408990.18 | E34: =(E32-E33) -> 509086.7 | F34: =(F32-F33) -> 509184.19 | G34: =(G32-G33) -> 509282.65 | H34: =(H32-H33) -> 509382.09 | I34: =(I32-I33) -> 509482.53 | ... M34: =(M32-M33) -> 509894.44 | N34: =SUM(B34:M34) -> 6022057.7 | O34: Выручка − себестоимость − команда − маркетинг − прочие − амортизация − проценты − налог.
A35: Все расходы в прибыли | B35: =(B8-B34) -> 481200 | C35: =(C8-C34) -> 491105.38 | D35: =(D8-D34) -> 591009.82 | E35: =(E8-E34) -> 490913.3 | F35: =(F8-F34) -> 490815.81 | G35: =(G8-G34) -> 490717.35 | H35: =(H8-H34) -> 490617.91 | I35: =(I8-I34) -> 490517.47 | ... M35: =(M8-M34) -> 490105.56 | N35: =SUM(B35:M35) -> 5977942.3 | O35: Результат
A36: Оплата от клиентов | B36: =IF(1-'Вводные'!$B$8>0,INDEX($B$8:$M$8,1,MAX(1,1-'Вводные'!$B$8)),0) -> 0 | C36: =IF(2-'Вводные'!$B$8>0,INDEX($B$8:$M$8,1,MAX(1,2-'Вводные'!$B$8)),0) -> 1000000 | D36: =IF(3-'Вводные'!$B$8>0,INDEX($B$8:$M$8,1,MAX(1,3-'Вводные'!$B$8)),0) -> 1000000 | E36: =IF(4-'Вводные'!$B$8>0,INDEX($B$8:$M$8,1,MAX(1,4-'Вводные'!$B$8)),0) -> 1000000 | F36: =IF(5-'Вводные'!$B$8>0,INDEX($B$8:$M$8,1,MAX(1,5-'Вводные'!$B$8)),0) -> 1000000 | G36: =IF(6-'Вводные'!$B$8>0,INDEX($B$8:$M$8,1,MAX(1,6-'Вводные'!$B$8)),0) -> 1000000 | H36: =IF(7-'Вводные'!$B$8>0,INDEX($B$8:$M$8,1,MAX(1,7-'Вводные'!$B$8)),0) -> 1000000 | I36: =IF(8-'Вводные'!$B$8>0,INDEX($B$8:$M$8,1,MAX(1,8-'Вводные'!$B$8)),0) -> 1000000 | J36: =IF(9-'Вводные'!$B$8>0,INDEX($B$8:$M$8,1,MAX(1,9-'Вводные'!$B$8)),0) -> 1000000 | K36: =IF(10-'Вводные'!$B$8>0,INDEX($B$8:$M$8,1,MAX(1,10-'Вводные'!$B$8)),0) -> 1000000 | L36: =IF(11-'Вводные'!$B$8>0,INDEX($B$8:$M$8,1,MAX(1,11-'Вводные'!$B$8)),0) -> 1000000 | M36: =IF(12-'Вводные'!$B$8>0,INDEX($B$8:$M$8,1,MAX(1,12-'Вводные'!$B$8)),0) -> 1000000 | N36: =SUM(B36:M36) -> 11000000 | O36: Денежный поток
A37: Оплата себестоимости | B37: =IF(1-'Вводные'!$B$9>0,INDEX($B$9:$M$9,1,MAX(1,1-'Вводные'!$B$9)),0) -> 0 | C37: =IF(2-'Вводные'!$B$9>0,INDEX($B$9:$M$9,1,MAX(1,2-'Вводные'!$B$9)),0) -> 0 | D37: =IF(3-'Вводные'!$B$9>0,INDEX($B$9:$M$9,1,MAX(1,3-'Вводные'!$B$9)),0) -> 400000 | E37: =IF(4-'Вводные'!$B$9>0,INDEX($B$9:$M$9,1,MAX(1,4-'Вводные'!$B$9)),0) -> 400000 | F37: =IF(5-'Вводные'!$B$9>0,INDEX($B$9:$M$9,1,MAX(1,5-'Вводные'!$B$9)),0) -> 400000 | G37: =IF(6-'Вводные'!$B$9>0,INDEX($B$9:$M$9,1,MAX(1,6-'Вводные'!$B$9)),0) -> 400000 | H37: =IF(7-'Вводные'!$B$9>0,INDEX($B$9:$M$9,1,MAX(1,7-'Вводные'!$B$9)),0) -> 400000 | I37: =IF(8-'Вводные'!$B$9>0,INDEX($B$9:$M$9,1,MAX(1,8-'Вводные'!$B$9)),0) -> 400000 | J37: =IF(9-'Вводные'!$B$9>0,INDEX($B$9:$M$9,1,MAX(1,9-'Вводные'!$B$9)),0) -> 400000 | K37: =IF(10-'Вводные'!$B$9>0,INDEX($B$9:$M$9,1,MAX(1,10-'Вводные'!$B$9)),0) -> 400000 | L37: =IF(11-'Вводные'!$B$9>0,INDEX($B$9:$M$9,1,MAX(1,11-'Вводные'!$B$9)),0) -> 400000 | M37: =IF(12-'Вводные'!$B$9>0,INDEX($B$9:$M$9,1,MAX(1,12-'Вводные'!$B$9)),0) -> 400000 | N37: =SUM(B37:M37) -> 4000000 | O37: Денежный поток
A38: Дебиторская задолженность | B38: =(0+(B8-B36)) -> 1000000 | C38: =(B38+(C8-C36)) -> 1000000 | D38: =(C38+(D8-D36)) -> 1000000 | E38: =(D38+(E8-E36)) -> 1000000 | F38: =(E38+(F8-F36)) -> 1000000 | G38: =(F38+(G8-G36)) -> 1000000 | H38: =(G38+(H8-H36)) -> 1000000 | I38: =(H38+(I8-I36)) -> 1000000 | J38: =(I38+(J8-J36)) -> 1000000 | ... M38: =(L38+(M8-M36)) -> 1000000 | N38: =M38 -> 1000000 | O38: Оборотный капитал
A39: Кредиторская задолженность | B39: =(0+(B9-B37)) -> 400000 | C39: =(B39+(C9-C37)) -> 800000 | D39: =(C39+(D9-D37)) -> 800000 | E39: =(D39+(E9-E37)) -> 800000 | F39: =(E39+(F9-F37)) -> 800000 | G39: =(F39+(G9-G37)) -> 800000 | H39: =(G39+(H9-H37)) -> 800000 | I39: =(H39+(I9-I37)) -> 800000 | J39: =(I39+(J9-J37)) -> 800000 | ... M39: =(L39+(M9-M37)) -> 800000 | N39: =M39 -> 800000 | O39: Оборотный капитал
A40: Операционный денежный поток | B40: =((B36-B37)-((B21+B29)+B33)) -> -81200 | C40: =((C36-C37)-((C21+C29)+C33)) -> 918894.62 | D40: =((D36-D37)-((D21+D29)+D33)) -> 418990.18 | E40: =((E36-E37)-((E21+E29)+E33)) -> 519086.7 | F40: =((F36-F37)-((F21+F29)+F33)) -> 519184.19 | G40: =((G36-G37)-((G21+G29)+G33)) -> 519282.65 | H40: =((H36-H37)-((H21+H29)+H33)) -> 519382.09 | I40: =((I36-I37)-((I21+I29)+I33)) -> 519482.53 | ... M40: =((M36-M37)-((M21+M29)+M33)) -> 519894.44 | N40: =SUM(B40:M40) -> 5932057.7 | O40: Оплата клиентов − оплаченная себестоимость − операционные расходы − проценты − налог. Без амортизации.
...

Sheet Вводные
A1: ВВОДНЫЕ / Мой бизнес
A2: Редактируйте колонку B. Суммы в KZT. Проценты задаются числом: 10 = 10%.
A3: Параметр | B3: Значение | C3: Пояснение
A4: Способ ввода выручки | B4: manual | C4: items — товары; manual — ручной оборот
A5: Себестоимость ручного оборота, % | B5: 40
A6: База условного налога | B6: revenue | C6: profit — прибыль; revenue — оборот; none — без налога
A7: Ставка налога, % | B7: 3
A8: Оплата клиентов через, мес. | B8: 1 | C8: Целые месяцы от 0 до 12
A9: Оплата себестоимости через, мес. | B9: 2 | C9: Целые месяцы от 0 до 12
A10: Деньги на начало | B10: 100000
A11: Взнос собственника до М1 | B11: 0
A12: Вложения до М1 | B12: 0
A13: Амортизация начальных вложений, мес. (0 — нет) | B13: 0 | C13: 0 отключает амортизацию начальных вложений
A14: Кредит до М1 | B14: 120000
A15: Годовая ставка кредита, % | B15: 12
A16: Срок кредита, мес. | B16: 12
A17: Множитель сценария | B17: 1 | C17: База: 1; осторожный: 0.8; оптимистичный: 1.2
A18: Ручной оборот · М1 | B18: 1000000
A19: Ручной оборот · М2 | B19: 1000000
A20: Ручной оборот · М3 | B20: 1000000
A21: Ручной оборот · М4 | B21: 1000000
A22: Ручной оборот · М5 | B22: 1000000
A23: Ручной оборот · М6 | B23: 1000000
A24: Ручной оборот · М7 | B24: 1000000
A25: Ручной оборот · М8 | B25: 1000000
A26: Ручной оборот · М9 | B26: 1000000
A27: Ручной оборот · М10 | B27: 1000000
A28: Ручной оборот · М11 | B28: 1000000
A29: Ручной оборот · М12 | B29: 1000000
A30: Основной продукт · Название | B30: Основной продукт
A31: Основной продукт · Количество в первый активный месяц | B31: 300
A32: Основной продукт · Цена | B32: 8500
A33: Основной продукт · Рост в месяц, % | B33: 4
A34: Основной продукт · Себестоимость, % выручки | B34: 35
A35: Основной продукт · С месяца | B35: 1
A36: Основной продукт · По месяц | B36: 12
A37: Комиссия · Название | B37: Комиссия
A38: Комиссия · Способ расчёта | B38: percent | C38: fixed — сумма; percent — % оборота; once — один раз
A39: Комиссия · Сумма или ставка | B39: 5
A40: Комиссия · Рост в месяц, % | B40: 0
...
