Workbook

Sheet Модель
A1: КОНТУР / Мой бизнес
A2: Базовый · KZT · 12 месяцев. Потоки — сумма; остатки — на конец М12.
A3: Чистая прибыль | B3: =N39 -> 12514745 | D3: Выручка | E3: =N8 -> 38315804 | G3: Деньги на конец | H3: =M47 -> 11514745
A4: Показатель | B4: М1 | C4: М2 | D4: М3 | E4: М4 | F4: М5 | G4: М6 | H4: М7 | I4: М8 | J4: М9 | K4: М10 | L4: М11 | M4: М12 | N4: Год / конец | O4: Как считается
A5: Основной продукт · количество | B5: =IF(AND((1>='Вводные'!$B$35),(1<='Вводные'!$B$36)),(('Вводные'!$B$31*'Вводные'!$B$17)*((1+('Вводные'!$B$33/100))^MAX(0,(1-'Вводные'!$B$35)))),0) -> 300 | C5: =IF(AND((2>='Вводные'!$B$35),(2<='Вводные'!$B$36)),(('Вводные'!$B$31*'Вводные'!$B$17)*((1+('Вводные'!$B$33/100))^MAX(0,(2-'Вводные'!$B$35)))),0) -> 312 | D5: =IF(AND((3>='Вводные'!$B$35),(3<='Вводные'!$B$36)),(('Вводные'!$B$31*'Вводные'!$B$17)*((1+('Вводные'!$B$33/100))^MAX(0,(3-'Вводные'!$B$35)))),0) -> 324.48 | E5: =IF(AND((4>='Вводные'!$B$35),(4<='Вводные'!$B$36)),(('Вводные'!$B$31*'Вводные'!$B$17)*((1+('Вводные'!$B$33/100))^MAX(0,(4-'Вводные'!$B$35)))),0) -> 337.4592 | F5: =IF(AND((5>='Вводные'!$B$35),(5<='Вводные'!$B$36)),(('Вводные'!$B$31*'Вводные'!$B$17)*((1+('Вводные'!$B$33/100))^MAX(0,(5-'Вводные'!$B$35)))),0) -> 350.95757 | G5: =IF(AND((6>='Вводные'!$B$35),(6<='Вводные'!$B$36)),(('Вводные'!$B$31*'Вводные'!$B$17)*((1+('Вводные'!$B$33/100))^MAX(0,(6-'Вводные'!$B$35)))),0) -> 364.99587 | H5: =IF(AND((7>='Вводные'!$B$35),(7<='Вводные'!$B$36)),(('Вводные'!$B$31*'Вводные'!$B$17)*((1+('Вводные'!$B$33/100))^MAX(0,(7-'Вводные'!$B$35)))),0) -> 379.59571 | I5: =IF(AND((8>='Вводные'!$B$35),(8<='Вводные'!$B$36)),(('Вводные'!$B$31*'Вводные'!$B$17)*((1+('Вводные'!$B$33/100))^MAX(0,(8-'Вводные'!$B$35)))),0) -> 394.77953 | J5: =IF(AND((9>='Вводные'!$B$35),(9<='Вводные'!$B$36)),(('Вводные'!$B$31*'Вводные'!$B$17)*((1+('Вводные'!$B$33/100))^MAX(0,(9-'Вводные'!$B$35)))),0) -> 410.57072 | K5: =IF(AND((10>='Вводные'!$B$35),(10<='Вводные'!$B$36)),(('Вводные'!$B$31*'Вводные'!$B$17)*((1+('Вводные'!$B$33/100))^MAX(0,(10-'Вводные'!$B$35)))),0) -> 426.99354 | L5: =IF(AND((11>='Вводные'!$B$35),(11<='Вводные'!$B$36)),(('Вводные'!$B$31*'Вводные'!$B$17)*((1+('Вводные'!$B$33/100))^MAX(0,(11-'Вводные'!$B$35)))),0) -> 444.07329 | M5: =IF(AND((12>='Вводные'!$B$35),(12<='Вводные'!$B$36)),(('Вводные'!$B$31*'Вводные'!$B$17)*((1+('Вводные'!$B$33/100))^MAX(0,(12-'Вводные'!$B$35)))),0) -> 461.83622 | N5: =SUM(B5:M5) -> 4507.7416 | O5: Продажи
A6: Основной продукт · выручка | B6: =(B5*'Вводные'!$B$32) -> 2550000 | C6: =(C5*'Вводные'!$B$32) -> 2652000 | D6: =(D5*'Вводные'!$B$32) -> 2758080 | E6: =(E5*'Вводные'!$B$32) -> 2868403.2 | F6: =(F5*'Вводные'!$B$32) -> 2983139.3 | G6: =(G5*'Вводные'!$B$32) -> 3102464.9 | H6: =(H5*'Вводные'!$B$32) -> 3226563.5 | I6: =(I5*'Вводные'!$B$32) -> 3355626 | ... M6: =(M5*'Вводные'!$B$32) -> 3925607.8 | N6: =SUM(B6:M6) -> 38315804 | O6: Продажи
A7: Основной продукт · себестоимость | B7: =(B6*('Вводные'!$B$34/100)) -> 892500 | C7: =(C6*('Вводные'!$B$34/100)) -> 928200 | D7: =(D6*('Вводные'!$B$34/100)) -> 965328 | E7: =(E6*('Вводные'!$B$34/100)) -> 1003941.1 | F7: =(F6*('Вводные'!$B$34/100)) -> 1044098.8 | G7: =(G6*('Вводные'!$B$34/100)) -> 1085862.7 | H7: =(H6*('Вводные'!$B$34/100)) -> 1129297.2 | I7: =(I6*('Вводные'!$B$34/100)) -> 1174469.1 | ... M7: =(M6*('Вводные'!$B$34/100)) -> 1373962.7 | N7: =SUM(B7:M7) -> 13410531 | O7: Продажи
A8: Выручка / оборот | B8: =IF(('Вводные'!$B$4="manual"),('Вводные'!$B$18*'Вводные'!$B$17),B6) -> 2550000 | C8: =IF(('Вводные'!$B$4="manual"),('Вводные'!$B$19*'Вводные'!$B$17),C6) -> 2652000 | D8: =IF(('Вводные'!$B$4="manual"),('Вводные'!$B$20*'Вводные'!$B$17),D6) -> 2758080 | E8: =IF(('Вводные'!$B$4="manual"),('Вводные'!$B$21*'Вводные'!$B$17),E6) -> 2868403.2 | F8: =IF(('Вводные'!$B$4="manual"),('Вводные'!$B$22*'Вводные'!$B$17),F6) -> 2983139.3 | G8: =IF(('Вводные'!$B$4="manual"),('Вводные'!$B$23*'Вводные'!$B$17),G6) -> 3102464.9 | H8: =IF(('Вводные'!$B$4="manual"),('Вводные'!$B$24*'Вводные'!$B$17),H6) -> 3226563.5 | I8: =IF(('Вводные'!$B$4="manual"),('Вводные'!$B$25*'Вводные'!$B$17),I6) -> 3355626 | J8: =IF(('Вводные'!$B$4="manual"),('Вводные'!$B$26*'Вводные'!$B$17),J6) -> 3489851.1 | K8: =IF(('Вводные'!$B$4="manual"),('Вводные'!$B$27*'Вводные'!$B$17),K6) -> 3629445.1 | L8: =IF(('Вводные'!$B$4="manual"),('Вводные'!$B$28*'Вводные'!$B$17),L6) -> 3774622.9 | M8: =IF(('Вводные'!$B$4="manual"),('Вводные'!$B$29*'Вводные'!$B$17),M6) -> 3925607.8 | N8: =SUM(B8:M8) -> 38315804 | O8: По продуктам: количество × цена. Вручную: введённый оборот. Сценарий применяется один раз.
A9: Себестоимость продаж | B9: =IF(('Вводные'!$B$4="manual"),(B8*('Вводные'!$B$5/100)),B7) -> 892500 | C9: =IF(('Вводные'!$B$4="manual"),(C8*('Вводные'!$B$5/100)),C7) -> 928200 | D9: =IF(('Вводные'!$B$4="manual"),(D8*('Вводные'!$B$5/100)),D7) -> 965328 | E9: =IF(('Вводные'!$B$4="manual"),(E8*('Вводные'!$B$5/100)),E7) -> 1003941.1 | F9: =IF(('Вводные'!$B$4="manual"),(F8*('Вводные'!$B$5/100)),F7) -> 1044098.8 | G9: =IF(('Вводные'!$B$4="manual"),(G8*('Вводные'!$B$5/100)),G7) -> 1085862.7 | H9: =IF(('Вводные'!$B$4="manual"),(H8*('Вводные'!$B$5/100)),H7) -> 1129297.2 | I9: =IF(('Вводные'!$B$4="manual"),(I8*('Вводные'!$B$5/100)),I7) -> 1174469.1 | ... M9: =IF(('Вводные'!$B$4="manual"),(M8*('Вводные'!$B$5/100)),M7) -> 1373962.7 | N9: =SUM(B9:M9) -> 13410531 | O9: Себестоимость продуктов или доля ручного оборота. Не дублируйте её в прочих расходах.
A10: Валовая прибыль | B10: =(B8-B9) -> 1657500 | C10: =(C8-C9) -> 1723800 | D10: =(D8-D9) -> 1792752 | E10: =(E8-E9) -> 1864462.1 | F10: =(F8-F9) -> 1939040.6 | G10: =(G8-G9) -> 2016602.2 | H10: =(H8-H9) -> 2097266.3 | I10: =(I8-I9) -> 2181156.9 | ... M10: =(M8-M9) -> 2551645.1 | N10: =SUM(B10:M10) -> 24905273 | O10: Выручка − себестоимость.
A11: Менеджер · оклады и бонусы | B11: =IF(AND((1>='Вводные'!$B$43),(1<='Вводные'!$B$44)),(('Вводные'!$B$38*('Вводные'!$B$39+'Вводные'!$B$40))*((1+('Вводные'!$B$42/100))^MAX(0,(1-'Вводные'!$B$43)))),0) -> 300000 | C11: =IF(AND((2>='Вводные'!$B$43),(2<='Вводные'!$B$44)),(('Вводные'!$B$38*('Вводные'!$B$39+'Вводные'!$B$40))*((1+('Вводные'!$B$42/100))^MAX(0,(2-'Вводные'!$B$43)))),0) -> 300000 | D11: =IF(AND((3>='Вводные'!$B$43),(3<='Вводные'!$B$44)),(('Вводные'!$B$38*('Вводные'!$B$39+'Вводные'!$B$40))*((1+('Вводные'!$B$42/100))^MAX(0,(3-'Вводные'!$B$43)))),0) -> 300000 | E11: =IF(AND((4>='Вводные'!$B$43),(4<='Вводные'!$B$44)),(('Вводные'!$B$38*('Вводные'!$B$39+'Вводные'!$B$40))*((1+('Вводные'!$B$42/100))^MAX(0,(4-'Вводные'!$B$43)))),0) -> 300000 | F11: =IF(AND((5>='Вводные'!$B$43),(5<='Вводные'!$B$44)),(('Вводные'!$B$38*('Вводные'!$B$39+'Вводные'!$B$40))*((1+('Вводные'!$B$42/100))^MAX(0,(5-'Вводные'!$B$43)))),0) -> 300000 | G11: =IF(AND((6>='Вводные'!$B$43),(6<='Вводные'!$B$44)),(('Вводные'!$B$38*('Вводные'!$B$39+'Вводные'!$B$40))*((1+('Вводные'!$B$42/100))^MAX(0,(6-'Вводные'!$B$43)))),0) -> 300000 | H11: =IF(AND((7>='Вводные'!$B$43),(7<='Вводные'!$B$44)),(('Вводные'!$B$38*('Вводные'!$B$39+'Вводные'!$B$40))*((1+('Вводные'!$B$42/100))^MAX(0,(7-'Вводные'!$B$43)))),0) -> 300000 | I11: =IF(AND((8>='Вводные'!$B$43),(8<='Вводные'!$B$44)),(('Вводные'!$B$38*('Вводные'!$B$39+'Вводные'!$B$40))*((1+('Вводные'!$B$42/100))^MAX(0,(8-'Вводные'!$B$43)))),0) -> 300000 | J11: =IF(AND((9>='Вводные'!$B$43),(9<='Вводные'!$B$44)),(('Вводные'!$B$38*('Вводные'!$B$39+'Вводные'!$B$40))*((1+('Вводные'!$B$42/100))^MAX(0,(9-'Вводные'!$B$43)))),0) -> 300000 | K11: =IF(AND((10>='Вводные'!$B$43),(10<='Вводные'!$B$44)),(('Вводные'!$B$38*('Вводные'!$B$39+'Вводные'!$B$40))*((1+('Вводные'!$B$42/100))^MAX(0,(10-'Вводные'!$B$43)))),0) -> 300000 | L11: =IF(AND((11>='Вводные'!$B$43),(11<='Вводные'!$B$44)),(('Вводные'!$B$38*('Вводные'!$B$39+'Вводные'!$B$40))*((1+('Вводные'!$B$42/100))^MAX(0,(11-'Вводные'!$B$43)))),0) -> 300000 | M11: =IF(AND((12>='Вводные'!$B$43),(12<='Вводные'!$B$44)),(('Вводные'!$B$38*('Вводные'!$B$39+'Вводные'!$B$40))*((1+('Вводные'!$B$42/100))^MAX(0,(12-'Вводные'!$B$43)))),0) -> 300000 | N11: =SUM(B11:M11) -> 3600000 | O11: Команда
A12: Менеджер · начисления | B12: =(B11*('Вводные'!$B$41/100)) -> 45000 | C12: =(C11*('Вводные'!$B$41/100)) -> 45000 | D12: =(D11*('Вводные'!$B$41/100)) -> 45000 | E12: =(E11*('Вводные'!$B$41/100)) -> 45000 | F12: =(F11*('Вводные'!$B$41/100)) -> 45000 | G12: =(G11*('Вводные'!$B$41/100)) -> 45000 | H12: =(H11*('Вводные'!$B$41/100)) -> 45000 | I12: =(I11*('Вводные'!$B$41/100)) -> 45000 | ... M12: =(M11*('Вводные'!$B$41/100)) -> 45000 | N12: =SUM(B12:M12) -> 540000 | O12: Команда
A13: Оклады и бонусы | B13: =B11 -> 300000 | C13: =C11 -> 300000 | D13: =D11 -> 300000 | E13: =E11 -> 300000 | F13: =F11 -> 300000 | G13: =G11 -> 300000 | H13: =H11 -> 300000 | I13: =I11 -> 300000 | ... M13: =M11 -> 300000 | N13: =SUM(B13:M13) -> 3600000 | O13: Команда
A14: Начисления работодателя | B14: =B12 -> 45000 | C14: =C12 -> 45000 | D14: =D12 -> 45000 | E14: =E12 -> 45000 | F14: =F12 -> 45000 | G14: =G12 -> 45000 | H14: =H12 -> 45000 | I14: =I12 -> 45000 | ... M14: =M12 -> 45000 | N14: =SUM(B14:M14) -> 540000 | O14: Команда
A15: Команда — всего | B15: =(B13+B14) -> 345000 | C15: =(C13+C14) -> 345000 | D15: =(D13+D14) -> 345000 | E15: =(E13+E14) -> 345000 | F15: =(F13+F14) -> 345000 | G15: =(G13+G14) -> 345000 | H15: =(H13+H14) -> 345000 | I15: =(I13+I14) -> 345000 | ... M15: =(M13+M14) -> 345000 | N15: =SUM(B15:M15) -> 4140000 | O15: Количество × (оклад + бонус) × рост × (1 + начисления). Ставки задаёте вы.
A16: Реклама · затраты | B16: =IF(AND((1>='Вводные'!$B$53),(1<='Вводные'!$B$54)),(('Вводные'!$B$46*((1+('Вводные'!$B$48/100))^MAX(0,(1-'Вводные'!$B$53))))+(B8*('Вводные'!$B$47/100))),0) -> 120000 | C16: =IF(AND((2>='Вводные'!$B$53),(2<='Вводные'!$B$54)),(('Вводные'!$B$46*((1+('Вводные'!$B$48/100))^MAX(0,(2-'Вводные'!$B$53))))+(C8*('Вводные'!$B$47/100))),0) -> 120000 | D16: =IF(AND((3>='Вводные'!$B$53),(3<='Вводные'!$B$54)),(('Вводные'!$B$46*((1+('Вводные'!$B$48/100))^MAX(0,(3-'Вводные'!$B$53))))+(D8*('Вводные'!$B$47/100))),0) -> 120000 | E16: =IF(AND((4>='Вводные'!$B$53),(4<='Вводные'!$B$54)),(('Вводные'!$B$46*((1+('Вводные'!$B$48/100))^MAX(0,(4-'Вводные'!$B$53))))+(E8*('Вводные'!$B$47/100))),0) -> 120000 | F16: =IF(AND((5>='Вводные'!$B$53),(5<='Вводные'!$B$54)),(('Вводные'!$B$46*((1+('Вводные'!$B$48/100))^MAX(0,(5-'Вводные'!$B$53))))+(F8*('Вводные'!$B$47/100))),0) -> 120000 | G16: =IF(AND((6>='Вводные'!$B$53),(6<='Вводные'!$B$54)),(('Вводные'!$B$46*((1+('Вводные'!$B$48/100))^MAX(0,(6-'Вводные'!$B$53))))+(G8*('Вводные'!$B$47/100))),0) -> 120000 | H16: =IF(AND((7>='Вводные'!$B$53),(7<='Вводные'!$B$54)),(('Вводные'!$B$46*((1+('Вводные'!$B$48/100))^MAX(0,(7-'Вводные'!$B$53))))+(H8*('Вводные'!$B$47/100))),0) -> 120000 | I16: =IF(AND((8>='Вводные'!$B$53),(8<='Вводные'!$B$54)),(('Вводные'!$B$46*((1+('Вводные'!$B$48/100))^MAX(0,(8-'Вводные'!$B$53))))+(I8*('Вводные'!$B$47/100))),0) -> 120000 | J16: =IF(AND((9>='Вводные'!$B$53),(9<='Вводные'!$B$54)),(('Вводные'!$B$46*((1+('Вводные'!$B$48/100))^MAX(0,(9-'Вводные'!$B$53))))+(J8*('Вводные'!$B$47/100))),0) -> 120000 | K16: =IF(AND((10>='Вводные'!$B$53),(10<='Вводные'!$B$54)),(('Вводные'!$B$46*((1+('Вводные'!$B$48/100))^MAX(0,(10-'Вводные'!$B$53))))+(K8*('Вводные'!$B$47/100))),0) -> 120000 | L16: =IF(AND((11>='Вводные'!$B$53),(11<='Вводные'!$B$54)),(('Вводные'!$B$46*((1+('Вводные'!$B$48/100))^MAX(0,(11-'Вводные'!$B$53))))+(L8*('Вводные'!$B$47/100))),0) -> 120000 | M16: =IF(AND((12>='Вводные'!$B$53),(12<='Вводные'!$B$54)),(('Вводные'!$B$46*((1+('Вводные'!$B$48/100))^MAX(0,(12-'Вводные'!$B$53))))+(M8*('Вводные'!$B$47/100))),0) -> 120000 | N16: =SUM(B16:M16) -> 1440000 | O16: Маркетинг
A17: Реклама · клики | B17: =IF(('Вводные'!$B$49>0),(B16/'Вводные'!$B$49),0) -> 800 | C17: =IF(('Вводные'!$B$49>0),(C16/'Вводные'!$B$49),0) -> 800 | D17: =IF(('Вводные'!$B$49>0),(D16/'Вводные'!$B$49),0) -> 800 | E17: =IF(('Вводные'!$B$49>0),(E16/'Вводные'!$B$49),0) -> 800 | F17: =IF(('Вводные'!$B$49>0),(F16/'Вводные'!$B$49),0) -> 800 | G17: =IF(('Вводные'!$B$49>0),(G16/'Вводные'!$B$49),0) -> 800 | H17: =IF(('Вводные'!$B$49>0),(H16/'Вводные'!$B$49),0) -> 800 | I17: =IF(('Вводные'!$B$49>0),(I16/'Вводные'!$B$49),0) -> 800 | ... M17: =IF(('Вводные'!$B$49>0),(M16/'Вводные'!$B$49),0) -> 800 | N17: =SUM(B17:M17) -> 9600 | O17: Маркетинг
A18: Реклама · заявки | B18: =(B17*('Вводные'!$B$50/100)) -> 80 | C18: =(C17*('Вводные'!$B$50/100)) -> 80 | D18: =(D17*('Вводные'!$B$50/100)) -> 80 | E18: =(E17*('Вводные'!$B$50/100)) -> 80 | F18: =(F17*('Вводные'!$B$50/100)) -> 80 | G18: =(G17*('Вводные'!$B$50/100)) -> 80 | H18: =(H17*('Вводные'!$B$50/100)) -> 80 | I18: =(I17*('Вводные'!$B$50/100)) -> 80 | ... M18: =(M17*('Вводные'!$B$50/100)) -> 80 | N18: =SUM(B18:M18) -> 960 | O18: Маркетинг
A19: Реклама · клиенты | B19: =(B18*('Вводные'!$B$51/100)) -> 16 | C19: =(C18*('Вводные'!$B$51/100)) -> 16 | D19: =(D18*('Вводные'!$B$51/100)) -> 16 | E19: =(E18*('Вводные'!$B$51/100)) -> 16 | F19: =(F18*('Вводные'!$B$51/100)) -> 16 | G19: =(G18*('Вводные'!$B$51/100)) -> 16 | H19: =(H18*('Вводные'!$B$51/100)) -> 16 | I19: =(I18*('Вводные'!$B$51/100)) -> 16 | ... M19: =(M18*('Вводные'!$B$51/100)) -> 16 | N19: =SUM(B19:M19) -> 192 | O19: Маркетинг
A20: Реклама · оценка выручки | B20: =(B19*'Вводные'!$B$52) -> 136000 | C20: =(C19*'Вводные'!$B$52) -> 136000 | D20: =(D19*'Вводные'!$B$52) -> 136000 | E20: =(E19*'Вводные'!$B$52) -> 136000 | F20: =(F19*'Вводные'!$B$52) -> 136000 | G20: =(G19*'Вводные'!$B$52) -> 136000 | H20: =(H19*'Вводные'!$B$52) -> 136000 | I20: =(I19*'Вводные'!$B$52) -> 136000 | ... M20: =(M19*'Вводные'!$B$52) -> 136000 | N20: =SUM(B20:M20) -> 1632000 | O20: Маркетинг
A21: Маркетинг — всего | B21: =B16 -> 120000 | C21: =C16 -> 120000 | D21: =D16 -> 120000 | E21: =E16 -> 120000 | F21: =F16 -> 120000 | G21: =G16 -> 120000 | H21: =H16 -> 120000 | I21: =I16 -> 120000 | ... M21: =M16 -> 120000 | N21: =SUM(B21:M21) -> 1440000 | O21: Бюджеты каналов + процент от выручки. Продажи из воронки уже должны входить в общий оборот.
A22: Заявки из рекламы, шт. | B22: =B18 -> 80 | C22: =C18 -> 80 | D22: =D18 -> 80 | E22: =E18 -> 80 | F22: =F18 -> 80 | G22: =G18 -> 80 | H22: =H18 -> 80 | I22: =I18 -> 80 | ... M22: =M18 -> 80 | N22: =SUM(B22:M22) -> 960 | O22: Маркетинг
A23: Клиенты из рекламы, шт. | B23: =B19 -> 16 | C23: =C19 -> 16 | D23: =D19 -> 16 | E23: =E19 -> 16 | F23: =F19 -> 16 | G23: =G19 -> 16 | H23: =H19 -> 16 | I23: =I19 -> 16 | ... M23: =M19 -> 16 | N23: =SUM(B23:M23) -> 192 | O23: Маркетинг
A24: Оценка выручки из рекламы | B24: =B20 -> 136000 | C24: =C20 -> 136000 | D24: =D20 -> 136000 | E24: =E20 -> 136000 | F24: =F20 -> 136000 | G24: =G20 -> 136000 | H24: =H20 -> 136000 | I24: =I20 -> 136000 | ... M24: =M20 -> 136000 | N24: =SUM(B24:M24) -> 1632000 | O24: Клиенты × чек каждого канала. Не прибавляется к обороту, чтобы не считать продажи дважды.
A25: Аренда | B25: =IF(AND(AND((1>='Вводные'!$B$59),(1<='Вводные'!$B$60)),IF(('Вводные'!$B$56="once"),(1='Вводные'!$B$59),TRUE)),IF(('Вводные'!$B$56="percent"),(B8*('Вводные'!$B$57/100)),('Вводные'!$B$57*((1+('Вводные'!$B$58/100))^MAX(0,(1-'Вводные'!$B$59))))),0) -> 250000 | C25: =IF(AND(AND((2>='Вводные'!$B$59),(2<='Вводные'!$B$60)),IF(('Вводные'!$B$56="once"),(2='Вводные'!$B$59),TRUE)),IF(('Вводные'!$B$56="percent"),(C8*('Вводные'!$B$57/100)),('Вводные'!$B$57*((1+('Вводные'!$B$58/100))^MAX(0,(2-'Вводные'!$B$59))))),0) -> 250000 | D25: =IF(AND(AND((3>='Вводные'!$B$59),(3<='Вводные'!$B$60)),IF(('Вводные'!$B$56="once"),(3='Вводные'!$B$59),TRUE)),IF(('Вводные'!$B$56="percent"),(D8*('Вводные'!$B$57/100)),('Вводные'!$B$57*((1+('Вводные'!$B$58/100))^MAX(0,(3-'Вводные'!$B$59))))),0) -> 250000 | E25: =IF(AND(AND((4>='Вводные'!$B$59),(4<='Вводные'!$B$60)),IF(('Вводные'!$B$56="once"),(4='Вводные'!$B$59),TRUE)),IF(('Вводные'!$B$56="percent"),(E8*('Вводные'!$B$57/100)),('Вводные'!$B$57*((1+('Вводные'!$B$58/100))^MAX(0,(4-'Вводные'!$B$59))))),0) -> 250000 | F25: =IF(AND(AND((5>='Вводные'!$B$59),(5<='Вводные'!$B$60)),IF(('Вводные'!$B$56="once"),(5='Вводные'!$B$59),TRUE)),IF(('Вводные'!$B$56="percent"),(F8*('Вводные'!$B$57/100)),('Вводные'!$B$57*((1+('Вводные'!$B$58/100))^MAX(0,(5-'Вводные'!$B$59))))),0) -> 250000 | G25: =IF(AND(AND((6>='Вводные'!$B$59),(6<='Вводные'!$B$60)),IF(('Вводные'!$B$56="once"),(6='Вводные'!$B$59),TRUE)),IF(('Вводные'!$B$56="percent"),(G8*('Вводные'!$B$57/100)),('Вводные'!$B$57*((1+('Вводные'!$B$58/100))^MAX(0,(6-'Вводные'!$B$59))))),0) -> 250000 | H25: =IF(AND(AND((7>='Вводные'!$B$59),(7<='Вводные'!$B$60)),IF(('Вводные'!$B$56="once"),(7='Вводные'!$B$59),TRUE)),IF(('Вводные'!$B$56="percent"),(H8*('Вводные'!$B$57/100)),('Вводные'!$B$57*((1+('Вводные'!$B$58/100))^MAX(0,(7-'Вводные'!$B$59))))),0) -> 250000 | I25: =IF(AND(AND((8>='Вводные'!$B$59),(8<='Вводные'!$B$60)),IF(('Вводные'!$B$56="once"),(8='Вводные'!$B$59),TRUE)),IF(('Вводные'!$B$56="percent"),(I8*('Вводные'!$B$57/100)),('Вводные'!$B$57*((1+('Вводные'!$B$58/100))^MAX(0,(8-'Вводные'!$B$59))))),0) -> 250000 | J25: =IF(AND(AND((9>='Вводные'!$B$59),(9<='Вводные'!$B$60)),IF(('Вводные'!$B$56="once"),(9='Вводные'!$B$59),TRUE)),IF(('Вводные'!$B$56="percent"),(J8*('Вводные'!$B$57/100)),('Вводные'!$B$57*((1+('Вводные'!$B$58/100))^MAX(0,(9-'Вводные'!$B$59))))),0) -> 250000 | K25: =IF(AND(AND((10>='Вводные'!$B$59),(10<='Вводные'!$B$60)),IF(('Вводные'!$B$56="once"),(10='Вводные'!$B$59),TRUE)),IF(('Вводные'!$B$56="percent"),(K8*('Вводные'!$B$57/100)),('Вводные'!$B$57*((1+('Вводные'!$B$58/100))^MAX(0,(10-'Вводные'!$B$59))))),0) -> 250000 | L25: =IF(AND(AND((11>='Вводные'!$B$59),(11<='Вводные'!$B$60)),IF(('Вводные'!$B$56="once"),(11='Вводные'!$B$59),TRUE)),IF(('Вводные'!$B$56="percent"),(L8*('Вводные'!$B$57/100)),('Вводные'!$B$57*((1+('Вводные'!$B$58/100))^MAX(0,(11-'Вводные'!$B$59))))),0) -> 250000 | M25: =IF(AND(AND((12>='Вводные'!$B$59),(12<='Вводные'!$B$60)),IF(('Вводные'!$B$56="once"),(12='Вводные'!$B$59),TRUE)),IF(('Вводные'!$B$56="percent"),(M8*('Вводные'!$B$57/100)),('Вводные'!$B$57*((1+('Вводные'!$B$58/100))^MAX(0,(12-'Вводные'!$B$59))))),0) -> 250000 | N25: =SUM(B25:M25) -> 3000000 | O25: Прочие расходы
A26: Сервисы и связь | B26: =IF(AND(AND((1>='Вводные'!$B$65),(1<='Вводные'!$B$66)),IF(('Вводные'!$B$62="once"),(1='Вводные'!$B$65),TRUE)),IF(('Вводные'!$B$62="percent"),(B8*('Вводные'!$B$63/100)),('Вводные'!$B$63*((1+('Вводные'!$B$64/100))^MAX(0,(1-'Вводные'!$B$65))))),0) -> 35000 | C26: =IF(AND(AND((2>='Вводные'!$B$65),(2<='Вводные'!$B$66)),IF(('Вводные'!$B$62="once"),(2='Вводные'!$B$65),TRUE)),IF(('Вводные'!$B$62="percent"),(C8*('Вводные'!$B$63/100)),('Вводные'!$B$63*((1+('Вводные'!$B$64/100))^MAX(0,(2-'Вводные'!$B$65))))),0) -> 35000 | D26: =IF(AND(AND((3>='Вводные'!$B$65),(3<='Вводные'!$B$66)),IF(('Вводные'!$B$62="once"),(3='Вводные'!$B$65),TRUE)),IF(('Вводные'!$B$62="percent"),(D8*('Вводные'!$B$63/100)),('Вводные'!$B$63*((1+('Вводные'!$B$64/100))^MAX(0,(3-'Вводные'!$B$65))))),0) -> 35000 | E26: =IF(AND(AND((4>='Вводные'!$B$65),(4<='Вводные'!$B$66)),IF(('Вводные'!$B$62="once"),(4='Вводные'!$B$65),TRUE)),IF(('Вводные'!$B$62="percent"),(E8*('Вводные'!$B$63/100)),('Вводные'!$B$63*((1+('Вводные'!$B$64/100))^MAX(0,(4-'Вводные'!$B$65))))),0) -> 35000 | F26: =IF(AND(AND((5>='Вводные'!$B$65),(5<='Вводные'!$B$66)),IF(('Вводные'!$B$62="once"),(5='Вводные'!$B$65),TRUE)),IF(('Вводные'!$B$62="percent"),(F8*('Вводные'!$B$63/100)),('Вводные'!$B$63*((1+('Вводные'!$B$64/100))^MAX(0,(5-'Вводные'!$B$65))))),0) -> 35000 | G26: =IF(AND(AND((6>='Вводные'!$B$65),(6<='Вводные'!$B$66)),IF(('Вводные'!$B$62="once"),(6='Вводные'!$B$65),TRUE)),IF(('Вводные'!$B$62="percent"),(G8*('Вводные'!$B$63/100)),('Вводные'!$B$63*((1+('Вводные'!$B$64/100))^MAX(0,(6-'Вводные'!$B$65))))),0) -> 35000 | H26: =IF(AND(AND((7>='Вводные'!$B$65),(7<='Вводные'!$B$66)),IF(('Вводные'!$B$62="once"),(7='Вводные'!$B$65),TRUE)),IF(('Вводные'!$B$62="percent"),(H8*('Вводные'!$B$63/100)),('Вводные'!$B$63*((1+('Вводные'!$B$64/100))^MAX(0,(7-'Вводные'!$B$65))))),0) -> 35000 | I26: =IF(AND(AND((8>='Вводные'!$B$65),(8<='Вводные'!$B$66)),IF(('Вводные'!$B$62="once"),(8='Вводные'!$B$65),TRUE)),IF(('Вводные'!$B$62="percent"),(I8*('Вводные'!$B$63/100)),('Вводные'!$B$63*((1+('Вводные'!$B$64/100))^MAX(0,(8-'Вводные'!$B$65))))),0) -> 35000 | J26: =IF(AND(AND((9>='Вводные'!$B$65),(9<='Вводные'!$B$66)),IF(('Вводные'!$B$62="once"),(9='Вводные'!$B$65),TRUE)),IF(('Вводные'!$B$62="percent"),(J8*('Вводные'!$B$63/100)),('Вводные'!$B$63*((1+('Вводные'!$B$64/100))^MAX(0,(9-'Вводные'!$B$65))))),0) -> 35000 | K26: =IF(AND(AND((10>='Вводные'!$B$65),(10<='Вводные'!$B$66)),IF(('Вводные'!$B$62="once"),(10='Вводные'!$B$65),TRUE)),IF(('Вводные'!$B$62="percent"),(K8*('Вводные'!$B$63/100)),('Вводные'!$B$63*((1+('Вводные'!$B$64/100))^MAX(0,(10-'Вводные'!$B$65))))),0) -> 35000 | L26: =IF(AND(AND((11>='Вводные'!$B$65),(11<='Вводные'!$B$66)),IF(('Вводные'!$B$62="once"),(11='Вводные'!$B$65),TRUE)),IF(('Вводные'!$B$62="percent"),(L8*('Вводные'!$B$63/100)),('Вводные'!$B$63*((1+('Вводные'!$B$64/100))^MAX(0,(11-'Вводные'!$B$65))))),0) -> 35000 | M26: =IF(AND(AND((12>='Вводные'!$B$65),(12<='Вводные'!$B$66)),IF(('Вводные'!$B$62="once"),(12='Вводные'!$B$65),TRUE)),IF(('Вводные'!$B$62="percent"),(M8*('Вводные'!$B$63/100)),('Вводные'!$B$63*((1+('Вводные'!$B$64/100))^MAX(0,(12-'Вводные'!$B$65))))),0) -> 35000 | N26: =SUM(B26:M26) -> 420000 | O26: Прочие расходы
A27: Прочие расходы — всего | B27: =(B25+B26) -> 285000 | C27: =(C25+C26) -> 285000 | D27: =(D25+D26) -> 285000 | E27: =(E25+E26) -> 285000 | F27: =(F25+F26) -> 285000 | G27: =(G25+G26) -> 285000 | H27: =(H25+H26) -> 285000 | I27: =(I25+I26) -> 285000 | ... M27: =(M25+M26) -> 285000 | N27: =SUM(B27:M27) -> 3420000 | O27: Результат
A28: Операционные расходы | B28: =((B15+B21)+B27) -> 750000 | C28: =((C15+C21)+C27) -> 750000 | D28: =((D15+D21)+D27) -> 750000 | E28: =((E15+E21)+E27) -> 750000 | F28: =((F15+F21)+F27) -> 750000 | G28: =((G15+G21)+G27) -> 750000 | H28: =((H15+H21)+H27) -> 750000 | I28: =((I15+I21)+I27) -> 750000 | ... M28: =((M15+M21)+M27) -> 750000 | N28: =SUM(B28:M28) -> 9000000 | O28: Команда + маркетинг + прочие расходы.
A29: EBITDA | B29: =(B10-B28) -> 907500 | C29: =(C10-C28) -> 973800 | D29: =(D10-D28) -> 1042752 | E29: =(E10-E28) -> 1114462.1 | F29: =(F10-F28) -> 1189040.6 | G29: =(G10-G28) -> 1266602.2 | H29: =(H10-H28) -> 1347266.3 | I29: =(I10-I28) -> 1431156.9 | ... M29: =(M10-M28) -> 1801645.1 | N29: =SUM(B29:M29) -> 15905273 | O29: Валовая прибыль − операционные расходы; до амортизации, процентов и налога.
A30: Покупка активов | B30: =0 -> 0 | C30: =0 -> 0 | D30: =0 -> 0 | E30: =0 -> 0 | F30: =0 -> 0 | G30: =0 -> 0 | H30: =0 -> 0 | I30: =0 -> 0 | ... M30: =0 -> 0 | N30: =SUM(B30:M30) -> 0 | O30: Денежный поток
A31: Амортизация | B31: =(IF(AND(('Вводные'!$B$13>0),(1<='Вводные'!$B$13)),('Вводные'!$B$12/MAX(1,'Вводные'!$B$13)),0)+0) -> 166666.67 | C31: =(IF(AND(('Вводные'!$B$13>0),(2<='Вводные'!$B$13)),('Вводные'!$B$12/MAX(1,'Вводные'!$B$13)),0)+0) -> 166666.67 | D31: =(IF(AND(('Вводные'!$B$13>0),(3<='Вводные'!$B$13)),('Вводные'!$B$12/MAX(1,'Вводные'!$B$13)),0)+0) -> 166666.67 | E31: =(IF(AND(('Вводные'!$B$13>0),(4<='Вводные'!$B$13)),('Вводные'!$B$12/MAX(1,'Вводные'!$B$13)),0)+0) -> 166666.67 | F31: =(IF(AND(('Вводные'!$B$13>0),(5<='Вводные'!$B$13)),('Вводные'!$B$12/MAX(1,'Вводные'!$B$13)),0)+0) -> 166666.67 | G31: =(IF(AND(('Вводные'!$B$13>0),(6<='Вводные'!$B$13)),('Вводные'!$B$12/MAX(1,'Вводные'!$B$13)),0)+0) -> 166666.67 | H31: =(IF(AND(('Вводные'!$B$13>0),(7<='Вводные'!$B$13)),('Вводные'!$B$12/MAX(1,'Вводные'!$B$13)),0)+0) -> 166666.67 | I31: =(IF(AND(('Вводные'!$B$13>0),(8<='Вводные'!$B$13)),('Вводные'!$B$12/MAX(1,'Вводные'!$B$13)),0)+0) -> 166666.67 | J31: =(IF(AND(('Вводные'!$B$13>0),(9<='Вводные'!$B$13)),('Вводные'!$B$12/MAX(1,'Вводные'!$B$13)),0)+0) -> 166666.67 | K31: =(IF(AND(('Вводные'!$B$13>0),(10<='Вводные'!$B$13)),('Вводные'!$B$12/MAX(1,'Вводные'!$B$13)),0)+0) -> 166666.67 | L31: =(IF(AND(('Вводные'!$B$13>0),(11<='Вводные'!$B$13)),('Вводные'!$B$12/MAX(1,'Вводные'!$B$13)),0)+0) -> 166666.67 | M31: =(IF(AND(('Вводные'!$B$13>0),(12<='Вводные'!$B$13)),('Вводные'!$B$12/MAX(1,'Вводные'!$B$13)),0)+0) -> 166666.67 | N31: =SUM(B31:M31) -> 2000000 | O31: Стоимость / срок в месяцах, начиная с месяца покупки. Покупка уменьшает деньги, амортизация — прибыль.
A32: Операционная прибыль (EBIT) | B32: =(B29-B31) -> 740833.33 | C32: =(C29-C31) -> 807133.33 | D32: =(D29-D31) -> 876085.33 | E32: =(E29-E31) -> 947795.41 | F32: =(F29-F31) -> 1022373.9 | G32: =(G29-G31) -> 1099935.5 | H32: =(H29-H31) -> 1180599.6 | I32: =(I29-I31) -> 1264490.3 | ... M32: =(M29-M31) -> 1634978.4 | N32: =SUM(B32:M32) -> 13905273 | O32: Результат
A33: Кредит на начало месяца | B33: =IF((1<='Вводные'!$B$16),MAX(0,IF(((('Вводные'!$B$15/100)/12)>0),(('Вводные'!$B$14*((1+(('Вводные'!$B$15/100)/12))^0))-(IF(((('Вводные'!$B$15/100)/12)>0),(('Вводные'!$B$14*(('Вводные'!$B$15/100)/12))/(1-((1+(('Вводные'!$B$15/100)/12))^(-1*'Вводные'!$B$16)))),('Вводные'!$B$14/'Вводные'!$B$16))*((((1+(('Вводные'!$B$15/100)/12))^0)-1)/(('Вводные'!$B$15/100)/12)))),('Вводные'!$B$14-(IF(((('Вводные'!$B$15/100)/12)>0),(('Вводные'!$B$14*(('Вводные'!$B$15/100)/12))/(1-((1+(('Вводные'!$B$15/100)/12))^(-1*'Вводные'!$B$16)))),('Вводные'!$B$14/'Вводные'!$B$16))*0)))),0) -> 0 | C33: =IF((2<='Вводные'!$B$16),MAX(0,IF(((('Вводные'!$B$15/100)/12)>0),(('Вводные'!$B$14*((1+(('Вводные'!$B$15/100)/12))^1))-(IF(((('Вводные'!$B$15/100)/12)>0),(('Вводные'!$B$14*(('Вводные'!$B$15/100)/12))/(1-((1+(('Вводные'!$B$15/100)/12))^(-1*'Вводные'!$B$16)))),('Вводные'!$B$14/'Вводные'!$B$16))*((((1+(('Вводные'!$B$15/100)/12))^1)-1)/(('Вводные'!$B$15/100)/12)))),('Вводные'!$B$14-(IF(((('Вводные'!$B$15/100)/12)>0),(('Вводные'!$B$14*(('Вводные'!$B$15/100)/12))/(1-((1+(('Вводные'!$B$15/100)/12))^(-1*'Вводные'!$B$16)))),('Вводные'!$B$14/'Вводные'!$B$16))*1)))),0) -> 0 | D33: =IF((3<='Вводные'!$B$16),MAX(0,IF(((('Вводные'!$B$15/100)/12)>0),(('Вводные'!$B$14*((1+(('Вводные'!$B$15/100)/12))^2))-(IF(((('Вводные'!$B$15/100)/12)>0),(('Вводные'!$B$14*(('Вводные'!$B$15/100)/12))/(1-((1+(('Вводные'!$B$15/100)/12))^(-1*'Вводные'!$B$16)))),('Вводные'!$B$14/'Вводные'!$B$16))*((((1+(('Вводные'!$B$15/100)/12))^2)-1)/(('Вводные'!$B$15/100)/12)))),('Вводные'!$B$14-(IF(((('Вводные'!$B$15/100)/12)>0),(('Вводные'!$B$14*(('Вводные'!$B$15/100)/12))/(1-((1+(('Вводные'!$B$15/100)/12))^(-1*'Вводные'!$B$16)))),('Вводные'!$B$14/'Вводные'!$B$16))*2)))),0) -> 0 | E33: =IF((4<='Вводные'!$B$16),MAX(0,IF(((('Вводные'!$B$15/100)/12)>0),(('Вводные'!$B$14*((1+(('Вводные'!$B$15/100)/12))^3))-(IF(((('Вводные'!$B$15/100)/12)>0),(('Вводные'!$B$14*(('Вводные'!$B$15/100)/12))/(1-((1+(('Вводные'!$B$15/100)/12))^(-1*'Вводные'!$B$16)))),('Вводные'!$B$14/'Вводные'!$B$16))*((((1+(('Вводные'!$B$15/100)/12))^3)-1)/(('Вводные'!$B$15/100)/12)))),('Вводные'!$B$14-(IF(((('Вводные'!$B$15/100)/12)>0),(('Вводные'!$B$14*(('Вводные'!$B$15/100)/12))/(1-((1+(('Вводные'!$B$15/100)/12))^(-1*'Вводные'!$B$16)))),('Вводные'!$B$14/'Вводные'!$B$16))*3)))),0) -> 0 | F33: =IF((5<='Вводные'!$B$16),MAX(0,IF(((('Вводные'!$B$15/100)/12)>0),(('Вводные'!$B$14*((1+(('Вводные'!$B$15/100)/12))^4))-(IF(((('Вводные'!$B$15/100)/12)>0),(('Вводные'!$B$14*(('Вводные'!$B$15/100)/12))/(1-((1+(('Вводные'!$B$15/100)/12))^(-1*'Вводные'!$B$16)))),('Вводные'!$B$14/'Вводные'!$B$16))*((((1+(('Вводные'!$B$15/100)/12))^4)-1)/(('Вводные'!$B$15/100)/12)))),('Вводные'!$B$14-(IF(((('Вводные'!$B$15/100)/12)>0),(('Вводные'!$B$14*(('Вводные'!$B$15/100)/12))/(1-((1+(('Вводные'!$B$15/100)/12))^(-1*'Вводные'!$B$16)))),('Вводные'!$B$14/'Вводные'!$B$16))*4)))),0) -> 0 | G33: =IF((6<='Вводные'!$B$16),MAX(0,IF(((('Вводные'!$B$15/100)/12)>0),(('Вводные'!$B$14*((1+(('Вводные'!$B$15/100)/12))^5))-(IF(((('Вводные'!$B$15/100)/12)>0),(('Вводные'!$B$14*(('Вводные'!$B$15/100)/12))/(1-((1+(('Вводные'!$B$15/100)/12))^(-1*'Вводные'!$B$16)))),('Вводные'!$B$14/'Вводные'!$B$16))*((((1+(('Вводные'!$B$15/100)/12))^5)-1)/(('Вводные'!$B$15/100)/12)))),('Вводные'!$B$14-(IF(((('Вводные'!$B$15/100)/12)>0),(('Вводные'!$B$14*(('Вводные'!$B$15/100)/12))/(1-((1+(('Вводные'!$B$15/100)/12))^(-1*'Вводные'!$B$16)))),('Вводные'!$B$14/'Вводные'!$B$16))*5)))),0) -> 0 | H33: =IF((7<='Вводные'!$B$16),MAX(0,IF(((('Вводные'!$B$15/100)/12)>0),(('Вводные'!$B$14*((1+(('Вводные'!$B$15/100)/12))^6))-(IF(((('Вводные'!$B$15/100)/12)>0),(('Вводные'!$B$14*(('Вводные'!$B$15/100)/12))/(1-((1+(('Вводные'!$B$15/100)/12))^(-1*'Вводные'!$B$16)))),('Вводные'!$B$14/'Вводные'!$B$16))*((((1+(('Вводные'!$B$15/100)/12))^6)-1)/(('Вводные'!$B$15/100)/12)))),('Вводные'!$B$14-(IF(((('Вводные'!$B$15/100)/12)>0),(('Вводные'!$B$14*(('Вводные'!$B$15/100)/12))/(1-((1+(('Вводные'!$B$15/100)/12))^(-1*'Вводные'!$B$16)))),('Вводные'!$B$14/'Вводные'!$B$16))*6)))),0) -> 0 | I33: =IF((8<='Вводные'!$B$16),MAX(0,IF(((('Вводные'!$B$15/100)/12)>0),(('Вводные'!$B$14*((1+(('Вводные'!$B$15/100)/12))^7))-(IF(((('Вводные'!$B$15/100)/12)>0),(('Вводные'!$B$14*(('Вводные'!$B$15/100)/12))/(1-((1+(('Вводные'!$B$15/100)/12))^(-1*'Вводные'!$B$16)))),('Вводные'!$B$14/'Вводные'!$B$16))*((((1+(('Вводные'!$B$15/100)/12))^7)-1)/(('Вводные'!$B$15/100)/12)))),('Вводные'!$B$14-(IF(((('Вводные'!$B$15/100)/12)>0),(('Вводные'!$B$14*(('Вводные'!$B$15/100)/12))/(1-((1+(('Вводные'!$B$15/100)/12))^(-1*'Вводные'!$B$16)))),('Вводные'!$B$14/'Вводные'!$B$16))*7)))),0) -> 0 | J33: =IF((9<='Вводные'!$B$16),MAX(0,IF(((('Вводные'!$B$15/100)/12)>0),(('Вводные'!$B$14*((1+(('Вводные'!$B$15/100)/12))^8))-(IF(((('Вводные'!$B$15/100)/12)>0),(('Вводные'!$B$14*(('Вводные'!$B$15/100)/12))/(1-((1+(('Вводные'!$B$15/100)/12))^(-1*'Вводные'!$B$16)))),('Вводные'!$B$14/'Вводные'!$B$16))*((((1+(('Вводные'!$B$15/100)/12))^8)-1)/(('Вводные'!$B$15/100)/12)))),('Вводные'!$B$14-(IF(((('Вводные'!$B$15/100)/12)>0),(('Вводные'!$B$14*(('Вводные'!$B$15/100)/12))/(1-((1+(('Вводные'!$B$15/100)/12))^(-1*'Вводные'!$B$16)))),('Вводные'!$B$14/'Вводные'!$B$16))*8)))),0) -> 0 | K33: =IF((10<='Вводные'!$B$16),MAX(0,IF(((('Вводные'!$B$15/100)/12)>0),(('Вводные'!$B$14*((1+(('Вводные'!$B$15/100)/12))^9))-(IF(((('Вводные'!$B$15/100)/12)>0),(('Вводные'!$B$14*(('Вводные'!$B$15/100)/12))/(1-((1+(('Вводные'!$B$15/100)/12))^(-1*'Вводные'!$B$16)))),('Вводные'!$B$14/'Вводные'!$B$16))*((((1+(('Вводные'!$B$15/100)/12))^9)-1)/(('Вводные'!$B$15/100)/12)))),('Вводные'!$B$14-(IF(((('Вводные'!$B$15/100)/12)>0),(('Вводные'!$B$14*(('Вводные'!$B$15/100)/12))/(1-((1+(('Вводные'!$B$15/100)/12))^(-1*'Вводные'!$B$16)))),('Вводные'!$B$14/'Вводные'!$B$16))*9)))),0) -> 0 | L33: =IF((11<='Вводные'!$B$16),MAX(0,IF(((('Вводные'!$B$15/100)/12)>0),(('Вводные'!$B$14*((1+(('Вводные'!$B$15/100)/12))^10))-(IF(((('Вводные'!$B$15/100)/12)>0),(('Вводные'!$B$14*(('Вводные'!$B$15/100)/12))/(1-((1+(('Вводные'!$B$15/100)/12))^(-1*'Вводные'!$B$16)))),('Вводные'!$B$14/'Вводные'!$B$16))*((((1+(('Вводные'!$B$15/100)/12))^10)-1)/(('Вводные'!$B$15/100)/12)))),('Вводные'!$B$14-(IF(((('Вводные'!$B$15/100)/12)>0),(('Вводные'!$B$14*(('Вводные'!$B$15/100)/12))/(1-((1+(('Вводные'!$B$15/100)/12))^(-1*'Вводные'!$B$16)))),('Вводные'!$B$14/'Вводные'!$B$16))*10)))),0) -> 0 | M33: =IF((12<='Вводные'!$B$16),MAX(0,IF(((('Вводные'!$B$15/100)/12)>0),(('Вводные'!$B$14*((1+(('Вводные'!$B$15/100)/12))^11))-(IF(((('Вводные'!$B$15/100)/12)>0),(('Вводные'!$B$14*(('Вводные'!$B$15/100)/12))/(1-((1+(('Вводные'!$B$15/100)/12))^(-1*'Вводные'!$B$16)))),('Вводные'!$B$14/'Вводные'!$B$16))*((((1+(('Вводные'!$B$15/100)/12))^11)-1)/(('Вводные'!$B$15/100)/12)))),('Вводные'!$B$14-(IF(((('Вводные'!$B$15/100)/12)>0),(('Вводные'!$B$14*(('Вводные'!$B$15/100)/12))/(1-((1+(('Вводные'!$B$15/100)/12))^(-1*'Вводные'!$B$16)))),('Вводные'!$B$14/'Вводные'!$B$16))*11)))),0) -> 0 | N33: =M33 -> 0 | O33: Кредит
A34: Проценты по кредиту | B34: =(B33*(('Вводные'!$B$15/100)/12)) -> 0 | C34: =(C33*(('Вводные'!$B$15/100)/12)) -> 0 | D34: =(D33*(('Вводные'!$B$15/100)/12)) -> 0 | E34: =(E33*(('Вводные'!$B$15/100)/12)) -> 0 | F34: =(F33*(('Вводные'!$B$15/100)/12)) -> 0 | G34: =(G33*(('Вводные'!$B$15/100)/12)) -> 0 | H34: =(H33*(('Вводные'!$B$15/100)/12)) -> 0 | I34: =(I33*(('Вводные'!$B$15/100)/12)) -> 0 | ... M34: =(M33*(('Вводные'!$B$15/100)/12)) -> 0 | N34: =SUM(B34:M34) -> 0 | O34: Результат
A35: Погашение тела кредита | B35: =IF((1<='Вводные'!$B$16),MIN(B33,MAX(0,(IF(((('Вводные'!$B$15/100)/12)>0),(('Вводные'!$B$14*(('Вводные'!$B$15/100)/12))/(1-((1+(('Вводные'!$B$15/100)/12))^(-1*'Вводные'!$B$16)))),('Вводные'!$B$14/'Вводные'!$B$16))-B34))),0) -> 0 | C35: =IF((2<='Вводные'!$B$16),MIN(C33,MAX(0,(IF(((('Вводные'!$B$15/100)/12)>0),(('Вводные'!$B$14*(('Вводные'!$B$15/100)/12))/(1-((1+(('Вводные'!$B$15/100)/12))^(-1*'Вводные'!$B$16)))),('Вводные'!$B$14/'Вводные'!$B$16))-C34))),0) -> 0 | D35: =IF((3<='Вводные'!$B$16),MIN(D33,MAX(0,(IF(((('Вводные'!$B$15/100)/12)>0),(('Вводные'!$B$14*(('Вводные'!$B$15/100)/12))/(1-((1+(('Вводные'!$B$15/100)/12))^(-1*'Вводные'!$B$16)))),('Вводные'!$B$14/'Вводные'!$B$16))-D34))),0) -> 0 | E35: =IF((4<='Вводные'!$B$16),MIN(E33,MAX(0,(IF(((('Вводные'!$B$15/100)/12)>0),(('Вводные'!$B$14*(('Вводные'!$B$15/100)/12))/(1-((1+(('Вводные'!$B$15/100)/12))^(-1*'Вводные'!$B$16)))),('Вводные'!$B$14/'Вводные'!$B$16))-E34))),0) -> 0 | F35: =IF((5<='Вводные'!$B$16),MIN(F33,MAX(0,(IF(((('Вводные'!$B$15/100)/12)>0),(('Вводные'!$B$14*(('Вводные'!$B$15/100)/12))/(1-((1+(('Вводные'!$B$15/100)/12))^(-1*'Вводные'!$B$16)))),('Вводные'!$B$14/'Вводные'!$B$16))-F34))),0) -> 0 | G35: =IF((6<='Вводные'!$B$16),MIN(G33,MAX(0,(IF(((('Вводные'!$B$15/100)/12)>0),(('Вводные'!$B$14*(('Вводные'!$B$15/100)/12))/(1-((1+(('Вводные'!$B$15/100)/12))^(-1*'Вводные'!$B$16)))),('Вводные'!$B$14/'Вводные'!$B$16))-G34))),0) -> 0 | H35: =IF((7<='Вводные'!$B$16),MIN(H33,MAX(0,(IF(((('Вводные'!$B$15/100)/12)>0),(('Вводные'!$B$14*(('Вводные'!$B$15/100)/12))/(1-((1+(('Вводные'!$B$15/100)/12))^(-1*'Вводные'!$B$16)))),('Вводные'!$B$14/'Вводные'!$B$16))-H34))),0) -> 0 | I35: =IF((8<='Вводные'!$B$16),MIN(I33,MAX(0,(IF(((('Вводные'!$B$15/100)/12)>0),(('Вводные'!$B$14*(('Вводные'!$B$15/100)/12))/(1-((1+(('Вводные'!$B$15/100)/12))^(-1*'Вводные'!$B$16)))),('Вводные'!$B$14/'Вводные'!$B$16))-I34))),0) -> 0 | J35: =IF((9<='Вводные'!$B$16),MIN(J33,MAX(0,(IF(((('Вводные'!$B$15/100)/12)>0),(('Вводные'!$B$14*(('Вводные'!$B$15/100)/12))/(1-((1+(('Вводные'!$B$15/100)/12))^(-1*'Вводные'!$B$16)))),('Вводные'!$B$14/'Вводные'!$B$16))-J34))),0) -> 0 | K35: =IF((10<='Вводные'!$B$16),MIN(K33,MAX(0,(IF(((('Вводные'!$B$15/100)/12)>0),(('Вводные'!$B$14*(('Вводные'!$B$15/100)/12))/(1-((1+(('Вводные'!$B$15/100)/12))^(-1*'Вводные'!$B$16)))),('Вводные'!$B$14/'Вводные'!$B$16))-K34))),0) -> 0 | L35: =IF((11<='Вводные'!$B$16),MIN(L33,MAX(0,(IF(((('Вводные'!$B$15/100)/12)>0),(('Вводные'!$B$14*(('Вводные'!$B$15/100)/12))/(1-((1+(('Вводные'!$B$15/100)/12))^(-1*'Вводные'!$B$16)))),('Вводные'!$B$14/'Вводные'!$B$16))-L34))),0) -> 0 | M35: =IF((12<='Вводные'!$B$16),MIN(M33,MAX(0,(IF(((('Вводные'!$B$15/100)/12)>0),(('Вводные'!$B$14*(('Вводные'!$B$15/100)/12))/(1-((1+(('Вводные'!$B$15/100)/12))^(-1*'Вводные'!$B$16)))),('Вводные'!$B$14/'Вводные'!$B$16))-M34))),0) -> 0 | N35: =SUM(B35:M35) -> 0 | O35: Аннуитетный платёж − проценты. Тело кредита уменьшает деньги, но не прибыль.
A36: Кредит на конец месяца | B36: =MAX(0,(B33-B35)) -> 0 | C36: =MAX(0,(C33-C35)) -> 0 | D36: =MAX(0,(D33-D35)) -> 0 | E36: =MAX(0,(E33-E35)) -> 0 | F36: =MAX(0,(F33-F35)) -> 0 | G36: =MAX(0,(G33-G35)) -> 0 | H36: =MAX(0,(H33-H35)) -> 0 | I36: =MAX(0,(I33-I35)) -> 0 | ... M36: =MAX(0,(M33-M35)) -> 0 | N36: =M36 -> 0 | O36: Кредит
A37: Прибыль до налога | B37: =(B32-B34) -> 740833.33 | C37: =(C32-C34) -> 807133.33 | D37: =(D32-D34) -> 876085.33 | E37: =(E32-E34) -> 947795.41 | F37: =(F32-F34) -> 1022373.9 | G37: =(G32-G34) -> 1099935.5 | H37: =(H32-H34) -> 1180599.6 | I37: =(I32-I34) -> 1264490.3 | ... M37: =(M32-M34) -> 1634978.4 | N37: =SUM(B37:M37) -> 13905273 | O37: Результат
A38: Условный налог | B38: =IF(('Вводные'!$B$6="none"),0,(IF(('Вводные'!$B$6="revenue"),B8,MAX(0,B37))*('Вводные'!$B$7/100))) -> 74083.333 | C38: =IF(('Вводные'!$B$6="none"),0,(IF(('Вводные'!$B$6="revenue"),C8,MAX(0,C37))*('Вводные'!$B$7/100))) -> 80713.333 | D38: =IF(('Вводные'!$B$6="none"),0,(IF(('Вводные'!$B$6="revenue"),D8,MAX(0,D37))*('Вводные'!$B$7/100))) -> 87608.533 | E38: =IF(('Вводные'!$B$6="none"),0,(IF(('Вводные'!$B$6="revenue"),E8,MAX(0,E37))*('Вводные'!$B$7/100))) -> 94779.541 | F38: =IF(('Вводные'!$B$6="none"),0,(IF(('Вводные'!$B$6="revenue"),F8,MAX(0,F37))*('Вводные'!$B$7/100))) -> 102237.39 | G38: =IF(('Вводные'!$B$6="none"),0,(IF(('Вводные'!$B$6="revenue"),G8,MAX(0,G37))*('Вводные'!$B$7/100))) -> 109993.55 | H38: =IF(('Вводные'!$B$6="none"),0,(IF(('Вводные'!$B$6="revenue"),H8,MAX(0,H37))*('Вводные'!$B$7/100))) -> 118059.96 | I38: =IF(('Вводные'!$B$6="none"),0,(IF(('Вводные'!$B$6="revenue"),I8,MAX(0,I37))*('Вводные'!$B$7/100))) -> 126449.03 | ... M38: =IF(('Вводные'!$B$6="none"),0,(IF(('Вводные'!$B$6="revenue"),M8,MAX(0,M37))*('Вводные'!$B$7/100))) -> 163497.84 | N38: =SUM(B38:M38) -> 1390527.3 | O38: Ваша ставка × оборот или положительная прибыль месяца. Без переноса убытков. Оплата в том же месяце.
A39: Чистая прибыль | B39: =(B37-B38) -> 666750 | C39: =(C37-C38) -> 726420 | D39: =(D37-D38) -> 788476.8 | E39: =(E37-E38) -> 853015.87 | F39: =(F37-F38) -> 920136.51 | G39: =(G37-G38) -> 989941.97 | H39: =(H37-H38) -> 1062539.6 | I39: =(I37-I38) -> 1138041.2 | ... M39: =(M37-M38) -> 1471480.6 | N39: =SUM(B39:M39) -> 12514745 | O39: Выручка − себестоимость − команда − маркетинг − прочие − амортизация − проценты − налог.
A40: Все расходы в прибыли | B40: =(B8-B39) -> 1883250 | C40: =(C8-C39) -> 1925580 | D40: =(D8-D39) -> 1969603.2 | E40: =(E8-E39) -> 2015387.3 | F40: =(F8-F39) -> 2063002.8 | G40: =(G8-G39) -> 2112522.9 | H40: =(H8-H39) -> 2164023.9 | I40: =(I8-I39) -> 2217584.8 | ... M40: =(M8-M39) -> 2454127.3 | N40: =SUM(B40:M40) -> 25801059 | O40: Результат
...

Sheet Вводные
A1: ВВОДНЫЕ / Мой бизнес
A2: Редактируйте колонку B. Суммы в KZT. Проценты задаются числом: 10 = 10%.
A3: Параметр | B3: Значение | C3: Пояснение
A4: Способ ввода выручки | B4: items | C4: items — товары; manual — ручной оборот
A5: Себестоимость ручного оборота, % | B5: 35
A6: База условного налога | B6: profit | C6: profit — прибыль; revenue — оборот; none — без налога
A7: Ставка налога, % | B7: 10
A8: Оплата клиентов через, мес. | B8: 0 | C8: Целые месяцы от 0 до 12
A9: Оплата себестоимости через, мес. | B9: 0 | C9: Целые месяцы от 0 до 12
A10: Деньги на начало | B10: 0
A11: Взнос собственника до М1 | B11: 3000000
A12: Вложения до М1 | B12: 6000000
A13: Амортизация начальных вложений, мес. (0 — нет) | B13: 36 | C13: 0 отключает амортизацию начальных вложений
A14: Кредит до М1 | B14: 0
A15: Годовая ставка кредита, % | B15: 18
A16: Срок кредита, мес. | B16: 24
A17: Множитель сценария | B17: 1 | C17: База: 1; осторожный: 0.8; оптимистичный: 1.2
A18: Ручной оборот · М1 | B18: 2550000
A19: Ручной оборот · М2 | B19: 2550000
A20: Ручной оборот · М3 | B20: 2550000
A21: Ручной оборот · М4 | B21: 2550000
A22: Ручной оборот · М5 | B22: 2550000
A23: Ручной оборот · М6 | B23: 2550000
A24: Ручной оборот · М7 | B24: 2550000
A25: Ручной оборот · М8 | B25: 2550000
A26: Ручной оборот · М9 | B26: 2550000
A27: Ручной оборот · М10 | B27: 2550000
A28: Ручной оборот · М11 | B28: 2550000
A29: Ручной оборот · М12 | B29: 2550000
A30: Основной продукт · Название | B30: Основной продукт
A31: Основной продукт · Количество в первый активный месяц | B31: 300
A32: Основной продукт · Цена | B32: 8500
A33: Основной продукт · Рост в месяц, % | B33: 4
A34: Основной продукт · Себестоимость, % выручки | B34: 35
A35: Основной продукт · С месяца | B35: 1 | C35: Номер периода: 1 — М1, …, 12 — М12
A36: Основной продукт · По месяц | B36: 12 | C36: Номер периода: 1 — М1, …, 12 — М12
A37: Менеджер · Название | B37: Менеджер
A38: Менеджер · Количество сотрудников | B38: 1
A39: Менеджер · Оклад одного / месяц | B39: 300000
A40: Менеджер · Бонус одного / месяц | B40: 0
...
