Workbook

Sheet Модель
A1: КОНТУР / Мой бизнес
A2: Базовый · KZT · 12 месяцев. Потоки — сумма; остатки — на конец М12.
A3: Чистая прибыль | B3: =N30 -> 110 | D3: Выручка | E3: =N8 -> 110 | G3: Деньги на конец | H3: =M38 -> 10
A4: Показатель | B4: М1 | C4: М2 | D4: М3 | E4: М4 | F4: М5 | G4: М6 | H4: М7 | I4: М8 | J4: М9 | K4: М10 | L4: М11 | M4: М12 | N4: Год / конец | O4: Как считается
A5: Основной продукт · количество | B5: =IF(AND((1>='Вводные'!$B$47),(1<='Вводные'!$B$48)),(('Вводные'!$B$43*'Вводные'!$B$29)*((1+('Вводные'!$B$45/100))^MAX(0,(1-'Вводные'!$B$47)))),0) -> 300 | C5: =IF(AND((2>='Вводные'!$B$47),(2<='Вводные'!$B$48)),(('Вводные'!$B$43*'Вводные'!$B$29)*((1+('Вводные'!$B$45/100))^MAX(0,(2-'Вводные'!$B$47)))),0) -> 312 | D5: =IF(AND((3>='Вводные'!$B$47),(3<='Вводные'!$B$48)),(('Вводные'!$B$43*'Вводные'!$B$29)*((1+('Вводные'!$B$45/100))^MAX(0,(3-'Вводные'!$B$47)))),0) -> 324.48 | E5: =IF(AND((4>='Вводные'!$B$47),(4<='Вводные'!$B$48)),(('Вводные'!$B$43*'Вводные'!$B$29)*((1+('Вводные'!$B$45/100))^MAX(0,(4-'Вводные'!$B$47)))),0) -> 337.4592 | F5: =IF(AND((5>='Вводные'!$B$47),(5<='Вводные'!$B$48)),(('Вводные'!$B$43*'Вводные'!$B$29)*((1+('Вводные'!$B$45/100))^MAX(0,(5-'Вводные'!$B$47)))),0) -> 350.95757 | G5: =IF(AND((6>='Вводные'!$B$47),(6<='Вводные'!$B$48)),(('Вводные'!$B$43*'Вводные'!$B$29)*((1+('Вводные'!$B$45/100))^MAX(0,(6-'Вводные'!$B$47)))),0) -> 364.99587 | H5: =IF(AND((7>='Вводные'!$B$47),(7<='Вводные'!$B$48)),(('Вводные'!$B$43*'Вводные'!$B$29)*((1+('Вводные'!$B$45/100))^MAX(0,(7-'Вводные'!$B$47)))),0) -> 379.59571 | I5: =IF(AND((8>='Вводные'!$B$47),(8<='Вводные'!$B$48)),(('Вводные'!$B$43*'Вводные'!$B$29)*((1+('Вводные'!$B$45/100))^MAX(0,(8-'Вводные'!$B$47)))),0) -> 394.77953 | J5: =IF(AND((9>='Вводные'!$B$47),(9<='Вводные'!$B$48)),(('Вводные'!$B$43*'Вводные'!$B$29)*((1+('Вводные'!$B$45/100))^MAX(0,(9-'Вводные'!$B$47)))),0) -> 410.57072 | K5: =IF(AND((10>='Вводные'!$B$47),(10<='Вводные'!$B$48)),(('Вводные'!$B$43*'Вводные'!$B$29)*((1+('Вводные'!$B$45/100))^MAX(0,(10-'Вводные'!$B$47)))),0) -> 426.99354 | L5: =IF(AND((11>='Вводные'!$B$47),(11<='Вводные'!$B$48)),(('Вводные'!$B$43*'Вводные'!$B$29)*((1+('Вводные'!$B$45/100))^MAX(0,(11-'Вводные'!$B$47)))),0) -> 444.07329 | M5: =IF(AND((12>='Вводные'!$B$47),(12<='Вводные'!$B$48)),(('Вводные'!$B$43*'Вводные'!$B$29)*((1+('Вводные'!$B$45/100))^MAX(0,(12-'Вводные'!$B$47)))),0) -> 461.83622 | N5: =SUM(B5:M5) -> 4507.7416 | O5: Продажи
A6: Основной продукт · выручка | B6: =(B5*'Вводные'!$B$44) -> 2550000 | C6: =(C5*'Вводные'!$B$44) -> 2652000 | D6: =(D5*'Вводные'!$B$44) -> 2758080 | E6: =(E5*'Вводные'!$B$44) -> 2868403.2 | F6: =(F5*'Вводные'!$B$44) -> 2983139.3 | G6: =(G5*'Вводные'!$B$44) -> 3102464.9 | H6: =(H5*'Вводные'!$B$44) -> 3226563.5 | I6: =(I5*'Вводные'!$B$44) -> 3355626 | ... M6: =(M5*'Вводные'!$B$44) -> 3925607.8 | N6: =SUM(B6:M6) -> 38315804 | O6: Продажи
A7: Основной продукт · себестоимость | B7: =(B6*('Вводные'!$B$46/100)) -> 892500 | C7: =(C6*('Вводные'!$B$46/100)) -> 928200 | D7: =(D6*('Вводные'!$B$46/100)) -> 965328 | E7: =(E6*('Вводные'!$B$46/100)) -> 1003941.1 | F7: =(F6*('Вводные'!$B$46/100)) -> 1044098.8 | G7: =(G6*('Вводные'!$B$46/100)) -> 1085862.7 | H7: =(H6*('Вводные'!$B$46/100)) -> 1129297.2 | I7: =(I6*('Вводные'!$B$46/100)) -> 1174469.1 | ... M7: =(M6*('Вводные'!$B$46/100)) -> 1373962.7 | N7: =SUM(B7:M7) -> 13410531 | O7: Продажи
A8: Выручка / оборот | B8: =IF(('Вводные'!$B$4="manual"),('Вводные'!$B$30*'Вводные'!$B$29),B6) -> 0 | C8: =IF(('Вводные'!$B$4="manual"),('Вводные'!$B$31*'Вводные'!$B$29),C6) -> 0 | D8: =IF(('Вводные'!$B$4="manual"),('Вводные'!$B$32*'Вводные'!$B$29),D6) -> 0 | E8: =IF(('Вводные'!$B$4="manual"),('Вводные'!$B$33*'Вводные'!$B$29),E6) -> 0 | F8: =IF(('Вводные'!$B$4="manual"),('Вводные'!$B$34*'Вводные'!$B$29),F6) -> 0 | G8: =IF(('Вводные'!$B$4="manual"),('Вводные'!$B$35*'Вводные'!$B$29),G6) -> 0 | H8: =IF(('Вводные'!$B$4="manual"),('Вводные'!$B$36*'Вводные'!$B$29),H6) -> 0 | I8: =IF(('Вводные'!$B$4="manual"),('Вводные'!$B$37*'Вводные'!$B$29),I6) -> 0 | J8: =IF(('Вводные'!$B$4="manual"),('Вводные'!$B$38*'Вводные'!$B$29),J6) -> 0 | K8: =IF(('Вводные'!$B$4="manual"),('Вводные'!$B$39*'Вводные'!$B$29),K6) -> 0 | L8: =IF(('Вводные'!$B$4="manual"),('Вводные'!$B$40*'Вводные'!$B$29),L6) -> 0 | M8: =IF(('Вводные'!$B$4="manual"),('Вводные'!$B$41*'Вводные'!$B$29),M6) -> 110 | N8: =SUM(B8:M8) -> 110 | O8: По продуктам: количество × цена. Вручную: введённый оборот. Сценарий применяется один раз.
A9: Себестоимость продаж | B9: =IF(('Вводные'!$B$4="manual"),(B8*('Вводные'!$B$5/100)),B7) -> 0 | C9: =IF(('Вводные'!$B$4="manual"),(C8*('Вводные'!$B$5/100)),C7) -> 0 | D9: =IF(('Вводные'!$B$4="manual"),(D8*('Вводные'!$B$5/100)),D7) -> 0 | E9: =IF(('Вводные'!$B$4="manual"),(E8*('Вводные'!$B$5/100)),E7) -> 0 | F9: =IF(('Вводные'!$B$4="manual"),(F8*('Вводные'!$B$5/100)),F7) -> 0 | G9: =IF(('Вводные'!$B$4="manual"),(G8*('Вводные'!$B$5/100)),G7) -> 0 | H9: =IF(('Вводные'!$B$4="manual"),(H8*('Вводные'!$B$5/100)),H7) -> 0 | I9: =IF(('Вводные'!$B$4="manual"),(I8*('Вводные'!$B$5/100)),I7) -> 0 | ... M9: =IF(('Вводные'!$B$4="manual"),(M8*('Вводные'!$B$5/100)),M7) -> 0 | N9: =SUM(B9:M9) -> 0 | O9: Себестоимость продуктов или доля ручного оборота. Не дублируйте её в прочих расходах.
A10: Валовая прибыль | B10: =(B8-B9) -> 0 | C10: =(C8-C9) -> 0 | D10: =(D8-D9) -> 0 | E10: =(E8-E9) -> 0 | F10: =(F8-F9) -> 0 | G10: =(G8-G9) -> 0 | H10: =(H8-H9) -> 0 | I10: =(I8-I9) -> 0 | ... M10: =(M8-M9) -> 110 | N10: =SUM(B10:M10) -> 110 | O10: Выручка − себестоимость.
A11: Оклады и бонусы | B11: =0 -> 0 | C11: =0 -> 0 | D11: =0 -> 0 | E11: =0 -> 0 | F11: =0 -> 0 | G11: =0 -> 0 | H11: =0 -> 0 | I11: =0 -> 0 | ... M11: =0 -> 0 | N11: =SUM(B11:M11) -> 0 | O11: Команда
A12: Начисления работодателя | B12: =0 -> 0 | C12: =0 -> 0 | D12: =0 -> 0 | E12: =0 -> 0 | F12: =0 -> 0 | G12: =0 -> 0 | H12: =0 -> 0 | I12: =0 -> 0 | ... M12: =0 -> 0 | N12: =SUM(B12:M12) -> 0 | O12: Команда
A13: Команда — всего | B13: =(B11+B12) -> 0 | C13: =(C11+C12) -> 0 | D13: =(D11+D12) -> 0 | E13: =(E11+E12) -> 0 | F13: =(F11+F12) -> 0 | G13: =(G11+G12) -> 0 | H13: =(H11+H12) -> 0 | I13: =(I11+I12) -> 0 | ... M13: =(M11+M12) -> 0 | N13: =SUM(B13:M13) -> 0 | O13: Количество × (оклад + бонус) × рост × (1 + начисления). Ставки задаёте вы.
A14: Маркетинг — всего | B14: =0 -> 0 | C14: =0 -> 0 | D14: =0 -> 0 | E14: =0 -> 0 | F14: =0 -> 0 | G14: =0 -> 0 | H14: =0 -> 0 | I14: =0 -> 0 | ... M14: =0 -> 0 | N14: =SUM(B14:M14) -> 0 | O14: Бюджеты каналов + процент от выручки. Продажи из воронки уже должны входить в общий оборот.
A15: Заявки из рекламы, шт. | B15: =0 -> 0 | C15: =0 -> 0 | D15: =0 -> 0 | E15: =0 -> 0 | F15: =0 -> 0 | G15: =0 -> 0 | H15: =0 -> 0 | I15: =0 -> 0 | ... M15: =0 -> 0 | N15: =SUM(B15:M15) -> 0 | O15: Маркетинг
A16: Клиенты из рекламы, шт. | B16: =0 -> 0 | C16: =0 -> 0 | D16: =0 -> 0 | E16: =0 -> 0 | F16: =0 -> 0 | G16: =0 -> 0 | H16: =0 -> 0 | I16: =0 -> 0 | ... M16: =0 -> 0 | N16: =SUM(B16:M16) -> 0 | O16: Маркетинг
A17: Оценка выручки из рекламы | B17: =0 -> 0 | C17: =0 -> 0 | D17: =0 -> 0 | E17: =0 -> 0 | F17: =0 -> 0 | G17: =0 -> 0 | H17: =0 -> 0 | I17: =0 -> 0 | ... M17: =0 -> 0 | N17: =SUM(B17:M17) -> 0 | O17: Клиенты × чек каждого канала. Не прибавляется к обороту, чтобы не считать продажи дважды.
A18: Прочие расходы — всего | B18: =0 -> 0 | C18: =0 -> 0 | D18: =0 -> 0 | E18: =0 -> 0 | F18: =0 -> 0 | G18: =0 -> 0 | H18: =0 -> 0 | I18: =0 -> 0 | ... M18: =0 -> 0 | N18: =SUM(B18:M18) -> 0 | O18: Результат
A19: Операционные расходы | B19: =((B13+B14)+B18) -> 0 | C19: =((C13+C14)+C18) -> 0 | D19: =((D13+D14)+D18) -> 0 | E19: =((E13+E14)+E18) -> 0 | F19: =((F13+F14)+F18) -> 0 | G19: =((G13+G14)+G18) -> 0 | H19: =((H13+H14)+H18) -> 0 | I19: =((I13+I14)+I18) -> 0 | ... M19: =((M13+M14)+M18) -> 0 | N19: =SUM(B19:M19) -> 0 | O19: Команда + маркетинг + прочие расходы.
A20: EBITDA | B20: =(B10-B19) -> 0 | C20: =(C10-C19) -> 0 | D20: =(D10-D19) -> 0 | E20: =(E10-E19) -> 0 | F20: =(F10-F19) -> 0 | G20: =(G10-G19) -> 0 | H20: =(H10-H19) -> 0 | I20: =(I10-I19) -> 0 | ... M20: =(M10-M19) -> 110 | N20: =SUM(B20:M20) -> 110 | O20: Валовая прибыль − операционные расходы; до амортизации, процентов и налога.
A21: Покупка активов | B21: =0 -> 0 | C21: =0 -> 0 | D21: =0 -> 0 | E21: =0 -> 0 | F21: =0 -> 0 | G21: =0 -> 0 | H21: =0 -> 0 | I21: =0 -> 0 | ... M21: =0 -> 0 | N21: =SUM(B21:M21) -> 0 | O21: Денежный поток
A22: Амортизация | B22: =(IF(AND(('Вводные'!$B$13>0),(1<='Вводные'!$B$13)),('Вводные'!$B$12/MAX(1,'Вводные'!$B$13)),0)+0) -> 0 | C22: =(IF(AND(('Вводные'!$B$13>0),(2<='Вводные'!$B$13)),('Вводные'!$B$12/MAX(1,'Вводные'!$B$13)),0)+0) -> 0 | D22: =(IF(AND(('Вводные'!$B$13>0),(3<='Вводные'!$B$13)),('Вводные'!$B$12/MAX(1,'Вводные'!$B$13)),0)+0) -> 0 | E22: =(IF(AND(('Вводные'!$B$13>0),(4<='Вводные'!$B$13)),('Вводные'!$B$12/MAX(1,'Вводные'!$B$13)),0)+0) -> 0 | F22: =(IF(AND(('Вводные'!$B$13>0),(5<='Вводные'!$B$13)),('Вводные'!$B$12/MAX(1,'Вводные'!$B$13)),0)+0) -> 0 | G22: =(IF(AND(('Вводные'!$B$13>0),(6<='Вводные'!$B$13)),('Вводные'!$B$12/MAX(1,'Вводные'!$B$13)),0)+0) -> 0 | H22: =(IF(AND(('Вводные'!$B$13>0),(7<='Вводные'!$B$13)),('Вводные'!$B$12/MAX(1,'Вводные'!$B$13)),0)+0) -> 0 | I22: =(IF(AND(('Вводные'!$B$13>0),(8<='Вводные'!$B$13)),('Вводные'!$B$12/MAX(1,'Вводные'!$B$13)),0)+0) -> 0 | J22: =(IF(AND(('Вводные'!$B$13>0),(9<='Вводные'!$B$13)),('Вводные'!$B$12/MAX(1,'Вводные'!$B$13)),0)+0) -> 0 | K22: =(IF(AND(('Вводные'!$B$13>0),(10<='Вводные'!$B$13)),('Вводные'!$B$12/MAX(1,'Вводные'!$B$13)),0)+0) -> 0 | L22: =(IF(AND(('Вводные'!$B$13>0),(11<='Вводные'!$B$13)),('Вводные'!$B$12/MAX(1,'Вводные'!$B$13)),0)+0) -> 0 | M22: =(IF(AND(('Вводные'!$B$13>0),(12<='Вводные'!$B$13)),('Вводные'!$B$12/MAX(1,'Вводные'!$B$13)),0)+0) -> 0 | N22: =SUM(B22:M22) -> 0 | O22: Стоимость / срок в месяцах, начиная с месяца покупки. Покупка уменьшает деньги, амортизация — прибыль.
A23: Операционная прибыль (EBIT) | B23: =(B20-B22) -> 0 | C23: =(C20-C22) -> 0 | D23: =(D20-D22) -> 0 | E23: =(E20-E22) -> 0 | F23: =(F20-F22) -> 0 | G23: =(G20-G22) -> 0 | H23: =(H20-H22) -> 0 | I23: =(I20-I22) -> 0 | ... M23: =(M20-M22) -> 110 | N23: =SUM(B23:M23) -> 110 | O23: Результат
A24: Кредит на начало месяца | B24: =IF((1<='Вводные'!$B$16),MAX(0,IF(((('Вводные'!$B$15/100)/12)>0),(('Вводные'!$B$14*((1+(('Вводные'!$B$15/100)/12))^0))-(IF(((('Вводные'!$B$15/100)/12)>0),(('Вводные'!$B$14*(('Вводные'!$B$15/100)/12))/(1-((1+(('Вводные'!$B$15/100)/12))^(-1*'Вводные'!$B$16)))),('Вводные'!$B$14/'Вводные'!$B$16))*((((1+(('Вводные'!$B$15/100)/12))^0)-1)/(('Вводные'!$B$15/100)/12)))),('Вводные'!$B$14-(IF(((('Вводные'!$B$15/100)/12)>0),(('Вводные'!$B$14*(('Вводные'!$B$15/100)/12))/(1-((1+(('Вводные'!$B$15/100)/12))^(-1*'Вводные'!$B$16)))),('Вводные'!$B$14/'Вводные'!$B$16))*0)))),0) -> 0 | C24: =IF((2<='Вводные'!$B$16),MAX(0,IF(((('Вводные'!$B$15/100)/12)>0),(('Вводные'!$B$14*((1+(('Вводные'!$B$15/100)/12))^1))-(IF(((('Вводные'!$B$15/100)/12)>0),(('Вводные'!$B$14*(('Вводные'!$B$15/100)/12))/(1-((1+(('Вводные'!$B$15/100)/12))^(-1*'Вводные'!$B$16)))),('Вводные'!$B$14/'Вводные'!$B$16))*((((1+(('Вводные'!$B$15/100)/12))^1)-1)/(('Вводные'!$B$15/100)/12)))),('Вводные'!$B$14-(IF(((('Вводные'!$B$15/100)/12)>0),(('Вводные'!$B$14*(('Вводные'!$B$15/100)/12))/(1-((1+(('Вводные'!$B$15/100)/12))^(-1*'Вводные'!$B$16)))),('Вводные'!$B$14/'Вводные'!$B$16))*1)))),0) -> 0 | D24: =IF((3<='Вводные'!$B$16),MAX(0,IF(((('Вводные'!$B$15/100)/12)>0),(('Вводные'!$B$14*((1+(('Вводные'!$B$15/100)/12))^2))-(IF(((('Вводные'!$B$15/100)/12)>0),(('Вводные'!$B$14*(('Вводные'!$B$15/100)/12))/(1-((1+(('Вводные'!$B$15/100)/12))^(-1*'Вводные'!$B$16)))),('Вводные'!$B$14/'Вводные'!$B$16))*((((1+(('Вводные'!$B$15/100)/12))^2)-1)/(('Вводные'!$B$15/100)/12)))),('Вводные'!$B$14-(IF(((('Вводные'!$B$15/100)/12)>0),(('Вводные'!$B$14*(('Вводные'!$B$15/100)/12))/(1-((1+(('Вводные'!$B$15/100)/12))^(-1*'Вводные'!$B$16)))),('Вводные'!$B$14/'Вводные'!$B$16))*2)))),0) -> 0 | E24: =IF((4<='Вводные'!$B$16),MAX(0,IF(((('Вводные'!$B$15/100)/12)>0),(('Вводные'!$B$14*((1+(('Вводные'!$B$15/100)/12))^3))-(IF(((('Вводные'!$B$15/100)/12)>0),(('Вводные'!$B$14*(('Вводные'!$B$15/100)/12))/(1-((1+(('Вводные'!$B$15/100)/12))^(-1*'Вводные'!$B$16)))),('Вводные'!$B$14/'Вводные'!$B$16))*((((1+(('Вводные'!$B$15/100)/12))^3)-1)/(('Вводные'!$B$15/100)/12)))),('Вводные'!$B$14-(IF(((('Вводные'!$B$15/100)/12)>0),(('Вводные'!$B$14*(('Вводные'!$B$15/100)/12))/(1-((1+(('Вводные'!$B$15/100)/12))^(-1*'Вводные'!$B$16)))),('Вводные'!$B$14/'Вводные'!$B$16))*3)))),0) -> 0 | F24: =IF((5<='Вводные'!$B$16),MAX(0,IF(((('Вводные'!$B$15/100)/12)>0),(('Вводные'!$B$14*((1+(('Вводные'!$B$15/100)/12))^4))-(IF(((('Вводные'!$B$15/100)/12)>0),(('Вводные'!$B$14*(('Вводные'!$B$15/100)/12))/(1-((1+(('Вводные'!$B$15/100)/12))^(-1*'Вводные'!$B$16)))),('Вводные'!$B$14/'Вводные'!$B$16))*((((1+(('Вводные'!$B$15/100)/12))^4)-1)/(('Вводные'!$B$15/100)/12)))),('Вводные'!$B$14-(IF(((('Вводные'!$B$15/100)/12)>0),(('Вводные'!$B$14*(('Вводные'!$B$15/100)/12))/(1-((1+(('Вводные'!$B$15/100)/12))^(-1*'Вводные'!$B$16)))),('Вводные'!$B$14/'Вводные'!$B$16))*4)))),0) -> 0 | G24: =IF((6<='Вводные'!$B$16),MAX(0,IF(((('Вводные'!$B$15/100)/12)>0),(('Вводные'!$B$14*((1+(('Вводные'!$B$15/100)/12))^5))-(IF(((('Вводные'!$B$15/100)/12)>0),(('Вводные'!$B$14*(('Вводные'!$B$15/100)/12))/(1-((1+(('Вводные'!$B$15/100)/12))^(-1*'Вводные'!$B$16)))),('Вводные'!$B$14/'Вводные'!$B$16))*((((1+(('Вводные'!$B$15/100)/12))^5)-1)/(('Вводные'!$B$15/100)/12)))),('Вводные'!$B$14-(IF(((('Вводные'!$B$15/100)/12)>0),(('Вводные'!$B$14*(('Вводные'!$B$15/100)/12))/(1-((1+(('Вводные'!$B$15/100)/12))^(-1*'Вводные'!$B$16)))),('Вводные'!$B$14/'Вводные'!$B$16))*5)))),0) -> 0 | H24: =IF((7<='Вводные'!$B$16),MAX(0,IF(((('Вводные'!$B$15/100)/12)>0),(('Вводные'!$B$14*((1+(('Вводные'!$B$15/100)/12))^6))-(IF(((('Вводные'!$B$15/100)/12)>0),(('Вводные'!$B$14*(('Вводные'!$B$15/100)/12))/(1-((1+(('Вводные'!$B$15/100)/12))^(-1*'Вводные'!$B$16)))),('Вводные'!$B$14/'Вводные'!$B$16))*((((1+(('Вводные'!$B$15/100)/12))^6)-1)/(('Вводные'!$B$15/100)/12)))),('Вводные'!$B$14-(IF(((('Вводные'!$B$15/100)/12)>0),(('Вводные'!$B$14*(('Вводные'!$B$15/100)/12))/(1-((1+(('Вводные'!$B$15/100)/12))^(-1*'Вводные'!$B$16)))),('Вводные'!$B$14/'Вводные'!$B$16))*6)))),0) -> 0 | I24: =IF((8<='Вводные'!$B$16),MAX(0,IF(((('Вводные'!$B$15/100)/12)>0),(('Вводные'!$B$14*((1+(('Вводные'!$B$15/100)/12))^7))-(IF(((('Вводные'!$B$15/100)/12)>0),(('Вводные'!$B$14*(('Вводные'!$B$15/100)/12))/(1-((1+(('Вводные'!$B$15/100)/12))^(-1*'Вводные'!$B$16)))),('Вводные'!$B$14/'Вводные'!$B$16))*((((1+(('Вводные'!$B$15/100)/12))^7)-1)/(('Вводные'!$B$15/100)/12)))),('Вводные'!$B$14-(IF(((('Вводные'!$B$15/100)/12)>0),(('Вводные'!$B$14*(('Вводные'!$B$15/100)/12))/(1-((1+(('Вводные'!$B$15/100)/12))^(-1*'Вводные'!$B$16)))),('Вводные'!$B$14/'Вводные'!$B$16))*7)))),0) -> 0 | J24: =IF((9<='Вводные'!$B$16),MAX(0,IF(((('Вводные'!$B$15/100)/12)>0),(('Вводные'!$B$14*((1+(('Вводные'!$B$15/100)/12))^8))-(IF(((('Вводные'!$B$15/100)/12)>0),(('Вводные'!$B$14*(('Вводные'!$B$15/100)/12))/(1-((1+(('Вводные'!$B$15/100)/12))^(-1*'Вводные'!$B$16)))),('Вводные'!$B$14/'Вводные'!$B$16))*((((1+(('Вводные'!$B$15/100)/12))^8)-1)/(('Вводные'!$B$15/100)/12)))),('Вводные'!$B$14-(IF(((('Вводные'!$B$15/100)/12)>0),(('Вводные'!$B$14*(('Вводные'!$B$15/100)/12))/(1-((1+(('Вводные'!$B$15/100)/12))^(-1*'Вводные'!$B$16)))),('Вводные'!$B$14/'Вводные'!$B$16))*8)))),0) -> 0 | K24: =IF((10<='Вводные'!$B$16),MAX(0,IF(((('Вводные'!$B$15/100)/12)>0),(('Вводные'!$B$14*((1+(('Вводные'!$B$15/100)/12))^9))-(IF(((('Вводные'!$B$15/100)/12)>0),(('Вводные'!$B$14*(('Вводные'!$B$15/100)/12))/(1-((1+(('Вводные'!$B$15/100)/12))^(-1*'Вводные'!$B$16)))),('Вводные'!$B$14/'Вводные'!$B$16))*((((1+(('Вводные'!$B$15/100)/12))^9)-1)/(('Вводные'!$B$15/100)/12)))),('Вводные'!$B$14-(IF(((('Вводные'!$B$15/100)/12)>0),(('Вводные'!$B$14*(('Вводные'!$B$15/100)/12))/(1-((1+(('Вводные'!$B$15/100)/12))^(-1*'Вводные'!$B$16)))),('Вводные'!$B$14/'Вводные'!$B$16))*9)))),0) -> 0 | L24: =IF((11<='Вводные'!$B$16),MAX(0,IF(((('Вводные'!$B$15/100)/12)>0),(('Вводные'!$B$14*((1+(('Вводные'!$B$15/100)/12))^10))-(IF(((('Вводные'!$B$15/100)/12)>0),(('Вводные'!$B$14*(('Вводные'!$B$15/100)/12))/(1-((1+(('Вводные'!$B$15/100)/12))^(-1*'Вводные'!$B$16)))),('Вводные'!$B$14/'Вводные'!$B$16))*((((1+(('Вводные'!$B$15/100)/12))^10)-1)/(('Вводные'!$B$15/100)/12)))),('Вводные'!$B$14-(IF(((('Вводные'!$B$15/100)/12)>0),(('Вводные'!$B$14*(('Вводные'!$B$15/100)/12))/(1-((1+(('Вводные'!$B$15/100)/12))^(-1*'Вводные'!$B$16)))),('Вводные'!$B$14/'Вводные'!$B$16))*10)))),0) -> 0 | M24: =IF((12<='Вводные'!$B$16),MAX(0,IF(((('Вводные'!$B$15/100)/12)>0),(('Вводные'!$B$14*((1+(('Вводные'!$B$15/100)/12))^11))-(IF(((('Вводные'!$B$15/100)/12)>0),(('Вводные'!$B$14*(('Вводные'!$B$15/100)/12))/(1-((1+(('Вводные'!$B$15/100)/12))^(-1*'Вводные'!$B$16)))),('Вводные'!$B$14/'Вводные'!$B$16))*((((1+(('Вводные'!$B$15/100)/12))^11)-1)/(('Вводные'!$B$15/100)/12)))),('Вводные'!$B$14-(IF(((('Вводные'!$B$15/100)/12)>0),(('Вводные'!$B$14*(('Вводные'!$B$15/100)/12))/(1-((1+(('Вводные'!$B$15/100)/12))^(-1*'Вводные'!$B$16)))),('Вводные'!$B$14/'Вводные'!$B$16))*11)))),0) -> 0 | N24: =M24 -> 0 | O24: Кредит
A25: Проценты по кредиту | B25: =(B24*(('Вводные'!$B$15/100)/12)) -> 0 | C25: =(C24*(('Вводные'!$B$15/100)/12)) -> 0 | D25: =(D24*(('Вводные'!$B$15/100)/12)) -> 0 | E25: =(E24*(('Вводные'!$B$15/100)/12)) -> 0 | F25: =(F24*(('Вводные'!$B$15/100)/12)) -> 0 | G25: =(G24*(('Вводные'!$B$15/100)/12)) -> 0 | H25: =(H24*(('Вводные'!$B$15/100)/12)) -> 0 | I25: =(I24*(('Вводные'!$B$15/100)/12)) -> 0 | ... M25: =(M24*(('Вводные'!$B$15/100)/12)) -> 0 | N25: =SUM(B25:M25) -> 0 | O25: Результат
A26: Погашение тела кредита | B26: =IF((1<='Вводные'!$B$16),MIN(B24,MAX(0,(IF(((('Вводные'!$B$15/100)/12)>0),(('Вводные'!$B$14*(('Вводные'!$B$15/100)/12))/(1-((1+(('Вводные'!$B$15/100)/12))^(-1*'Вводные'!$B$16)))),('Вводные'!$B$14/'Вводные'!$B$16))-B25))),0) -> 0 | C26: =IF((2<='Вводные'!$B$16),MIN(C24,MAX(0,(IF(((('Вводные'!$B$15/100)/12)>0),(('Вводные'!$B$14*(('Вводные'!$B$15/100)/12))/(1-((1+(('Вводные'!$B$15/100)/12))^(-1*'Вводные'!$B$16)))),('Вводные'!$B$14/'Вводные'!$B$16))-C25))),0) -> 0 | D26: =IF((3<='Вводные'!$B$16),MIN(D24,MAX(0,(IF(((('Вводные'!$B$15/100)/12)>0),(('Вводные'!$B$14*(('Вводные'!$B$15/100)/12))/(1-((1+(('Вводные'!$B$15/100)/12))^(-1*'Вводные'!$B$16)))),('Вводные'!$B$14/'Вводные'!$B$16))-D25))),0) -> 0 | E26: =IF((4<='Вводные'!$B$16),MIN(E24,MAX(0,(IF(((('Вводные'!$B$15/100)/12)>0),(('Вводные'!$B$14*(('Вводные'!$B$15/100)/12))/(1-((1+(('Вводные'!$B$15/100)/12))^(-1*'Вводные'!$B$16)))),('Вводные'!$B$14/'Вводные'!$B$16))-E25))),0) -> 0 | F26: =IF((5<='Вводные'!$B$16),MIN(F24,MAX(0,(IF(((('Вводные'!$B$15/100)/12)>0),(('Вводные'!$B$14*(('Вводные'!$B$15/100)/12))/(1-((1+(('Вводные'!$B$15/100)/12))^(-1*'Вводные'!$B$16)))),('Вводные'!$B$14/'Вводные'!$B$16))-F25))),0) -> 0 | G26: =IF((6<='Вводные'!$B$16),MIN(G24,MAX(0,(IF(((('Вводные'!$B$15/100)/12)>0),(('Вводные'!$B$14*(('Вводные'!$B$15/100)/12))/(1-((1+(('Вводные'!$B$15/100)/12))^(-1*'Вводные'!$B$16)))),('Вводные'!$B$14/'Вводные'!$B$16))-G25))),0) -> 0 | H26: =IF((7<='Вводные'!$B$16),MIN(H24,MAX(0,(IF(((('Вводные'!$B$15/100)/12)>0),(('Вводные'!$B$14*(('Вводные'!$B$15/100)/12))/(1-((1+(('Вводные'!$B$15/100)/12))^(-1*'Вводные'!$B$16)))),('Вводные'!$B$14/'Вводные'!$B$16))-H25))),0) -> 0 | I26: =IF((8<='Вводные'!$B$16),MIN(I24,MAX(0,(IF(((('Вводные'!$B$15/100)/12)>0),(('Вводные'!$B$14*(('Вводные'!$B$15/100)/12))/(1-((1+(('Вводные'!$B$15/100)/12))^(-1*'Вводные'!$B$16)))),('Вводные'!$B$14/'Вводные'!$B$16))-I25))),0) -> 0 | J26: =IF((9<='Вводные'!$B$16),MIN(J24,MAX(0,(IF(((('Вводные'!$B$15/100)/12)>0),(('Вводные'!$B$14*(('Вводные'!$B$15/100)/12))/(1-((1+(('Вводные'!$B$15/100)/12))^(-1*'Вводные'!$B$16)))),('Вводные'!$B$14/'Вводные'!$B$16))-J25))),0) -> 0 | K26: =IF((10<='Вводные'!$B$16),MIN(K24,MAX(0,(IF(((('Вводные'!$B$15/100)/12)>0),(('Вводные'!$B$14*(('Вводные'!$B$15/100)/12))/(1-((1+(('Вводные'!$B$15/100)/12))^(-1*'Вводные'!$B$16)))),('Вводные'!$B$14/'Вводные'!$B$16))-K25))),0) -> 0 | L26: =IF((11<='Вводные'!$B$16),MIN(L24,MAX(0,(IF(((('Вводные'!$B$15/100)/12)>0),(('Вводные'!$B$14*(('Вводные'!$B$15/100)/12))/(1-((1+(('Вводные'!$B$15/100)/12))^(-1*'Вводные'!$B$16)))),('Вводные'!$B$14/'Вводные'!$B$16))-L25))),0) -> 0 | M26: =IF((12<='Вводные'!$B$16),MIN(M24,MAX(0,(IF(((('Вводные'!$B$15/100)/12)>0),(('Вводные'!$B$14*(('Вводные'!$B$15/100)/12))/(1-((1+(('Вводные'!$B$15/100)/12))^(-1*'Вводные'!$B$16)))),('Вводные'!$B$14/'Вводные'!$B$16))-M25))),0) -> 0 | N26: =SUM(B26:M26) -> 0 | O26: Аннуитетный платёж − проценты. Тело кредита уменьшает деньги, но не прибыль.
A27: Кредит на конец месяца | B27: =MAX(0,(B24-B26)) -> 0 | C27: =MAX(0,(C24-C26)) -> 0 | D27: =MAX(0,(D24-D26)) -> 0 | E27: =MAX(0,(E24-E26)) -> 0 | F27: =MAX(0,(F24-F26)) -> 0 | G27: =MAX(0,(G24-G26)) -> 0 | H27: =MAX(0,(H24-H26)) -> 0 | I27: =MAX(0,(I24-I26)) -> 0 | ... M27: =MAX(0,(M24-M26)) -> 0 | N27: =M27 -> 0 | O27: Кредит
A28: Прибыль до налога | B28: =(B23-B25) -> 0 | C28: =(C23-C25) -> 0 | D28: =(D23-D25) -> 0 | E28: =(E23-E25) -> 0 | F28: =(F23-F25) -> 0 | G28: =(G23-G25) -> 0 | H28: =(H23-H25) -> 0 | I28: =(I23-I25) -> 0 | ... M28: =(M23-M25) -> 110 | N28: =SUM(B28:M28) -> 110 | O28: Результат
A29: Условный налог | B29: =IF(('Вводные'!$B$6="none"),0,(IF(('Вводные'!$B$6="revenue"),B8,MAX(0,B28))*('Вводные'!$B$7/100))) -> 0 | C29: =IF(('Вводные'!$B$6="none"),0,(IF(('Вводные'!$B$6="revenue"),C8,MAX(0,C28))*('Вводные'!$B$7/100))) -> 0 | D29: =IF(('Вводные'!$B$6="none"),0,(IF(('Вводные'!$B$6="revenue"),D8,MAX(0,D28))*('Вводные'!$B$7/100))) -> 0 | E29: =IF(('Вводные'!$B$6="none"),0,(IF(('Вводные'!$B$6="revenue"),E8,MAX(0,E28))*('Вводные'!$B$7/100))) -> 0 | F29: =IF(('Вводные'!$B$6="none"),0,(IF(('Вводные'!$B$6="revenue"),F8,MAX(0,F28))*('Вводные'!$B$7/100))) -> 0 | G29: =IF(('Вводные'!$B$6="none"),0,(IF(('Вводные'!$B$6="revenue"),G8,MAX(0,G28))*('Вводные'!$B$7/100))) -> 0 | H29: =IF(('Вводные'!$B$6="none"),0,(IF(('Вводные'!$B$6="revenue"),H8,MAX(0,H28))*('Вводные'!$B$7/100))) -> 0 | I29: =IF(('Вводные'!$B$6="none"),0,(IF(('Вводные'!$B$6="revenue"),I8,MAX(0,I28))*('Вводные'!$B$7/100))) -> 0 | ... M29: =IF(('Вводные'!$B$6="none"),0,(IF(('Вводные'!$B$6="revenue"),M8,MAX(0,M28))*('Вводные'!$B$7/100))) -> 0 | N29: =SUM(B29:M29) -> 0 | O29: Ваша ставка × оборот или положительная прибыль месяца. Без переноса убытков. Оплата в том же месяце.
A30: Чистая прибыль | B30: =(B28-B29) -> 0 | C30: =(C28-C29) -> 0 | D30: =(D28-D29) -> 0 | E30: =(E28-E29) -> 0 | F30: =(F28-F29) -> 0 | G30: =(G28-G29) -> 0 | H30: =(H28-H29) -> 0 | I30: =(I28-I29) -> 0 | ... M30: =(M28-M29) -> 110 | N30: =SUM(B30:M30) -> 110 | O30: Выручка − себестоимость − команда − маркетинг − прочие − амортизация − проценты − налог.
A31: Все расходы в прибыли | B31: =(B8-B30) -> 0 | C31: =(C8-C30) -> 0 | D31: =(D8-D30) -> 0 | E31: =(E8-E30) -> 0 | F31: =(F8-F30) -> 0 | G31: =(G8-G30) -> 0 | H31: =(H8-H30) -> 0 | I31: =(I8-I30) -> 0 | ... M31: =(M8-M30) -> 0 | N31: =SUM(B31:M31) -> 0 | O31: Результат
A32: Оплата от клиентов | B32: =IF(1-'Вводные'!$B$8>0,INDEX($B$8:$M$8,1,MAX(1,1-'Вводные'!$B$8)),0) -> 0 | C32: =IF(2-'Вводные'!$B$8>0,INDEX($B$8:$M$8,1,MAX(1,2-'Вводные'!$B$8)),0) -> 0 | D32: =IF(3-'Вводные'!$B$8>0,INDEX($B$8:$M$8,1,MAX(1,3-'Вводные'!$B$8)),0) -> 0 | E32: =IF(4-'Вводные'!$B$8>0,INDEX($B$8:$M$8,1,MAX(1,4-'Вводные'!$B$8)),0) -> 0 | F32: =IF(5-'Вводные'!$B$8>0,INDEX($B$8:$M$8,1,MAX(1,5-'Вводные'!$B$8)),0) -> 0 | G32: =IF(6-'Вводные'!$B$8>0,INDEX($B$8:$M$8,1,MAX(1,6-'Вводные'!$B$8)),0) -> 0 | H32: =IF(7-'Вводные'!$B$8>0,INDEX($B$8:$M$8,1,MAX(1,7-'Вводные'!$B$8)),0) -> 0 | I32: =IF(8-'Вводные'!$B$8>0,INDEX($B$8:$M$8,1,MAX(1,8-'Вводные'!$B$8)),0) -> 0 | J32: =IF(9-'Вводные'!$B$8>0,INDEX($B$8:$M$8,1,MAX(1,9-'Вводные'!$B$8)),0) -> 0 | K32: =IF(10-'Вводные'!$B$8>0,INDEX($B$8:$M$8,1,MAX(1,10-'Вводные'!$B$8)),0) -> 0 | L32: =IF(11-'Вводные'!$B$8>0,INDEX($B$8:$M$8,1,MAX(1,11-'Вводные'!$B$8)),0) -> 0 | M32: =IF(12-'Вводные'!$B$8>0,INDEX($B$8:$M$8,1,MAX(1,12-'Вводные'!$B$8)),0) -> 110 | N32: =SUM(B32:M32) -> 110 | O32: Денежный поток
A33: Оплата себестоимости | B33: =IF(1-'Вводные'!$B$9>0,INDEX($B$9:$M$9,1,MAX(1,1-'Вводные'!$B$9)),0) -> 0 | C33: =IF(2-'Вводные'!$B$9>0,INDEX($B$9:$M$9,1,MAX(1,2-'Вводные'!$B$9)),0) -> 0 | D33: =IF(3-'Вводные'!$B$9>0,INDEX($B$9:$M$9,1,MAX(1,3-'Вводные'!$B$9)),0) -> 0 | E33: =IF(4-'Вводные'!$B$9>0,INDEX($B$9:$M$9,1,MAX(1,4-'Вводные'!$B$9)),0) -> 0 | F33: =IF(5-'Вводные'!$B$9>0,INDEX($B$9:$M$9,1,MAX(1,5-'Вводные'!$B$9)),0) -> 0 | G33: =IF(6-'Вводные'!$B$9>0,INDEX($B$9:$M$9,1,MAX(1,6-'Вводные'!$B$9)),0) -> 0 | H33: =IF(7-'Вводные'!$B$9>0,INDEX($B$9:$M$9,1,MAX(1,7-'Вводные'!$B$9)),0) -> 0 | I33: =IF(8-'Вводные'!$B$9>0,INDEX($B$9:$M$9,1,MAX(1,8-'Вводные'!$B$9)),0) -> 0 | J33: =IF(9-'Вводные'!$B$9>0,INDEX($B$9:$M$9,1,MAX(1,9-'Вводные'!$B$9)),0) -> 0 | K33: =IF(10-'Вводные'!$B$9>0,INDEX($B$9:$M$9,1,MAX(1,10-'Вводные'!$B$9)),0) -> 0 | L33: =IF(11-'Вводные'!$B$9>0,INDEX($B$9:$M$9,1,MAX(1,11-'Вводные'!$B$9)),0) -> 0 | M33: =IF(12-'Вводные'!$B$9>0,INDEX($B$9:$M$9,1,MAX(1,12-'Вводные'!$B$9)),0) -> 0 | N33: =SUM(B33:M33) -> 0 | O33: Денежный поток
A34: Дебиторская задолженность | B34: =(0+(B8-B32)) -> 0 | C34: =(B34+(C8-C32)) -> 0 | D34: =(C34+(D8-D32)) -> 0 | E34: =(D34+(E8-E32)) -> 0 | F34: =(E34+(F8-F32)) -> 0 | G34: =(F34+(G8-G32)) -> 0 | H34: =(G34+(H8-H32)) -> 0 | I34: =(H34+(I8-I32)) -> 0 | J34: =(I34+(J8-J32)) -> 0 | ... M34: =(L34+(M8-M32)) -> 0 | N34: =M34 -> 0 | O34: Оборотный капитал
A35: Кредиторская задолженность | B35: =(0+(B9-B33)) -> 0 | C35: =(B35+(C9-C33)) -> 0 | D35: =(C35+(D9-D33)) -> 0 | E35: =(D35+(E9-E33)) -> 0 | F35: =(E35+(F9-F33)) -> 0 | G35: =(F35+(G9-G33)) -> 0 | H35: =(G35+(H9-H33)) -> 0 | I35: =(H35+(I9-I33)) -> 0 | J35: =(I35+(J9-J33)) -> 0 | ... M35: =(L35+(M9-M33)) -> 0 | N35: =M35 -> 0 | O35: Оборотный капитал
A36: Операционный денежный поток | B36: =((B32-B33)-((B19+B25)+B29)) -> 0 | C36: =((C32-C33)-((C19+C25)+C29)) -> 0 | D36: =((D32-D33)-((D19+D25)+D29)) -> 0 | E36: =((E32-E33)-((E19+E25)+E29)) -> 0 | F36: =((F32-F33)-((F19+F25)+F29)) -> 0 | G36: =((G32-G33)-((G19+G25)+G29)) -> 0 | H36: =((H32-H33)-((H19+H25)+H29)) -> 0 | I36: =((I32-I33)-((I19+I25)+I29)) -> 0 | ... M36: =((M32-M33)-((M19+M25)+M29)) -> 110 | N36: =SUM(B36:M36) -> 110 | O36: Оплата клиентов − оплаченная себестоимость − операционные расходы − проценты − налог. Без амортизации.
A37: Изменение денег за месяц | B37: =((B36-B21)-B26) -> 0 | C37: =((C36-C21)-C26) -> 0 | D37: =((D36-D21)-D26) -> 0 | E37: =((E36-E21)-E26) -> 0 | F37: =((F36-F21)-F26) -> 0 | G37: =((G36-G21)-G26) -> 0 | H37: =((H36-H21)-H26) -> 0 | I37: =((I36-I21)-I26) -> 0 | ... M37: =((M36-M21)-M26) -> 110 | N37: =SUM(B37:M37) -> 110 | O37: Операционный поток − покупка активов − тело кредита.
A38: Деньги на конец месяца | B38: =(((('Вводные'!$B$10+'Вводные'!$B$11)+'Вводные'!$B$14)-'Вводные'!$B$12)+B37) -> -100 | C38: =(B38+C37) -> -100 | D38: =(C38+D37) -> -100 | E38: =(D38+E37) -> -100 | F38: =(E38+F37) -> -100 | G38: =(F38+G37) -> -100 | H38: =(G38+H37) -> -100 | I38: =(H38+I37) -> -100 | J38: =(I38+J37) -> -100 | ... M38: =(L38+M37) -> 10 | N38: =M38 -> 10 | O38: Старт = деньги на начало + взнос собственника + кредит − начальные вложения. Затем прибавляется изменение денег.
A39: Покрытие вложений, накопленно | B39: =((-1*'Вводные'!$B$12)+(B36-B21)) -> -100 | C39: =(B39+(C36-C21)) -> -100 | D39: =(C39+(D36-D21)) -> -100 | E39: =(D39+(E36-E21)) -> -100 | F39: =(E39+(F36-F21)) -> -100 | G39: =(F39+(G36-G21)) -> -100 | H39: =(G39+(H36-H21)) -> -100 | I39: =(H39+(I36-I21)) -> -100 | J39: =(I39+(J36-J21)) -> -100 | ... M39: =(L39+(M36-M21)) -> 10 | N39: =M39 -> 10 | O39: Накопленный операционный поток − вложения. Без взносов, выдачи и тела кредита; после процентов. Поздние покупки могут снова уменьшить показатель.
A40: Свободный поток после покупок | B40: =(B36-B21) -> 0 | C40: =(C36-C21) -> 0 | D40: =(D36-D21) -> 0 | E40: =(E36-E21) -> 0 | F40: =(F36-F21) -> 0 | G40: =(G36-G21) -> 0 | H40: =(H36-H21) -> 0 | I40: =(I36-I21) -> 0 | ... M40: =(M36-M21) -> 110 | N40: =SUM(B40:M40) -> 110 | O40: Операционный поток − покупка активов, до погашения тела кредита.
...

Sheet Вводные
A1: ВВОДНЫЕ / Мой бизнес
A2: Редактируйте колонку B. Суммы в KZT. Проценты задаются числом: 10 = 10%.
A3: Параметр | B3: Значение | C3: Пояснение
A4: Способ ввода выручки | B4: manual | C4: items — товары; manual — ручной оборот
A5: Себестоимость ручного оборота, % | B5: 0
A6: База условного налога | B6: none | C6: profit — прибыль; revenue — оборот; none — без налога
A7: Ставка налога, % | B7: 10
A8: Оплата клиентов через, мес. | B8: 0 | C8: Целые месяцы от 0 до 12
A9: Оплата себестоимости через, мес. | B9: 0 | C9: Целые месяцы от 0 до 12
A10: Деньги на начало | B10: 0
A11: Взнос собственника до М1 | B11: 0
A12: Вложения до М1 | B12: 100
A13: Амортизация начальных вложений, мес. (0 — нет) | B13: 0 | C13: 0 отключает амортизацию начальных вложений
A14: Кредит до М1 | B14: 0
A15: Годовая ставка кредита, % | B15: 18
A16: Срок кредита, мес. | B16: 24
A17: Дисконтирование: эффективная годовая ставка, % | B17: 10
A18: Валовая маржа рекламных продаж, % | B18: 65
A19: Средний собственный капитал за год | B19: 200
A20: Средние активы за год | B20: 400
A21: Выручка на клиента за месяц | B21: 0
A22: Валовая маржа клиента, % | B22: 65
A23: Средний срок жизни клиента, мес. | B23: 12
A24: Прочие затраты на привлечение за год, уже в расходах | B24: 0
A25: Начальная сумма накоплений | B25: 1000
... A28: Пополнение в конце каждого месяца | B28: 100
A29: Множитель сценария | B29: 1 | C29: База: 1; осторожный: 0.8; оптимистичный: 1.2
A30: Ручной оборот · М1 | B30: 0
A31: Ручной оборот · М2 | B31: 0
A32: Ручной оборот · М3 | B32: 0
A33: Ручной оборот · М4 | B33: 0
A34: Ручной оборот · М5 | B34: 0
A35: Ручной оборот · М6 | B35: 0
A36: Ручной оборот · М7 | B36: 0
A37: Ручной оборот · М8 | B37: 0
A38: Ручной оборот · М9 | B38: 0
A39: Ручной оборот · М10 | B39: 0
A40: Ручной оборот · М11 | B40: 0
A41: Ручной оборот · М12 | B41: 110
A42: Основной продукт · Название | B42: Основной продукт
...

Sheet Показатели
A1: Доходность, клиенты и сложные проценты
A2: Все показатели бизнеса — за 12 месяцев выбранного сценария. Накопления — отдельный расчёт.
A3: Показатель | B3: Значение | C3: Формула и условия
A4: ROI | B4: =IF('Модель'!N42>0,'Модель'!N30/'Модель'!N42,"") -> 1.1 | C4: Чистая прибыль / все инвестиции. Учётная доходность за горизонт модели.
A5: ROMI | B5: =IF(TRUE,IF('Модель'!N14>0,('Модель'!N17*'Вводные'!B18/100-'Модель'!N14)/'Модель'!N14,""),"") | C5: (Рекламная выручка × валовая маржа − маркетинг) / маркетинг. Оценка атрибуции, не причинный прирост.
A6: ROAS, раз | B6: =IF(TRUE,IF('Модель'!N14>0,'Модель'!N17/'Модель'!N14,""),"") | C6: Оценка рекламной выручки / бюджет каналов.
A7: RR: рентабельность затрат | B7: =IF('Модель'!N31>0,'Модель'!N30/'Модель'!N31,"") | C7: Чистая прибыль / все расходы в прибыли.
A8: Маржа чистой прибыли | B8: =IF('Модель'!N8>0,'Модель'!N30/'Модель'!N8,"") -> 1 | C8: Чистая прибыль / выручка.
A9: Срок окупаемости, мес. | B9: =IF(MIN(C41:N41)<1000000000,MIN(C41:N41),"Не достигнут") -> 11.909091 | C9: Первое покрытие отрицательного накопленного потока. Доля месяца — линейная интерполяция.
A10: Дисконтированный срок, мес. | B10: =IF(MIN(C42:N42)<1000000000,MIN(C42:N42),"Не достигнут") -> Не достигнут | C10: Первое покрытие дисконтированных вложений; горизонт 12 месяцев.
A11: NPV | B11: =SUM(B36:N36) -> -2.8421709e-14 | C11: Начальные вложения и свободные потоки после процентов и налога; без выдачи и тела кредита, без остаточной стоимости.
A12: IRR: эффективная годовая | B12: =IF(ISNUMBER(B13),(1+B13)^12-1,"Не определена / неоднозначна") -> 0.1 | C12: (1 + месячная IRR)^12 − 1.
A13: IRR: месячная | B13: =IF(AND(MIN(B35:N35)<0,MAX(B35:N35)>0,SUM(B40:N40)=1),IFERROR(IRR(B35:N35,0.007974140428903738),"Нет сходимости"),"Не определена / неоднозначна") -> 0.0079741404 | C13: Ставка, при которой NPV = 0. При нескольких сменах знака не показывается как однозначная.
A14: ROE | B14: =IF('Вводные'!B19>0,'Модель'!N30/'Вводные'!B19,"") -> 0.55 | C14: Чистая прибыль / введённый средний собственный капитал за год.
A15: ROA | B15: =IF('Вводные'!B20>0,'Модель'!N30/'Вводные'!B20,"") -> 0.275 | C15: Чистая прибыль / введённые средние активы за год.
A16: LTV: валовая прибыль | B16: =IF('Вводные'!B21>0,'Вводные'!B21*'Вводные'!B22/100*'Вводные'!B23,"") | C16: Месячная выручка на клиента × валовая маржа × срок жизни. До привлечения, без дисконтирования.
A17: CAC: стоимость нового клиента | B17: =IF(TRUE,IF('Модель'!N16>0,('Модель'!N14+'Вводные'!B24)/'Модель'!N16,""),"") | C17: Маркетинг и прочие затраты на привлечение / новые клиенты воронки. Прочие затраты уже должны быть в расходах.
A18: LTV / CAC, раз | B18: =IF(AND(ISNUMBER(B16),ISNUMBER(B17),B17>0),B16/B17,"") | C18: Валовая прибыль за жизнь клиента / стоимость привлечения.
A20: Месячная ставка дисконтирования | B20: =(1+'Вводные'!B17/100)^(1/12)-1 -> 0.0079741404 | C20: Эквивалент эффективной годовой ставки.
A23: Сложные проценты: отдельный калькулятор
A24: Месячная ставка накоплений | B24: =(1+'Вводные'!B26/100)^(1/12)-1 -> 0 | C24: Эквивалент эффективной годовой ставки.
A25: Будущая сумма | B25: ='Вводные'!B25*(1+B24)^'Вводные'!B27+'Вводные'!B28*IF(B24=0,'Вводные'!B27,((1+B24)^'Вводные'!B27-1)/B24) -> 2200 | C25: Начальная сумма с капитализацией плюс пополнения в конце каждого месяца. Не включено в модель бизнеса.
A26: Всего внесено | B26: ='Вводные'!B25+'Вводные'!B28*'Вводные'!B27 -> 2200 | C26: Начальная сумма + все пополнения.
A27: Начислено процентов | B27: =B25-B26 -> 0 | C27: Будущая сумма − внесённые средства.
A30: NPV: https://corporatefinanceinstitute.com/resources/valuation/net-present-value-npv/
A31: IRR: https://corporatefinanceinstitute.com/resources/valuation/internal-rate-return-irr/
A34: Потоки и проверка окупаемости | B34: М0 | C34: М1 | D34: М2 | E34: М3 | F34: М4 | G34: М5 | H34: М6 | I34: М7 | J34: М8 | K34: М9 | L34: М10 | M34: М11 | N34: М12
A35: Свободный денежный поток | B35: =-'Вводные'!B12 -> -100 | C35: ='Модель'!B40 -> 0 | D35: ='Модель'!C40 -> 0 | E35: ='Модель'!D40 -> 0 | F35: ='Модель'!E40 -> 0 | G35: ='Модель'!F40 -> 0 | H35: ='Модель'!G40 -> 0 | I35: ='Модель'!H40 -> 0 | J35: ='Модель'!I40 -> 0 | ... N35: ='Модель'!M40 -> 110
A36: Дисконтированный поток | B36: =B35/(1+$B$20)^0 -> -100 | C36: =C35/(1+$B$20)^1 -> 0 | D36: =D35/(1+$B$20)^2 -> 0 | E36: =E35/(1+$B$20)^3 -> 0 | F36: =F35/(1+$B$20)^4 -> 0 | G36: =G35/(1+$B$20)^5 -> 0 | H36: =H35/(1+$B$20)^6 -> 0 | I36: =I35/(1+$B$20)^7 -> 0 | J36: =J35/(1+$B$20)^8 -> 0 | K36: =K35/(1+$B$20)^9 -> 0 | L36: =L35/(1+$B$20)^10 -> 0 | M36: =M35/(1+$B$20)^11 -> 0 | N36: =N35/(1+$B$20)^12 -> 100
A37: Поток накопленно | B37: =B35 -> -100 | C37: =B37+C35 -> -100 | D37: =C37+D35 -> -100 | E37: =D37+E35 -> -100 | F37: =E37+F35 -> -100 | G37: =F37+G35 -> -100 | H37: =G37+H35 -> -100 | I37: =H37+I35 -> -100 | J37: =I37+J35 -> -100 | ... N37: =M37+N35 -> 10
A38: Дисконтированный накопленно | B38: =B36 -> -100 | C38: =B38+C36 -> -100 | D38: =C38+D36 -> -100 | E38: =D38+E36 -> -100 | F38: =E38+F36 -> -100 | G38: =F38+G36 -> -100 | H38: =G38+H36 -> -100 | I38: =H38+I36 -> -100 | J38: =I38+J36 -> -100 | ... N38: =M38+N36 -> -2.8421709e-14
A39: Последний ненулевой знак | B39: =SIGN(B35) -> -1 | C39: =IF(C35=0,B39,SIGN(C35)) -> -1 | D39: =IF(D35=0,C39,SIGN(D35)) -> -1 | E39: =IF(E35=0,D39,SIGN(E35)) -> -1 | F39: =IF(F35=0,E39,SIGN(F35)) -> -1 | G39: =IF(G35=0,F39,SIGN(G35)) -> -1 | H39: =IF(H35=0,G39,SIGN(H35)) -> -1 | I39: =IF(I35=0,H39,SIGN(I35)) -> -1 | J39: =IF(J35=0,I39,SIGN(J35)) -> -1 | ... N39: =IF(N35=0,M39,SIGN(N35)) -> 1
A40: Смена знака | B40: =0 -> 0 | C40: =IF(AND(B39<>0,C35<>0,B39<>SIGN(C35)),1,0) -> 0 | D40: =IF(AND(C39<>0,D35<>0,C39<>SIGN(D35)),1,0) -> 0 | E40: =IF(AND(D39<>0,E35<>0,D39<>SIGN(E35)),1,0) -> 0 | F40: =IF(AND(E39<>0,F35<>0,E39<>SIGN(F35)),1,0) -> 0 | G40: =IF(AND(F39<>0,G35<>0,F39<>SIGN(G35)),1,0) -> 0 | H40: =IF(AND(G39<>0,H35<>0,G39<>SIGN(H35)),1,0) -> 0 | I40: =IF(AND(H39<>0,I35<>0,H39<>SIGN(I35)),1,0) -> 0 | J40: =IF(AND(I39<>0,J35<>0,I39<>SIGN(J35)),1,0) -> 0 | ... N40: =IF(AND(M39<>0,N35<>0,M39<>SIGN(N35)),1,0) -> 1
A41: Кандидат срока, 1e9 = нет | B41: =1000000000 -> 1000000000 | C41: =IF(AND(B37<0,C37>=0,C35>0),0-B37/C35,1000000000) -> 1000000000 | D41: =IF(AND(C37<0,D37>=0,D35>0),1-C37/D35,1000000000) -> 1000000000 | E41: =IF(AND(D37<0,E37>=0,E35>0),2-D37/E35,1000000000) -> 1000000000 | F41: =IF(AND(E37<0,F37>=0,F35>0),3-E37/F35,1000000000) -> 1000000000 | G41: =IF(AND(F37<0,G37>=0,G35>0),4-F37/G35,1000000000) -> 1000000000 | H41: =IF(AND(G37<0,H37>=0,H35>0),5-G37/H35,1000000000) -> 1000000000 | I41: =IF(AND(H37<0,I37>=0,I35>0),6-H37/I35,1000000000) -> 1000000000 | J41: =IF(AND(I37<0,J37>=0,J35>0),7-I37/J35,1000000000) -> 1000000000 | K41: =IF(AND(J37<0,K37>=0,K35>0),8-J37/K35,1000000000) -> 1000000000 | L41: =IF(AND(K37<0,L37>=0,L35>0),9-K37/L35,1000000000) -> 1000000000 | M41: =IF(AND(L37<0,M37>=0,M35>0),10-L37/M35,1000000000) -> 1000000000 | N41: =IF(AND(M37<0,N37>=0,N35>0),11-M37/N35,1000000000) -> 11.909091
A42: Дисконт. кандидат, 1e9 = нет | B42: =1000000000 -> 1000000000 | C42: =IF(AND(B38<0,C38>=0,C36>0),0-B38/C36,1000000000) -> 1000000000 | D42: =IF(AND(C38<0,D38>=0,D36>0),1-C38/D36,1000000000) -> 1000000000 | E42: =IF(AND(D38<0,E38>=0,E36>0),2-D38/E36,1000000000) -> 1000000000 | F42: =IF(AND(E38<0,F38>=0,F36>0),3-E38/F36,1000000000) -> 1000000000 | G42: =IF(AND(F38<0,G38>=0,G36>0),4-F38/G36,1000000000) -> 1000000000 | H42: =IF(AND(G38<0,H38>=0,H36>0),5-G38/H36,1000000000) -> 1000000000 | I42: =IF(AND(H38<0,I38>=0,I36>0),6-H38/I36,1000000000) -> 1000000000 | J42: =IF(AND(I38<0,J38>=0,J36>0),7-I38/J36,1000000000) -> 1000000000 | K42: =IF(AND(J38<0,K38>=0,K36>0),8-J38/K36,1000000000) -> 1000000000 | L42: =IF(AND(K38<0,L38>=0,L36>0),9-K38/L36,1000000000) -> 1000000000 | M42: =IF(AND(L38<0,M38>=0,M36>0),10-L38/M36,1000000000) -> 1000000000 | N42: =IF(AND(M38<0,N38>=0,N36>0),11-M38/N36,1000000000) -> 1000000000
