Workbook

Sheet Модель
A1: КОНТУР / Мой бизнес
A2: Базовый · KZT · 12 месяцев. Потоки — сумма; остатки — на конец М12.
A3: Чистая прибыль | B3: =N40 -> 13414745 | D3: Выручка | E3: =N8 -> 38315804 | G3: Деньги на конец | H3: =M48 -> 14414745
A4: Показатель | B4: М1 | C4: М2 | D4: М3 | E4: М4 | F4: М5 | G4: М6 | H4: М7 | I4: М8 | J4: М9 | K4: М10 | L4: М11 | M4: М12 | N4: Год / конец | O4: Как считается
A5: Основной продукт · количество | B5: =IF(AND((1>='Вводные'!$B$47),(1<='Вводные'!$B$48)),(('Вводные'!$B$43*'Вводные'!$B$29)*((1+('Вводные'!$B$45/100))^MAX(0,(1-'Вводные'!$B$47)))),0) -> 300 | C5: =IF(AND((2>='Вводные'!$B$47),(2<='Вводные'!$B$48)),(('Вводные'!$B$43*'Вводные'!$B$29)*((1+('Вводные'!$B$45/100))^MAX(0,(2-'Вводные'!$B$47)))),0) -> 312 | D5: =IF(AND((3>='Вводные'!$B$47),(3<='Вводные'!$B$48)),(('Вводные'!$B$43*'Вводные'!$B$29)*((1+('Вводные'!$B$45/100))^MAX(0,(3-'Вводные'!$B$47)))),0) -> 324.48 | E5: =IF(AND((4>='Вводные'!$B$47),(4<='Вводные'!$B$48)),(('Вводные'!$B$43*'Вводные'!$B$29)*((1+('Вводные'!$B$45/100))^MAX(0,(4-'Вводные'!$B$47)))),0) -> 337.4592 | F5: =IF(AND((5>='Вводные'!$B$47),(5<='Вводные'!$B$48)),(('Вводные'!$B$43*'Вводные'!$B$29)*((1+('Вводные'!$B$45/100))^MAX(0,(5-'Вводные'!$B$47)))),0) -> 350.95757 | G5: =IF(AND((6>='Вводные'!$B$47),(6<='Вводные'!$B$48)),(('Вводные'!$B$43*'Вводные'!$B$29)*((1+('Вводные'!$B$45/100))^MAX(0,(6-'Вводные'!$B$47)))),0) -> 364.99587 | H5: =IF(AND((7>='Вводные'!$B$47),(7<='Вводные'!$B$48)),(('Вводные'!$B$43*'Вводные'!$B$29)*((1+('Вводные'!$B$45/100))^MAX(0,(7-'Вводные'!$B$47)))),0) -> 379.59571 | I5: =IF(AND((8>='Вводные'!$B$47),(8<='Вводные'!$B$48)),(('Вводные'!$B$43*'Вводные'!$B$29)*((1+('Вводные'!$B$45/100))^MAX(0,(8-'Вводные'!$B$47)))),0) -> 394.77953 | J5: =IF(AND((9>='Вводные'!$B$47),(9<='Вводные'!$B$48)),(('Вводные'!$B$43*'Вводные'!$B$29)*((1+('Вводные'!$B$45/100))^MAX(0,(9-'Вводные'!$B$47)))),0) -> 410.57072 | K5: =IF(AND((10>='Вводные'!$B$47),(10<='Вводные'!$B$48)),(('Вводные'!$B$43*'Вводные'!$B$29)*((1+('Вводные'!$B$45/100))^MAX(0,(10-'Вводные'!$B$47)))),0) -> 426.99354 | L5: =IF(AND((11>='Вводные'!$B$47),(11<='Вводные'!$B$48)),(('Вводные'!$B$43*'Вводные'!$B$29)*((1+('Вводные'!$B$45/100))^MAX(0,(11-'Вводные'!$B$47)))),0) -> 444.07329 | M5: =IF(AND((12>='Вводные'!$B$47),(12<='Вводные'!$B$48)),(('Вводные'!$B$43*'Вводные'!$B$29)*((1+('Вводные'!$B$45/100))^MAX(0,(12-'Вводные'!$B$47)))),0) -> 461.83622 | N5: =SUM(B5:M5) -> 4507.7416 | O5: Продажи
A6: Основной продукт · выручка | B6: =(B5*'Вводные'!$B$44) -> 2550000 | C6: =(C5*'Вводные'!$B$44) -> 2652000 | D6: =(D5*'Вводные'!$B$44) -> 2758080 | E6: =(E5*'Вводные'!$B$44) -> 2868403.2 | F6: =(F5*'Вводные'!$B$44) -> 2983139.3 | G6: =(G5*'Вводные'!$B$44) -> 3102464.9 | H6: =(H5*'Вводные'!$B$44) -> 3226563.5 | I6: =(I5*'Вводные'!$B$44) -> 3355626 | ... M6: =(M5*'Вводные'!$B$44) -> 3925607.8 | N6: =SUM(B6:M6) -> 38315804 | O6: Продажи
A7: Основной продукт · себестоимость | B7: =(B6*('Вводные'!$B$46/100)) -> 892500 | C7: =(C6*('Вводные'!$B$46/100)) -> 928200 | D7: =(D6*('Вводные'!$B$46/100)) -> 965328 | E7: =(E6*('Вводные'!$B$46/100)) -> 1003941.1 | F7: =(F6*('Вводные'!$B$46/100)) -> 1044098.8 | G7: =(G6*('Вводные'!$B$46/100)) -> 1085862.7 | H7: =(H6*('Вводные'!$B$46/100)) -> 1129297.2 | I7: =(I6*('Вводные'!$B$46/100)) -> 1174469.1 | ... M7: =(M6*('Вводные'!$B$46/100)) -> 1373962.7 | N7: =SUM(B7:M7) -> 13410531 | O7: Продажи
A8: Выручка / оборот | B8: =IF(('Вводные'!$B$4="manual"),('Вводные'!$B$30*'Вводные'!$B$29),B6) -> 2550000 | C8: =IF(('Вводные'!$B$4="manual"),('Вводные'!$B$31*'Вводные'!$B$29),C6) -> 2652000 | D8: =IF(('Вводные'!$B$4="manual"),('Вводные'!$B$32*'Вводные'!$B$29),D6) -> 2758080 | E8: =IF(('Вводные'!$B$4="manual"),('Вводные'!$B$33*'Вводные'!$B$29),E6) -> 2868403.2 | F8: =IF(('Вводные'!$B$4="manual"),('Вводные'!$B$34*'Вводные'!$B$29),F6) -> 2983139.3 | G8: =IF(('Вводные'!$B$4="manual"),('Вводные'!$B$35*'Вводные'!$B$29),G6) -> 3102464.9 | H8: =IF(('Вводные'!$B$4="manual"),('Вводные'!$B$36*'Вводные'!$B$29),H6) -> 3226563.5 | I8: =IF(('Вводные'!$B$4="manual"),('Вводные'!$B$37*'Вводные'!$B$29),I6) -> 3355626 | J8: =IF(('Вводные'!$B$4="manual"),('Вводные'!$B$38*'Вводные'!$B$29),J6) -> 3489851.1 | K8: =IF(('Вводные'!$B$4="manual"),('Вводные'!$B$39*'Вводные'!$B$29),K6) -> 3629445.1 | L8: =IF(('Вводные'!$B$4="manual"),('Вводные'!$B$40*'Вводные'!$B$29),L6) -> 3774622.9 | M8: =IF(('Вводные'!$B$4="manual"),('Вводные'!$B$41*'Вводные'!$B$29),M6) -> 3925607.8 | N8: =SUM(B8:M8) -> 38315804 | O8: По продуктам: количество × цена. Вручную: введённый оборот. Сценарий применяется один раз.
A9: Себестоимость продаж | B9: =IF(('Вводные'!$B$4="manual"),(B8*('Вводные'!$B$5/100)),B7) -> 892500 | C9: =IF(('Вводные'!$B$4="manual"),(C8*('Вводные'!$B$5/100)),C7) -> 928200 | D9: =IF(('Вводные'!$B$4="manual"),(D8*('Вводные'!$B$5/100)),D7) -> 965328 | E9: =IF(('Вводные'!$B$4="manual"),(E8*('Вводные'!$B$5/100)),E7) -> 1003941.1 | F9: =IF(('Вводные'!$B$4="manual"),(F8*('Вводные'!$B$5/100)),F7) -> 1044098.8 | G9: =IF(('Вводные'!$B$4="manual"),(G8*('Вводные'!$B$5/100)),G7) -> 1085862.7 | H9: =IF(('Вводные'!$B$4="manual"),(H8*('Вводные'!$B$5/100)),H7) -> 1129297.2 | I9: =IF(('Вводные'!$B$4="manual"),(I8*('Вводные'!$B$5/100)),I7) -> 1174469.1 | ... M9: =IF(('Вводные'!$B$4="manual"),(M8*('Вводные'!$B$5/100)),M7) -> 1373962.7 | N9: =SUM(B9:M9) -> 13410531 | O9: Себестоимость продуктов или доля ручного оборота. Не дублируйте её в прочих расходах.
A10: Валовая прибыль | B10: =(B8-B9) -> 1657500 | C10: =(C8-C9) -> 1723800 | D10: =(D8-D9) -> 1792752 | E10: =(E8-E9) -> 1864462.1 | F10: =(F8-F9) -> 1939040.6 | G10: =(G8-G9) -> 2016602.2 | H10: =(H8-H9) -> 2097266.3 | I10: =(I8-I9) -> 2181156.9 | ... M10: =(M8-M9) -> 2551645.1 | N10: =SUM(B10:M10) -> 24905273 | O10: Выручка − себестоимость.
A11: Менеджер · оклады и бонусы | B11: =IF(AND((1>='Вводные'!$B$55),(1<='Вводные'!$B$56)),(('Вводные'!$B$50*('Вводные'!$B$51+'Вводные'!$B$52))*((1+('Вводные'!$B$54/100))^MAX(0,(1-'Вводные'!$B$55)))),0) -> 300000 | C11: =IF(AND((2>='Вводные'!$B$55),(2<='Вводные'!$B$56)),(('Вводные'!$B$50*('Вводные'!$B$51+'Вводные'!$B$52))*((1+('Вводные'!$B$54/100))^MAX(0,(2-'Вводные'!$B$55)))),0) -> 300000 | D11: =IF(AND((3>='Вводные'!$B$55),(3<='Вводные'!$B$56)),(('Вводные'!$B$50*('Вводные'!$B$51+'Вводные'!$B$52))*((1+('Вводные'!$B$54/100))^MAX(0,(3-'Вводные'!$B$55)))),0) -> 300000 | E11: =IF(AND((4>='Вводные'!$B$55),(4<='Вводные'!$B$56)),(('Вводные'!$B$50*('Вводные'!$B$51+'Вводные'!$B$52))*((1+('Вводные'!$B$54/100))^MAX(0,(4-'Вводные'!$B$55)))),0) -> 300000 | F11: =IF(AND((5>='Вводные'!$B$55),(5<='Вводные'!$B$56)),(('Вводные'!$B$50*('Вводные'!$B$51+'Вводные'!$B$52))*((1+('Вводные'!$B$54/100))^MAX(0,(5-'Вводные'!$B$55)))),0) -> 300000 | G11: =IF(AND((6>='Вводные'!$B$55),(6<='Вводные'!$B$56)),(('Вводные'!$B$50*('Вводные'!$B$51+'Вводные'!$B$52))*((1+('Вводные'!$B$54/100))^MAX(0,(6-'Вводные'!$B$55)))),0) -> 300000 | H11: =IF(AND((7>='Вводные'!$B$55),(7<='Вводные'!$B$56)),(('Вводные'!$B$50*('Вводные'!$B$51+'Вводные'!$B$52))*((1+('Вводные'!$B$54/100))^MAX(0,(7-'Вводные'!$B$55)))),0) -> 300000 | I11: =IF(AND((8>='Вводные'!$B$55),(8<='Вводные'!$B$56)),(('Вводные'!$B$50*('Вводные'!$B$51+'Вводные'!$B$52))*((1+('Вводные'!$B$54/100))^MAX(0,(8-'Вводные'!$B$55)))),0) -> 300000 | J11: =IF(AND((9>='Вводные'!$B$55),(9<='Вводные'!$B$56)),(('Вводные'!$B$50*('Вводные'!$B$51+'Вводные'!$B$52))*((1+('Вводные'!$B$54/100))^MAX(0,(9-'Вводные'!$B$55)))),0) -> 300000 | K11: =IF(AND((10>='Вводные'!$B$55),(10<='Вводные'!$B$56)),(('Вводные'!$B$50*('Вводные'!$B$51+'Вводные'!$B$52))*((1+('Вводные'!$B$54/100))^MAX(0,(10-'Вводные'!$B$55)))),0) -> 300000 | L11: =IF(AND((11>='Вводные'!$B$55),(11<='Вводные'!$B$56)),(('Вводные'!$B$50*('Вводные'!$B$51+'Вводные'!$B$52))*((1+('Вводные'!$B$54/100))^MAX(0,(11-'Вводные'!$B$55)))),0) -> 300000 | M11: =IF(AND((12>='Вводные'!$B$55),(12<='Вводные'!$B$56)),(('Вводные'!$B$50*('Вводные'!$B$51+'Вводные'!$B$52))*((1+('Вводные'!$B$54/100))^MAX(0,(12-'Вводные'!$B$55)))),0) -> 300000 | N11: =SUM(B11:M11) -> 3600000 | O11: Команда
A12: Менеджер · начисления | B12: =(B11*('Вводные'!$B$53/100)) -> 45000 | C12: =(C11*('Вводные'!$B$53/100)) -> 45000 | D12: =(D11*('Вводные'!$B$53/100)) -> 45000 | E12: =(E11*('Вводные'!$B$53/100)) -> 45000 | F12: =(F11*('Вводные'!$B$53/100)) -> 45000 | G12: =(G11*('Вводные'!$B$53/100)) -> 45000 | H12: =(H11*('Вводные'!$B$53/100)) -> 45000 | I12: =(I11*('Вводные'!$B$53/100)) -> 45000 | ... M12: =(M11*('Вводные'!$B$53/100)) -> 45000 | N12: =SUM(B12:M12) -> 540000 | O12: Команда
A13: Оклады и бонусы | B13: =B11 -> 300000 | C13: =C11 -> 300000 | D13: =D11 -> 300000 | E13: =E11 -> 300000 | F13: =F11 -> 300000 | G13: =G11 -> 300000 | H13: =H11 -> 300000 | I13: =I11 -> 300000 | ... M13: =M11 -> 300000 | N13: =SUM(B13:M13) -> 3600000 | O13: Команда
A14: Начисления работодателя | B14: =B12 -> 45000 | C14: =C12 -> 45000 | D14: =D12 -> 45000 | E14: =E12 -> 45000 | F14: =F12 -> 45000 | G14: =G12 -> 45000 | H14: =H12 -> 45000 | I14: =I12 -> 45000 | ... M14: =M12 -> 45000 | N14: =SUM(B14:M14) -> 540000 | O14: Команда
A15: Команда — всего | B15: =(B13+B14) -> 345000 | C15: =(C13+C14) -> 345000 | D15: =(D13+D14) -> 345000 | E15: =(E13+E14) -> 345000 | F15: =(F13+F14) -> 345000 | G15: =(G13+G14) -> 345000 | H15: =(H13+H14) -> 345000 | I15: =(I13+I14) -> 345000 | ... M15: =(M13+M14) -> 345000 | N15: =SUM(B15:M15) -> 4140000 | O15: Количество × (оклад + бонус) × рост × (1 + начисления). Ставки задаёте вы.
A16: Реклама · затраты | B16: =IF(AND((1>='Вводные'!$B$65),(1<='Вводные'!$B$66)),(('Вводные'!$B$58*((1+('Вводные'!$B$60/100))^MAX(0,(1-'Вводные'!$B$65))))+(B8*('Вводные'!$B$59/100))),0) -> 120000 | C16: =IF(AND((2>='Вводные'!$B$65),(2<='Вводные'!$B$66)),(('Вводные'!$B$58*((1+('Вводные'!$B$60/100))^MAX(0,(2-'Вводные'!$B$65))))+(C8*('Вводные'!$B$59/100))),0) -> 120000 | D16: =IF(AND((3>='Вводные'!$B$65),(3<='Вводные'!$B$66)),(('Вводные'!$B$58*((1+('Вводные'!$B$60/100))^MAX(0,(3-'Вводные'!$B$65))))+(D8*('Вводные'!$B$59/100))),0) -> 120000 | E16: =IF(AND((4>='Вводные'!$B$65),(4<='Вводные'!$B$66)),(('Вводные'!$B$58*((1+('Вводные'!$B$60/100))^MAX(0,(4-'Вводные'!$B$65))))+(E8*('Вводные'!$B$59/100))),0) -> 120000 | F16: =IF(AND((5>='Вводные'!$B$65),(5<='Вводные'!$B$66)),(('Вводные'!$B$58*((1+('Вводные'!$B$60/100))^MAX(0,(5-'Вводные'!$B$65))))+(F8*('Вводные'!$B$59/100))),0) -> 120000 | G16: =IF(AND((6>='Вводные'!$B$65),(6<='Вводные'!$B$66)),(('Вводные'!$B$58*((1+('Вводные'!$B$60/100))^MAX(0,(6-'Вводные'!$B$65))))+(G8*('Вводные'!$B$59/100))),0) -> 120000 | H16: =IF(AND((7>='Вводные'!$B$65),(7<='Вводные'!$B$66)),(('Вводные'!$B$58*((1+('Вводные'!$B$60/100))^MAX(0,(7-'Вводные'!$B$65))))+(H8*('Вводные'!$B$59/100))),0) -> 120000 | I16: =IF(AND((8>='Вводные'!$B$65),(8<='Вводные'!$B$66)),(('Вводные'!$B$58*((1+('Вводные'!$B$60/100))^MAX(0,(8-'Вводные'!$B$65))))+(I8*('Вводные'!$B$59/100))),0) -> 120000 | J16: =IF(AND((9>='Вводные'!$B$65),(9<='Вводные'!$B$66)),(('Вводные'!$B$58*((1+('Вводные'!$B$60/100))^MAX(0,(9-'Вводные'!$B$65))))+(J8*('Вводные'!$B$59/100))),0) -> 120000 | K16: =IF(AND((10>='Вводные'!$B$65),(10<='Вводные'!$B$66)),(('Вводные'!$B$58*((1+('Вводные'!$B$60/100))^MAX(0,(10-'Вводные'!$B$65))))+(K8*('Вводные'!$B$59/100))),0) -> 120000 | L16: =IF(AND((11>='Вводные'!$B$65),(11<='Вводные'!$B$66)),(('Вводные'!$B$58*((1+('Вводные'!$B$60/100))^MAX(0,(11-'Вводные'!$B$65))))+(L8*('Вводные'!$B$59/100))),0) -> 120000 | M16: =IF(AND((12>='Вводные'!$B$65),(12<='Вводные'!$B$66)),(('Вводные'!$B$58*((1+('Вводные'!$B$60/100))^MAX(0,(12-'Вводные'!$B$65))))+(M8*('Вводные'!$B$59/100))),0) -> 120000 | N16: =SUM(B16:M16) -> 1440000 | O16: Маркетинг
A17: Реклама · клики | B17: =IF(('Вводные'!$B$61>0),(B16/'Вводные'!$B$61),0) -> 800 | C17: =IF(('Вводные'!$B$61>0),(C16/'Вводные'!$B$61),0) -> 800 | D17: =IF(('Вводные'!$B$61>0),(D16/'Вводные'!$B$61),0) -> 800 | E17: =IF(('Вводные'!$B$61>0),(E16/'Вводные'!$B$61),0) -> 800 | F17: =IF(('Вводные'!$B$61>0),(F16/'Вводные'!$B$61),0) -> 800 | G17: =IF(('Вводные'!$B$61>0),(G16/'Вводные'!$B$61),0) -> 800 | H17: =IF(('Вводные'!$B$61>0),(H16/'Вводные'!$B$61),0) -> 800 | I17: =IF(('Вводные'!$B$61>0),(I16/'Вводные'!$B$61),0) -> 800 | ... M17: =IF(('Вводные'!$B$61>0),(M16/'Вводные'!$B$61),0) -> 800 | N17: =SUM(B17:M17) -> 9600 | O17: Маркетинг
A18: Реклама · заявки | B18: =(B17*('Вводные'!$B$62/100)) -> 80 | C18: =(C17*('Вводные'!$B$62/100)) -> 80 | D18: =(D17*('Вводные'!$B$62/100)) -> 80 | E18: =(E17*('Вводные'!$B$62/100)) -> 80 | F18: =(F17*('Вводные'!$B$62/100)) -> 80 | G18: =(G17*('Вводные'!$B$62/100)) -> 80 | H18: =(H17*('Вводные'!$B$62/100)) -> 80 | I18: =(I17*('Вводные'!$B$62/100)) -> 80 | ... M18: =(M17*('Вводные'!$B$62/100)) -> 80 | N18: =SUM(B18:M18) -> 960 | O18: Маркетинг
A19: Реклама · клиенты | B19: =(B18*('Вводные'!$B$63/100)) -> 16 | C19: =(C18*('Вводные'!$B$63/100)) -> 16 | D19: =(D18*('Вводные'!$B$63/100)) -> 16 | E19: =(E18*('Вводные'!$B$63/100)) -> 16 | F19: =(F18*('Вводные'!$B$63/100)) -> 16 | G19: =(G18*('Вводные'!$B$63/100)) -> 16 | H19: =(H18*('Вводные'!$B$63/100)) -> 16 | I19: =(I18*('Вводные'!$B$63/100)) -> 16 | ... M19: =(M18*('Вводные'!$B$63/100)) -> 16 | N19: =SUM(B19:M19) -> 192 | O19: Маркетинг
A20: Реклама · оценка выручки | B20: =(B19*'Вводные'!$B$64) -> 136000 | C20: =(C19*'Вводные'!$B$64) -> 136000 | D20: =(D19*'Вводные'!$B$64) -> 136000 | E20: =(E19*'Вводные'!$B$64) -> 136000 | F20: =(F19*'Вводные'!$B$64) -> 136000 | G20: =(G19*'Вводные'!$B$64) -> 136000 | H20: =(H19*'Вводные'!$B$64) -> 136000 | I20: =(I19*'Вводные'!$B$64) -> 136000 | ... M20: =(M19*'Вводные'!$B$64) -> 136000 | N20: =SUM(B20:M20) -> 1632000 | O20: Маркетинг
A21: Маркетинг — всего | B21: =B16 -> 120000 | C21: =C16 -> 120000 | D21: =D16 -> 120000 | E21: =E16 -> 120000 | F21: =F16 -> 120000 | G21: =G16 -> 120000 | H21: =H16 -> 120000 | I21: =I16 -> 120000 | ... M21: =M16 -> 120000 | N21: =SUM(B21:M21) -> 1440000 | O21: Бюджеты каналов + процент от выручки. Продажи из воронки уже должны входить в общий оборот.
A22: Заявки из рекламы, шт. | B22: =B18 -> 80 | C22: =C18 -> 80 | D22: =D18 -> 80 | E22: =E18 -> 80 | F22: =F18 -> 80 | G22: =G18 -> 80 | H22: =H18 -> 80 | I22: =I18 -> 80 | ... M22: =M18 -> 80 | N22: =SUM(B22:M22) -> 960 | O22: Маркетинг
A23: Клиенты из рекламы, шт. | B23: =B19 -> 16 | C23: =C19 -> 16 | D23: =D19 -> 16 | E23: =E19 -> 16 | F23: =F19 -> 16 | G23: =G19 -> 16 | H23: =H19 -> 16 | I23: =I19 -> 16 | ... M23: =M19 -> 16 | N23: =SUM(B23:M23) -> 192 | O23: Маркетинг
A24: Оценка выручки из рекламы | B24: =B20 -> 136000 | C24: =C20 -> 136000 | D24: =D20 -> 136000 | E24: =E20 -> 136000 | F24: =F20 -> 136000 | G24: =G20 -> 136000 | H24: =H20 -> 136000 | I24: =I20 -> 136000 | ... M24: =M20 -> 136000 | N24: =SUM(B24:M24) -> 1632000 | O24: Клиенты × чек каждого канала. Не прибавляется к обороту, чтобы не считать продажи дважды.
A25: Аренда | B25: =IF(AND(AND((1>='Вводные'!$B$71),(1<='Вводные'!$B$72)),IF(('Вводные'!$B$68="once"),(1='Вводные'!$B$71),TRUE)),IF(('Вводные'!$B$68="percent"),(B8*('Вводные'!$B$69/100)),('Вводные'!$B$69*((1+('Вводные'!$B$70/100))^MAX(0,(1-'Вводные'!$B$71))))),0) -> 250000 | C25: =IF(AND(AND((2>='Вводные'!$B$71),(2<='Вводные'!$B$72)),IF(('Вводные'!$B$68="once"),(2='Вводные'!$B$71),TRUE)),IF(('Вводные'!$B$68="percent"),(C8*('Вводные'!$B$69/100)),('Вводные'!$B$69*((1+('Вводные'!$B$70/100))^MAX(0,(2-'Вводные'!$B$71))))),0) -> 250000 | D25: =IF(AND(AND((3>='Вводные'!$B$71),(3<='Вводные'!$B$72)),IF(('Вводные'!$B$68="once"),(3='Вводные'!$B$71),TRUE)),IF(('Вводные'!$B$68="percent"),(D8*('Вводные'!$B$69/100)),('Вводные'!$B$69*((1+('Вводные'!$B$70/100))^MAX(0,(3-'Вводные'!$B$71))))),0) -> 250000 | E25: =IF(AND(AND((4>='Вводные'!$B$71),(4<='Вводные'!$B$72)),IF(('Вводные'!$B$68="once"),(4='Вводные'!$B$71),TRUE)),IF(('Вводные'!$B$68="percent"),(E8*('Вводные'!$B$69/100)),('Вводные'!$B$69*((1+('Вводные'!$B$70/100))^MAX(0,(4-'Вводные'!$B$71))))),0) -> 250000 | F25: =IF(AND(AND((5>='Вводные'!$B$71),(5<='Вводные'!$B$72)),IF(('Вводные'!$B$68="once"),(5='Вводные'!$B$71),TRUE)),IF(('Вводные'!$B$68="percent"),(F8*('Вводные'!$B$69/100)),('Вводные'!$B$69*((1+('Вводные'!$B$70/100))^MAX(0,(5-'Вводные'!$B$71))))),0) -> 250000 | G25: =IF(AND(AND((6>='Вводные'!$B$71),(6<='Вводные'!$B$72)),IF(('Вводные'!$B$68="once"),(6='Вводные'!$B$71),TRUE)),IF(('Вводные'!$B$68="percent"),(G8*('Вводные'!$B$69/100)),('Вводные'!$B$69*((1+('Вводные'!$B$70/100))^MAX(0,(6-'Вводные'!$B$71))))),0) -> 250000 | H25: =IF(AND(AND((7>='Вводные'!$B$71),(7<='Вводные'!$B$72)),IF(('Вводные'!$B$68="once"),(7='Вводные'!$B$71),TRUE)),IF(('Вводные'!$B$68="percent"),(H8*('Вводные'!$B$69/100)),('Вводные'!$B$69*((1+('Вводные'!$B$70/100))^MAX(0,(7-'Вводные'!$B$71))))),0) -> 250000 | I25: =IF(AND(AND((8>='Вводные'!$B$71),(8<='Вводные'!$B$72)),IF(('Вводные'!$B$68="once"),(8='Вводные'!$B$71),TRUE)),IF(('Вводные'!$B$68="percent"),(I8*('Вводные'!$B$69/100)),('Вводные'!$B$69*((1+('Вводные'!$B$70/100))^MAX(0,(8-'Вводные'!$B$71))))),0) -> 250000 | J25: =IF(AND(AND((9>='Вводные'!$B$71),(9<='Вводные'!$B$72)),IF(('Вводные'!$B$68="once"),(9='Вводные'!$B$71),TRUE)),IF(('Вводные'!$B$68="percent"),(J8*('Вводные'!$B$69/100)),('Вводные'!$B$69*((1+('Вводные'!$B$70/100))^MAX(0,(9-'Вводные'!$B$71))))),0) -> 250000 | K25: =IF(AND(AND((10>='Вводные'!$B$71),(10<='Вводные'!$B$72)),IF(('Вводные'!$B$68="once"),(10='Вводные'!$B$71),TRUE)),IF(('Вводные'!$B$68="percent"),(K8*('Вводные'!$B$69/100)),('Вводные'!$B$69*((1+('Вводные'!$B$70/100))^MAX(0,(10-'Вводные'!$B$71))))),0) -> 250000 | L25: =IF(AND(AND((11>='Вводные'!$B$71),(11<='Вводные'!$B$72)),IF(('Вводные'!$B$68="once"),(11='Вводные'!$B$71),TRUE)),IF(('Вводные'!$B$68="percent"),(L8*('Вводные'!$B$69/100)),('Вводные'!$B$69*((1+('Вводные'!$B$70/100))^MAX(0,(11-'Вводные'!$B$71))))),0) -> 250000 | M25: =IF(AND(AND((12>='Вводные'!$B$71),(12<='Вводные'!$B$72)),IF(('Вводные'!$B$68="once"),(12='Вводные'!$B$71),TRUE)),IF(('Вводные'!$B$68="percent"),(M8*('Вводные'!$B$69/100)),('Вводные'!$B$69*((1+('Вводные'!$B$70/100))^MAX(0,(12-'Вводные'!$B$71))))),0) -> 250000 | N25: =SUM(B25:M25) -> 3000000 | O25: Прочие расходы
A26: Сервисы и связь | B26: =IF(AND(AND((1>='Вводные'!$B$77),(1<='Вводные'!$B$78)),IF(('Вводные'!$B$74="once"),(1='Вводные'!$B$77),TRUE)),IF(('Вводные'!$B$74="percent"),(B8*('Вводные'!$B$75/100)),('Вводные'!$B$75*((1+('Вводные'!$B$76/100))^MAX(0,(1-'Вводные'!$B$77))))),0) -> 35000 | C26: =IF(AND(AND((2>='Вводные'!$B$77),(2<='Вводные'!$B$78)),IF(('Вводные'!$B$74="once"),(2='Вводные'!$B$77),TRUE)),IF(('Вводные'!$B$74="percent"),(C8*('Вводные'!$B$75/100)),('Вводные'!$B$75*((1+('Вводные'!$B$76/100))^MAX(0,(2-'Вводные'!$B$77))))),0) -> 35000 | D26: =IF(AND(AND((3>='Вводные'!$B$77),(3<='Вводные'!$B$78)),IF(('Вводные'!$B$74="once"),(3='Вводные'!$B$77),TRUE)),IF(('Вводные'!$B$74="percent"),(D8*('Вводные'!$B$75/100)),('Вводные'!$B$75*((1+('Вводные'!$B$76/100))^MAX(0,(3-'Вводные'!$B$77))))),0) -> 35000 | E26: =IF(AND(AND((4>='Вводные'!$B$77),(4<='Вводные'!$B$78)),IF(('Вводные'!$B$74="once"),(4='Вводные'!$B$77),TRUE)),IF(('Вводные'!$B$74="percent"),(E8*('Вводные'!$B$75/100)),('Вводные'!$B$75*((1+('Вводные'!$B$76/100))^MAX(0,(4-'Вводные'!$B$77))))),0) -> 35000 | F26: =IF(AND(AND((5>='Вводные'!$B$77),(5<='Вводные'!$B$78)),IF(('Вводные'!$B$74="once"),(5='Вводные'!$B$77),TRUE)),IF(('Вводные'!$B$74="percent"),(F8*('Вводные'!$B$75/100)),('Вводные'!$B$75*((1+('Вводные'!$B$76/100))^MAX(0,(5-'Вводные'!$B$77))))),0) -> 35000 | G26: =IF(AND(AND((6>='Вводные'!$B$77),(6<='Вводные'!$B$78)),IF(('Вводные'!$B$74="once"),(6='Вводные'!$B$77),TRUE)),IF(('Вводные'!$B$74="percent"),(G8*('Вводные'!$B$75/100)),('Вводные'!$B$75*((1+('Вводные'!$B$76/100))^MAX(0,(6-'Вводные'!$B$77))))),0) -> 35000 | H26: =IF(AND(AND((7>='Вводные'!$B$77),(7<='Вводные'!$B$78)),IF(('Вводные'!$B$74="once"),(7='Вводные'!$B$77),TRUE)),IF(('Вводные'!$B$74="percent"),(H8*('Вводные'!$B$75/100)),('Вводные'!$B$75*((1+('Вводные'!$B$76/100))^MAX(0,(7-'Вводные'!$B$77))))),0) -> 35000 | I26: =IF(AND(AND((8>='Вводные'!$B$77),(8<='Вводные'!$B$78)),IF(('Вводные'!$B$74="once"),(8='Вводные'!$B$77),TRUE)),IF(('Вводные'!$B$74="percent"),(I8*('Вводные'!$B$75/100)),('Вводные'!$B$75*((1+('Вводные'!$B$76/100))^MAX(0,(8-'Вводные'!$B$77))))),0) -> 35000 | J26: =IF(AND(AND((9>='Вводные'!$B$77),(9<='Вводные'!$B$78)),IF(('Вводные'!$B$74="once"),(9='Вводные'!$B$77),TRUE)),IF(('Вводные'!$B$74="percent"),(J8*('Вводные'!$B$75/100)),('Вводные'!$B$75*((1+('Вводные'!$B$76/100))^MAX(0,(9-'Вводные'!$B$77))))),0) -> 35000 | K26: =IF(AND(AND((10>='Вводные'!$B$77),(10<='Вводные'!$B$78)),IF(('Вводные'!$B$74="once"),(10='Вводные'!$B$77),TRUE)),IF(('Вводные'!$B$74="percent"),(K8*('Вводные'!$B$75/100)),('Вводные'!$B$75*((1+('Вводные'!$B$76/100))^MAX(0,(10-'Вводные'!$B$77))))),0) -> 35000 | L26: =IF(AND(AND((11>='Вводные'!$B$77),(11<='Вводные'!$B$78)),IF(('Вводные'!$B$74="once"),(11='Вводные'!$B$77),TRUE)),IF(('Вводные'!$B$74="percent"),(L8*('Вводные'!$B$75/100)),('Вводные'!$B$75*((1+('Вводные'!$B$76/100))^MAX(0,(11-'Вводные'!$B$77))))),0) -> 35000 | M26: =IF(AND(AND((12>='Вводные'!$B$77),(12<='Вводные'!$B$78)),IF(('Вводные'!$B$74="once"),(12='Вводные'!$B$77),TRUE)),IF(('Вводные'!$B$74="percent"),(M8*('Вводные'!$B$75/100)),('Вводные'!$B$75*((1+('Вводные'!$B$76/100))^MAX(0,(12-'Вводные'!$B$77))))),0) -> 35000 | N26: =SUM(B26:M26) -> 420000 | O26: Прочие расходы
A27: Новая статья | B27: =IF(AND(AND((1>='Вводные'!$B$83),(1<='Вводные'!$B$84)),IF(('Вводные'!$B$80="once"),(1='Вводные'!$B$83),TRUE)),IF(('Вводные'!$B$80="percent"),(B8*('Вводные'!$B$81/100)),('Вводные'!$B$81*((1+('Вводные'!$B$82/100))^MAX(0,(1-'Вводные'!$B$83))))),0) -> 0 | C27: =IF(AND(AND((2>='Вводные'!$B$83),(2<='Вводные'!$B$84)),IF(('Вводные'!$B$80="once"),(2='Вводные'!$B$83),TRUE)),IF(('Вводные'!$B$80="percent"),(C8*('Вводные'!$B$81/100)),('Вводные'!$B$81*((1+('Вводные'!$B$82/100))^MAX(0,(2-'Вводные'!$B$83))))),0) -> 0 | D27: =IF(AND(AND((3>='Вводные'!$B$83),(3<='Вводные'!$B$84)),IF(('Вводные'!$B$80="once"),(3='Вводные'!$B$83),TRUE)),IF(('Вводные'!$B$80="percent"),(D8*('Вводные'!$B$81/100)),('Вводные'!$B$81*((1+('Вводные'!$B$82/100))^MAX(0,(3-'Вводные'!$B$83))))),0) -> 0 | E27: =IF(AND(AND((4>='Вводные'!$B$83),(4<='Вводные'!$B$84)),IF(('Вводные'!$B$80="once"),(4='Вводные'!$B$83),TRUE)),IF(('Вводные'!$B$80="percent"),(E8*('Вводные'!$B$81/100)),('Вводные'!$B$81*((1+('Вводные'!$B$82/100))^MAX(0,(4-'Вводные'!$B$83))))),0) -> 0 | F27: =IF(AND(AND((5>='Вводные'!$B$83),(5<='Вводные'!$B$84)),IF(('Вводные'!$B$80="once"),(5='Вводные'!$B$83),TRUE)),IF(('Вводные'!$B$80="percent"),(F8*('Вводные'!$B$81/100)),('Вводные'!$B$81*((1+('Вводные'!$B$82/100))^MAX(0,(5-'Вводные'!$B$83))))),0) -> 0 | G27: =IF(AND(AND((6>='Вводные'!$B$83),(6<='Вводные'!$B$84)),IF(('Вводные'!$B$80="once"),(6='Вводные'!$B$83),TRUE)),IF(('Вводные'!$B$80="percent"),(G8*('Вводные'!$B$81/100)),('Вводные'!$B$81*((1+('Вводные'!$B$82/100))^MAX(0,(6-'Вводные'!$B$83))))),0) -> 0 | H27: =IF(AND(AND((7>='Вводные'!$B$83),(7<='Вводные'!$B$84)),IF(('Вводные'!$B$80="once"),(7='Вводные'!$B$83),TRUE)),IF(('Вводные'!$B$80="percent"),(H8*('Вводные'!$B$81/100)),('Вводные'!$B$81*((1+('Вводные'!$B$82/100))^MAX(0,(7-'Вводные'!$B$83))))),0) -> 0 | I27: =IF(AND(AND((8>='Вводные'!$B$83),(8<='Вводные'!$B$84)),IF(('Вводные'!$B$80="once"),(8='Вводные'!$B$83),TRUE)),IF(('Вводные'!$B$80="percent"),(I8*('Вводные'!$B$81/100)),('Вводные'!$B$81*((1+('Вводные'!$B$82/100))^MAX(0,(8-'Вводные'!$B$83))))),0) -> 0 | J27: =IF(AND(AND((9>='Вводные'!$B$83),(9<='Вводные'!$B$84)),IF(('Вводные'!$B$80="once"),(9='Вводные'!$B$83),TRUE)),IF(('Вводные'!$B$80="percent"),(J8*('Вводные'!$B$81/100)),('Вводные'!$B$81*((1+('Вводные'!$B$82/100))^MAX(0,(9-'Вводные'!$B$83))))),0) -> 0 | K27: =IF(AND(AND((10>='Вводные'!$B$83),(10<='Вводные'!$B$84)),IF(('Вводные'!$B$80="once"),(10='Вводные'!$B$83),TRUE)),IF(('Вводные'!$B$80="percent"),(K8*('Вводные'!$B$81/100)),('Вводные'!$B$81*((1+('Вводные'!$B$82/100))^MAX(0,(10-'Вводные'!$B$83))))),0) -> 0 | L27: =IF(AND(AND((11>='Вводные'!$B$83),(11<='Вводные'!$B$84)),IF(('Вводные'!$B$80="once"),(11='Вводные'!$B$83),TRUE)),IF(('Вводные'!$B$80="percent"),(L8*('Вводные'!$B$81/100)),('Вводные'!$B$81*((1+('Вводные'!$B$82/100))^MAX(0,(11-'Вводные'!$B$83))))),0) -> 0 | M27: =IF(AND(AND((12>='Вводные'!$B$83),(12<='Вводные'!$B$84)),IF(('Вводные'!$B$80="once"),(12='Вводные'!$B$83),TRUE)),IF(('Вводные'!$B$80="percent"),(M8*('Вводные'!$B$81/100)),('Вводные'!$B$81*((1+('Вводные'!$B$82/100))^MAX(0,(12-'Вводные'!$B$83))))),0) -> 0 | N27: =SUM(B27:M27) -> 0 | O27: Прочие расходы
A28: Прочие расходы — всего | B28: =((B25+B26)+B27) -> 285000 | C28: =((C25+C26)+C27) -> 285000 | D28: =((D25+D26)+D27) -> 285000 | E28: =((E25+E26)+E27) -> 285000 | F28: =((F25+F26)+F27) -> 285000 | G28: =((G25+G26)+G27) -> 285000 | H28: =((H25+H26)+H27) -> 285000 | I28: =((I25+I26)+I27) -> 285000 | ... M28: =((M25+M26)+M27) -> 285000 | N28: =SUM(B28:M28) -> 3420000 | O28: Результат
A29: Операционные расходы | B29: =((B15+B21)+B28) -> 750000 | C29: =((C15+C21)+C28) -> 750000 | D29: =((D15+D21)+D28) -> 750000 | E29: =((E15+E21)+E28) -> 750000 | F29: =((F15+F21)+F28) -> 750000 | G29: =((G15+G21)+G28) -> 750000 | H29: =((H15+H21)+H28) -> 750000 | I29: =((I15+I21)+I28) -> 750000 | ... M29: =((M15+M21)+M28) -> 750000 | N29: =SUM(B29:M29) -> 9000000 | O29: Команда + маркетинг + прочие расходы.
A30: EBITDA | B30: =(B10-B29) -> 907500 | C30: =(C10-C29) -> 973800 | D30: =(D10-D29) -> 1042752 | E30: =(E10-E29) -> 1114462.1 | F30: =(F10-F29) -> 1189040.6 | G30: =(G10-G29) -> 1266602.2 | H30: =(H10-H29) -> 1347266.3 | I30: =(I10-I29) -> 1431156.9 | ... M30: =(M10-M29) -> 1801645.1 | N30: =SUM(B30:M30) -> 15905273 | O30: Валовая прибыль − операционные расходы; до амортизации, процентов и налога.
A31: Покупка активов | B31: =0 -> 0 | C31: =0 -> 0 | D31: =0 -> 0 | E31: =0 -> 0 | F31: =0 -> 0 | G31: =0 -> 0 | H31: =0 -> 0 | I31: =0 -> 0 | ... M31: =0 -> 0 | N31: =SUM(B31:M31) -> 0 | O31: Денежный поток
A32: Амортизация | B32: =(IF(AND(('Вводные'!$B$13>0),(1<='Вводные'!$B$13)),('Вводные'!$B$12/MAX(1,'Вводные'!$B$13)),0)+0) -> 83333.333 | C32: =(IF(AND(('Вводные'!$B$13>0),(2<='Вводные'!$B$13)),('Вводные'!$B$12/MAX(1,'Вводные'!$B$13)),0)+0) -> 83333.333 | D32: =(IF(AND(('Вводные'!$B$13>0),(3<='Вводные'!$B$13)),('Вводные'!$B$12/MAX(1,'Вводные'!$B$13)),0)+0) -> 83333.333 | E32: =(IF(AND(('Вводные'!$B$13>0),(4<='Вводные'!$B$13)),('Вводные'!$B$12/MAX(1,'Вводные'!$B$13)),0)+0) -> 83333.333 | F32: =(IF(AND(('Вводные'!$B$13>0),(5<='Вводные'!$B$13)),('Вводные'!$B$12/MAX(1,'Вводные'!$B$13)),0)+0) -> 83333.333 | G32: =(IF(AND(('Вводные'!$B$13>0),(6<='Вводные'!$B$13)),('Вводные'!$B$12/MAX(1,'Вводные'!$B$13)),0)+0) -> 83333.333 | H32: =(IF(AND(('Вводные'!$B$13>0),(7<='Вводные'!$B$13)),('Вводные'!$B$12/MAX(1,'Вводные'!$B$13)),0)+0) -> 83333.333 | I32: =(IF(AND(('Вводные'!$B$13>0),(8<='Вводные'!$B$13)),('Вводные'!$B$12/MAX(1,'Вводные'!$B$13)),0)+0) -> 83333.333 | J32: =(IF(AND(('Вводные'!$B$13>0),(9<='Вводные'!$B$13)),('Вводные'!$B$12/MAX(1,'Вводные'!$B$13)),0)+0) -> 83333.333 | K32: =(IF(AND(('Вводные'!$B$13>0),(10<='Вводные'!$B$13)),('Вводные'!$B$12/MAX(1,'Вводные'!$B$13)),0)+0) -> 83333.333 | L32: =(IF(AND(('Вводные'!$B$13>0),(11<='Вводные'!$B$13)),('Вводные'!$B$12/MAX(1,'Вводные'!$B$13)),0)+0) -> 83333.333 | M32: =(IF(AND(('Вводные'!$B$13>0),(12<='Вводные'!$B$13)),('Вводные'!$B$12/MAX(1,'Вводные'!$B$13)),0)+0) -> 83333.333 | N32: =SUM(B32:M32) -> 1000000 | O32: Стоимость / срок в месяцах, начиная с месяца покупки. Покупка уменьшает деньги, амортизация — прибыль.
A33: Операционная прибыль (EBIT) | B33: =(B30-B32) -> 824166.67 | C33: =(C30-C32) -> 890466.67 | D33: =(D30-D32) -> 959418.67 | E33: =(E30-E32) -> 1031128.7 | F33: =(F30-F32) -> 1105707.2 | G33: =(G30-G32) -> 1183268.9 | H33: =(H30-H32) -> 1263932.9 | I33: =(I30-I32) -> 1347823.6 | ... M33: =(M30-M32) -> 1718311.8 | N33: =SUM(B33:M33) -> 14905273 | O33: Результат
A34: Кредит на начало месяца | B34: =IF((1<='Вводные'!$B$16),MAX(0,IF(((('Вводные'!$B$15/100)/12)>0),(('Вводные'!$B$14*((1+(('Вводные'!$B$15/100)/12))^0))-(IF(((('Вводные'!$B$15/100)/12)>0),(('Вводные'!$B$14*(('Вводные'!$B$15/100)/12))/(1-((1+(('Вводные'!$B$15/100)/12))^(-1*'Вводные'!$B$16)))),('Вводные'!$B$14/'Вводные'!$B$16))*((((1+(('Вводные'!$B$15/100)/12))^0)-1)/(('Вводные'!$B$15/100)/12)))),('Вводные'!$B$14-(IF(((('Вводные'!$B$15/100)/12)>0),(('Вводные'!$B$14*(('Вводные'!$B$15/100)/12))/(1-((1+(('Вводные'!$B$15/100)/12))^(-1*'Вводные'!$B$16)))),('Вводные'!$B$14/'Вводные'!$B$16))*0)))),0) -> 0 | C34: =IF((2<='Вводные'!$B$16),MAX(0,IF(((('Вводные'!$B$15/100)/12)>0),(('Вводные'!$B$14*((1+(('Вводные'!$B$15/100)/12))^1))-(IF(((('Вводные'!$B$15/100)/12)>0),(('Вводные'!$B$14*(('Вводные'!$B$15/100)/12))/(1-((1+(('Вводные'!$B$15/100)/12))^(-1*'Вводные'!$B$16)))),('Вводные'!$B$14/'Вводные'!$B$16))*((((1+(('Вводные'!$B$15/100)/12))^1)-1)/(('Вводные'!$B$15/100)/12)))),('Вводные'!$B$14-(IF(((('Вводные'!$B$15/100)/12)>0),(('Вводные'!$B$14*(('Вводные'!$B$15/100)/12))/(1-((1+(('Вводные'!$B$15/100)/12))^(-1*'Вводные'!$B$16)))),('Вводные'!$B$14/'Вводные'!$B$16))*1)))),0) -> 0 | D34: =IF((3<='Вводные'!$B$16),MAX(0,IF(((('Вводные'!$B$15/100)/12)>0),(('Вводные'!$B$14*((1+(('Вводные'!$B$15/100)/12))^2))-(IF(((('Вводные'!$B$15/100)/12)>0),(('Вводные'!$B$14*(('Вводные'!$B$15/100)/12))/(1-((1+(('Вводные'!$B$15/100)/12))^(-1*'Вводные'!$B$16)))),('Вводные'!$B$14/'Вводные'!$B$16))*((((1+(('Вводные'!$B$15/100)/12))^2)-1)/(('Вводные'!$B$15/100)/12)))),('Вводные'!$B$14-(IF(((('Вводные'!$B$15/100)/12)>0),(('Вводные'!$B$14*(('Вводные'!$B$15/100)/12))/(1-((1+(('Вводные'!$B$15/100)/12))^(-1*'Вводные'!$B$16)))),('Вводные'!$B$14/'Вводные'!$B$16))*2)))),0) -> 0 | E34: =IF((4<='Вводные'!$B$16),MAX(0,IF(((('Вводные'!$B$15/100)/12)>0),(('Вводные'!$B$14*((1+(('Вводные'!$B$15/100)/12))^3))-(IF(((('Вводные'!$B$15/100)/12)>0),(('Вводные'!$B$14*(('Вводные'!$B$15/100)/12))/(1-((1+(('Вводные'!$B$15/100)/12))^(-1*'Вводные'!$B$16)))),('Вводные'!$B$14/'Вводные'!$B$16))*((((1+(('Вводные'!$B$15/100)/12))^3)-1)/(('Вводные'!$B$15/100)/12)))),('Вводные'!$B$14-(IF(((('Вводные'!$B$15/100)/12)>0),(('Вводные'!$B$14*(('Вводные'!$B$15/100)/12))/(1-((1+(('Вводные'!$B$15/100)/12))^(-1*'Вводные'!$B$16)))),('Вводные'!$B$14/'Вводные'!$B$16))*3)))),0) -> 0 | F34: =IF((5<='Вводные'!$B$16),MAX(0,IF(((('Вводные'!$B$15/100)/12)>0),(('Вводные'!$B$14*((1+(('Вводные'!$B$15/100)/12))^4))-(IF(((('Вводные'!$B$15/100)/12)>0),(('Вводные'!$B$14*(('Вводные'!$B$15/100)/12))/(1-((1+(('Вводные'!$B$15/100)/12))^(-1*'Вводные'!$B$16)))),('Вводные'!$B$14/'Вводные'!$B$16))*((((1+(('Вводные'!$B$15/100)/12))^4)-1)/(('Вводные'!$B$15/100)/12)))),('Вводные'!$B$14-(IF(((('Вводные'!$B$15/100)/12)>0),(('Вводные'!$B$14*(('Вводные'!$B$15/100)/12))/(1-((1+(('Вводные'!$B$15/100)/12))^(-1*'Вводные'!$B$16)))),('Вводные'!$B$14/'Вводные'!$B$16))*4)))),0) -> 0 | G34: =IF((6<='Вводные'!$B$16),MAX(0,IF(((('Вводные'!$B$15/100)/12)>0),(('Вводные'!$B$14*((1+(('Вводные'!$B$15/100)/12))^5))-(IF(((('Вводные'!$B$15/100)/12)>0),(('Вводные'!$B$14*(('Вводные'!$B$15/100)/12))/(1-((1+(('Вводные'!$B$15/100)/12))^(-1*'Вводные'!$B$16)))),('Вводные'!$B$14/'Вводные'!$B$16))*((((1+(('Вводные'!$B$15/100)/12))^5)-1)/(('Вводные'!$B$15/100)/12)))),('Вводные'!$B$14-(IF(((('Вводные'!$B$15/100)/12)>0),(('Вводные'!$B$14*(('Вводные'!$B$15/100)/12))/(1-((1+(('Вводные'!$B$15/100)/12))^(-1*'Вводные'!$B$16)))),('Вводные'!$B$14/'Вводные'!$B$16))*5)))),0) -> 0 | H34: =IF((7<='Вводные'!$B$16),MAX(0,IF(((('Вводные'!$B$15/100)/12)>0),(('Вводные'!$B$14*((1+(('Вводные'!$B$15/100)/12))^6))-(IF(((('Вводные'!$B$15/100)/12)>0),(('Вводные'!$B$14*(('Вводные'!$B$15/100)/12))/(1-((1+(('Вводные'!$B$15/100)/12))^(-1*'Вводные'!$B$16)))),('Вводные'!$B$14/'Вводные'!$B$16))*((((1+(('Вводные'!$B$15/100)/12))^6)-1)/(('Вводные'!$B$15/100)/12)))),('Вводные'!$B$14-(IF(((('Вводные'!$B$15/100)/12)>0),(('Вводные'!$B$14*(('Вводные'!$B$15/100)/12))/(1-((1+(('Вводные'!$B$15/100)/12))^(-1*'Вводные'!$B$16)))),('Вводные'!$B$14/'Вводные'!$B$16))*6)))),0) -> 0 | I34: =IF((8<='Вводные'!$B$16),MAX(0,IF(((('Вводные'!$B$15/100)/12)>0),(('Вводные'!$B$14*((1+(('Вводные'!$B$15/100)/12))^7))-(IF(((('Вводные'!$B$15/100)/12)>0),(('Вводные'!$B$14*(('Вводные'!$B$15/100)/12))/(1-((1+(('Вводные'!$B$15/100)/12))^(-1*'Вводные'!$B$16)))),('Вводные'!$B$14/'Вводные'!$B$16))*((((1+(('Вводные'!$B$15/100)/12))^7)-1)/(('Вводные'!$B$15/100)/12)))),('Вводные'!$B$14-(IF(((('Вводные'!$B$15/100)/12)>0),(('Вводные'!$B$14*(('Вводные'!$B$15/100)/12))/(1-((1+(('Вводные'!$B$15/100)/12))^(-1*'Вводные'!$B$16)))),('Вводные'!$B$14/'Вводные'!$B$16))*7)))),0) -> 0 | J34: =IF((9<='Вводные'!$B$16),MAX(0,IF(((('Вводные'!$B$15/100)/12)>0),(('Вводные'!$B$14*((1+(('Вводные'!$B$15/100)/12))^8))-(IF(((('Вводные'!$B$15/100)/12)>0),(('Вводные'!$B$14*(('Вводные'!$B$15/100)/12))/(1-((1+(('Вводные'!$B$15/100)/12))^(-1*'Вводные'!$B$16)))),('Вводные'!$B$14/'Вводные'!$B$16))*((((1+(('Вводные'!$B$15/100)/12))^8)-1)/(('Вводные'!$B$15/100)/12)))),('Вводные'!$B$14-(IF(((('Вводные'!$B$15/100)/12)>0),(('Вводные'!$B$14*(('Вводные'!$B$15/100)/12))/(1-((1+(('Вводные'!$B$15/100)/12))^(-1*'Вводные'!$B$16)))),('Вводные'!$B$14/'Вводные'!$B$16))*8)))),0) -> 0 | K34: =IF((10<='Вводные'!$B$16),MAX(0,IF(((('Вводные'!$B$15/100)/12)>0),(('Вводные'!$B$14*((1+(('Вводные'!$B$15/100)/12))^9))-(IF(((('Вводные'!$B$15/100)/12)>0),(('Вводные'!$B$14*(('Вводные'!$B$15/100)/12))/(1-((1+(('Вводные'!$B$15/100)/12))^(-1*'Вводные'!$B$16)))),('Вводные'!$B$14/'Вводные'!$B$16))*((((1+(('Вводные'!$B$15/100)/12))^9)-1)/(('Вводные'!$B$15/100)/12)))),('Вводные'!$B$14-(IF(((('Вводные'!$B$15/100)/12)>0),(('Вводные'!$B$14*(('Вводные'!$B$15/100)/12))/(1-((1+(('Вводные'!$B$15/100)/12))^(-1*'Вводные'!$B$16)))),('Вводные'!$B$14/'Вводные'!$B$16))*9)))),0) -> 0 | L34: =IF((11<='Вводные'!$B$16),MAX(0,IF(((('Вводные'!$B$15/100)/12)>0),(('Вводные'!$B$14*((1+(('Вводные'!$B$15/100)/12))^10))-(IF(((('Вводные'!$B$15/100)/12)>0),(('Вводные'!$B$14*(('Вводные'!$B$15/100)/12))/(1-((1+(('Вводные'!$B$15/100)/12))^(-1*'Вводные'!$B$16)))),('Вводные'!$B$14/'Вводные'!$B$16))*((((1+(('Вводные'!$B$15/100)/12))^10)-1)/(('Вводные'!$B$15/100)/12)))),('Вводные'!$B$14-(IF(((('Вводные'!$B$15/100)/12)>0),(('Вводные'!$B$14*(('Вводные'!$B$15/100)/12))/(1-((1+(('Вводные'!$B$15/100)/12))^(-1*'Вводные'!$B$16)))),('Вводные'!$B$14/'Вводные'!$B$16))*10)))),0) -> 0 | M34: =IF((12<='Вводные'!$B$16),MAX(0,IF(((('Вводные'!$B$15/100)/12)>0),(('Вводные'!$B$14*((1+(('Вводные'!$B$15/100)/12))^11))-(IF(((('Вводные'!$B$15/100)/12)>0),(('Вводные'!$B$14*(('Вводные'!$B$15/100)/12))/(1-((1+(('Вводные'!$B$15/100)/12))^(-1*'Вводные'!$B$16)))),('Вводные'!$B$14/'Вводные'!$B$16))*((((1+(('Вводные'!$B$15/100)/12))^11)-1)/(('Вводные'!$B$15/100)/12)))),('Вводные'!$B$14-(IF(((('Вводные'!$B$15/100)/12)>0),(('Вводные'!$B$14*(('Вводные'!$B$15/100)/12))/(1-((1+(('Вводные'!$B$15/100)/12))^(-1*'Вводные'!$B$16)))),('Вводные'!$B$14/'Вводные'!$B$16))*11)))),0) -> 0 | N34: =M34 -> 0 | O34: Кредит
A35: Проценты по кредиту | B35: =(B34*(('Вводные'!$B$15/100)/12)) -> 0 | C35: =(C34*(('Вводные'!$B$15/100)/12)) -> 0 | D35: =(D34*(('Вводные'!$B$15/100)/12)) -> 0 | E35: =(E34*(('Вводные'!$B$15/100)/12)) -> 0 | F35: =(F34*(('Вводные'!$B$15/100)/12)) -> 0 | G35: =(G34*(('Вводные'!$B$15/100)/12)) -> 0 | H35: =(H34*(('Вводные'!$B$15/100)/12)) -> 0 | I35: =(I34*(('Вводные'!$B$15/100)/12)) -> 0 | ... M35: =(M34*(('Вводные'!$B$15/100)/12)) -> 0 | N35: =SUM(B35:M35) -> 0 | O35: Результат
A36: Погашение тела кредита | B36: =IF((1<='Вводные'!$B$16),MIN(B34,MAX(0,(IF(((('Вводные'!$B$15/100)/12)>0),(('Вводные'!$B$14*(('Вводные'!$B$15/100)/12))/(1-((1+(('Вводные'!$B$15/100)/12))^(-1*'Вводные'!$B$16)))),('Вводные'!$B$14/'Вводные'!$B$16))-B35))),0) -> 0 | C36: =IF((2<='Вводные'!$B$16),MIN(C34,MAX(0,(IF(((('Вводные'!$B$15/100)/12)>0),(('Вводные'!$B$14*(('Вводные'!$B$15/100)/12))/(1-((1+(('Вводные'!$B$15/100)/12))^(-1*'Вводные'!$B$16)))),('Вводные'!$B$14/'Вводные'!$B$16))-C35))),0) -> 0 | D36: =IF((3<='Вводные'!$B$16),MIN(D34,MAX(0,(IF(((('Вводные'!$B$15/100)/12)>0),(('Вводные'!$B$14*(('Вводные'!$B$15/100)/12))/(1-((1+(('Вводные'!$B$15/100)/12))^(-1*'Вводные'!$B$16)))),('Вводные'!$B$14/'Вводные'!$B$16))-D35))),0) -> 0 | E36: =IF((4<='Вводные'!$B$16),MIN(E34,MAX(0,(IF(((('Вводные'!$B$15/100)/12)>0),(('Вводные'!$B$14*(('Вводные'!$B$15/100)/12))/(1-((1+(('Вводные'!$B$15/100)/12))^(-1*'Вводные'!$B$16)))),('Вводные'!$B$14/'Вводные'!$B$16))-E35))),0) -> 0 | F36: =IF((5<='Вводные'!$B$16),MIN(F34,MAX(0,(IF(((('Вводные'!$B$15/100)/12)>0),(('Вводные'!$B$14*(('Вводные'!$B$15/100)/12))/(1-((1+(('Вводные'!$B$15/100)/12))^(-1*'Вводные'!$B$16)))),('Вводные'!$B$14/'Вводные'!$B$16))-F35))),0) -> 0 | G36: =IF((6<='Вводные'!$B$16),MIN(G34,MAX(0,(IF(((('Вводные'!$B$15/100)/12)>0),(('Вводные'!$B$14*(('Вводные'!$B$15/100)/12))/(1-((1+(('Вводные'!$B$15/100)/12))^(-1*'Вводные'!$B$16)))),('Вводные'!$B$14/'Вводные'!$B$16))-G35))),0) -> 0 | H36: =IF((7<='Вводные'!$B$16),MIN(H34,MAX(0,(IF(((('Вводные'!$B$15/100)/12)>0),(('Вводные'!$B$14*(('Вводные'!$B$15/100)/12))/(1-((1+(('Вводные'!$B$15/100)/12))^(-1*'Вводные'!$B$16)))),('Вводные'!$B$14/'Вводные'!$B$16))-H35))),0) -> 0 | I36: =IF((8<='Вводные'!$B$16),MIN(I34,MAX(0,(IF(((('Вводные'!$B$15/100)/12)>0),(('Вводные'!$B$14*(('Вводные'!$B$15/100)/12))/(1-((1+(('Вводные'!$B$15/100)/12))^(-1*'Вводные'!$B$16)))),('Вводные'!$B$14/'Вводные'!$B$16))-I35))),0) -> 0 | J36: =IF((9<='Вводные'!$B$16),MIN(J34,MAX(0,(IF(((('Вводные'!$B$15/100)/12)>0),(('Вводные'!$B$14*(('Вводные'!$B$15/100)/12))/(1-((1+(('Вводные'!$B$15/100)/12))^(-1*'Вводные'!$B$16)))),('Вводные'!$B$14/'Вводные'!$B$16))-J35))),0) -> 0 | K36: =IF((10<='Вводные'!$B$16),MIN(K34,MAX(0,(IF(((('Вводные'!$B$15/100)/12)>0),(('Вводные'!$B$14*(('Вводные'!$B$15/100)/12))/(1-((1+(('Вводные'!$B$15/100)/12))^(-1*'Вводные'!$B$16)))),('Вводные'!$B$14/'Вводные'!$B$16))-K35))),0) -> 0 | L36: =IF((11<='Вводные'!$B$16),MIN(L34,MAX(0,(IF(((('Вводные'!$B$15/100)/12)>0),(('Вводные'!$B$14*(('Вводные'!$B$15/100)/12))/(1-((1+(('Вводные'!$B$15/100)/12))^(-1*'Вводные'!$B$16)))),('Вводные'!$B$14/'Вводные'!$B$16))-L35))),0) -> 0 | M36: =IF((12<='Вводные'!$B$16),MIN(M34,MAX(0,(IF(((('Вводные'!$B$15/100)/12)>0),(('Вводные'!$B$14*(('Вводные'!$B$15/100)/12))/(1-((1+(('Вводные'!$B$15/100)/12))^(-1*'Вводные'!$B$16)))),('Вводные'!$B$14/'Вводные'!$B$16))-M35))),0) -> 0 | N36: =SUM(B36:M36) -> 0 | O36: Аннуитетный платёж − проценты. Тело кредита уменьшает деньги, но не прибыль.
A37: Кредит на конец месяца | B37: =MAX(0,(B34-B36)) -> 0 | C37: =MAX(0,(C34-C36)) -> 0 | D37: =MAX(0,(D34-D36)) -> 0 | E37: =MAX(0,(E34-E36)) -> 0 | F37: =MAX(0,(F34-F36)) -> 0 | G37: =MAX(0,(G34-G36)) -> 0 | H37: =MAX(0,(H34-H36)) -> 0 | I37: =MAX(0,(I34-I36)) -> 0 | ... M37: =MAX(0,(M34-M36)) -> 0 | N37: =M37 -> 0 | O37: Кредит
A38: Прибыль до налога | B38: =(B33-B35) -> 824166.67 | C38: =(C33-C35) -> 890466.67 | D38: =(D33-D35) -> 959418.67 | E38: =(E33-E35) -> 1031128.7 | F38: =(F33-F35) -> 1105707.2 | G38: =(G33-G35) -> 1183268.9 | H38: =(H33-H35) -> 1263932.9 | I38: =(I33-I35) -> 1347823.6 | ... M38: =(M33-M35) -> 1718311.8 | N38: =SUM(B38:M38) -> 14905273 | O38: Результат
A39: Условный налог | B39: =IF(('Вводные'!$B$6="none"),0,(IF(('Вводные'!$B$6="revenue"),B8,MAX(0,B38))*('Вводные'!$B$7/100))) -> 82416.667 | C39: =IF(('Вводные'!$B$6="none"),0,(IF(('Вводные'!$B$6="revenue"),C8,MAX(0,C38))*('Вводные'!$B$7/100))) -> 89046.667 | D39: =IF(('Вводные'!$B$6="none"),0,(IF(('Вводные'!$B$6="revenue"),D8,MAX(0,D38))*('Вводные'!$B$7/100))) -> 95941.867 | E39: =IF(('Вводные'!$B$6="none"),0,(IF(('Вводные'!$B$6="revenue"),E8,MAX(0,E38))*('Вводные'!$B$7/100))) -> 103112.87 | F39: =IF(('Вводные'!$B$6="none"),0,(IF(('Вводные'!$B$6="revenue"),F8,MAX(0,F38))*('Вводные'!$B$7/100))) -> 110570.72 | G39: =IF(('Вводные'!$B$6="none"),0,(IF(('Вводные'!$B$6="revenue"),G8,MAX(0,G38))*('Вводные'!$B$7/100))) -> 118326.89 | H39: =IF(('Вводные'!$B$6="none"),0,(IF(('Вводные'!$B$6="revenue"),H8,MAX(0,H38))*('Вводные'!$B$7/100))) -> 126393.29 | I39: =IF(('Вводные'!$B$6="none"),0,(IF(('Вводные'!$B$6="revenue"),I8,MAX(0,I38))*('Вводные'!$B$7/100))) -> 134782.36 | ... M39: =IF(('Вводные'!$B$6="none"),0,(IF(('Вводные'!$B$6="revenue"),M8,MAX(0,M38))*('Вводные'!$B$7/100))) -> 171831.18 | N39: =SUM(B39:M39) -> 1490527.3 | O39: Ваша ставка × оборот или положительная прибыль месяца. Без переноса убытков. Оплата в том же месяце.
A40: Чистая прибыль | B40: =(B38-B39) -> 741750 | C40: =(C38-C39) -> 801420 | D40: =(D38-D39) -> 863476.8 | E40: =(E38-E39) -> 928015.87 | F40: =(F38-F39) -> 995136.51 | G40: =(G38-G39) -> 1064942 | H40: =(H38-H39) -> 1137539.6 | I40: =(I38-I39) -> 1213041.2 | ... M40: =(M38-M39) -> 1546480.6 | N40: =SUM(B40:M40) -> 13414745 | O40: Выручка − себестоимость − команда − маркетинг − прочие − амортизация − проценты − налог.
...

Sheet Вводные
A1: ВВОДНЫЕ / Мой бизнес
A2: Редактируйте колонку B. Суммы в KZT. Проценты задаются числом: 10 = 10%.
A3: Параметр | B3: Значение | C3: Пояснение
A4: Способ ввода выручки | B4: items | C4: items — товары; manual — ручной оборот
A5: Себестоимость ручного оборота, % | B5: 35
A6: База условного налога | B6: profit | C6: profit — прибыль; revenue — оборот; none — без налога
A7: Ставка налога, % | B7: 10
A8: Оплата клиентов через, мес. | B8: 0 | C8: Целые месяцы от 0 до 12
A9: Оплата себестоимости через, мес. | B9: 0 | C9: Целые месяцы от 0 до 12
A10: Деньги на начало | B10: 0
A11: Взнос собственника до М1 | B11: 3000000
A12: Вложения до М1 | B12: 3000000
A13: Амортизация начальных вложений, мес. (0 — нет) | B13: 36 | C13: 0 отключает амортизацию начальных вложений
A14: Кредит до М1 | B14: 0
A15: Годовая ставка кредита, % | B15: 18
A16: Срок кредита, мес. | B16: 24
A17: Дисконтирование: эффективная годовая ставка, % | B17: 12
A18: Валовая маржа рекламных продаж, % | B18: 65
A19: Средний собственный капитал за год | B19: 3000000
A20: Средние активы за год | B20: 6000000
A21: Выручка на клиента за месяц | B21: 8500
A22: Валовая маржа клиента, % | B22: 65
A23: Средний срок жизни клиента, мес. | B23: 12
A24: Прочие затраты на привлечение за год, уже в расходах | B24: 0
A25: Начальная сумма накоплений | B25: 100000
... A28: Пополнение в конце каждого месяца | B28: 0
A29: Множитель сценария | B29: 1 | C29: База: 1; осторожный: 0.8; оптимистичный: 1.2
A30: Ручной оборот · М1 | B30: 2550000
A31: Ручной оборот · М2 | B31: 2550000
A32: Ручной оборот · М3 | B32: 2550000
A33: Ручной оборот · М4 | B33: 2550000
A34: Ручной оборот · М5 | B34: 2550000
A35: Ручной оборот · М6 | B35: 2550000
A36: Ручной оборот · М7 | B36: 2550000
A37: Ручной оборот · М8 | B37: 2550000
A38: Ручной оборот · М9 | B38: 2550000
A39: Ручной оборот · М10 | B39: 2550000
A40: Ручной оборот · М11 | B40: 2550000
A41: Ручной оборот · М12 | B41: 2550000
A42: Основной продукт · Название | B42: Основной продукт
...

Sheet Показатели
A1: Доходность, клиенты и сложные проценты
A2: Все показатели бизнеса — за 12 месяцев выбранного сценария. Накопления — отдельный расчёт.
A3: Показатель | B3: Значение | C3: Формула и условия
A4: ROI | B4: =IF('Модель'!N52>0,'Модель'!N40/'Модель'!N52,"") -> 4.4715818 | C4: Чистая прибыль / все инвестиции. Учётная доходность за горизонт модели.
A5: ROMI | B5: =IF(AND(OR('Модель'!N16=0,'Вводные'!B61>0)),IF('Модель'!N21>0,('Модель'!N24*'Вводные'!B18/100-'Модель'!N21)/'Модель'!N21,""),"") -> -0.26333333 | C5: (Рекламная выручка × валовая маржа − маркетинг) / маркетинг. Оценка атрибуции, не причинный прирост.
A6: ROAS, раз | B6: =IF(AND(OR('Модель'!N16=0,'Вводные'!B61>0)),IF('Модель'!N21>0,'Модель'!N24/'Модель'!N21,""),"") -> 1.1333333 | C6: Оценка рекламной выручки / бюджет каналов.
A7: RR: рентабельность затрат | B7: =IF('Модель'!N41>0,'Модель'!N40/'Модель'!N41,"") -> 0.53872189 | C7: Чистая прибыль / все расходы в прибыли.
A8: Маржа чистой прибыли | B8: =IF('Модель'!N8>0,'Модель'!N40/'Модель'!N8,"") -> 0.35010998 | C8: Чистая прибыль / выручка.
A9: Срок окупаемости, мес. | B9: =IF(MIN(C41:N41)<1000000000,MIN(C41:N41),"Не достигнут") -> 3.3395001 | C9: Первое покрытие отрицательного накопленного потока. Доля месяца — линейная интерполяция.
A10: Дисконтированный срок, мес. | B10: =IF(MIN(C42:N42)<1000000000,MIN(C42:N42),"Не достигнут") -> 3.4046918 | C10: Первое покрытие дисконтированных вложений; горизонт 12 месяцев.
A11: NPV | B11: =SUM(B36:N36) -> 10471042 | C11: Начальные вложения и свободные потоки после процентов и налога; без выдачи и тела кредита, без остаточной стоимости.
A12: IRR: эффективная годовая | B12: =IF(ISNUMBER(B13),(1+B13)^12-1,"Не определена / неоднозначна") -> 27.357837 | C12: (1 + месячная IRR)^12 − 1.
A13: IRR: месячная | B13: =IF(AND(MIN(B35:N35)<0,MAX(B35:N35)>0,SUM(B40:N40)=1),IFERROR(IRR(B35:N35,0.3214663002989485),"Нет сходимости"),"Не определена / неоднозначна") -> 0.3214663 | C13: Ставка, при которой NPV = 0. При нескольких сменах знака не показывается как однозначная.
A14: ROE | B14: =IF('Вводные'!B19>0,'Модель'!N40/'Вводные'!B19,"") -> 4.4715818 | C14: Чистая прибыль / введённый средний собственный капитал за год.
A15: ROA | B15: =IF('Вводные'!B20>0,'Модель'!N40/'Вводные'!B20,"") -> 2.2357909 | C15: Чистая прибыль / введённые средние активы за год.
A16: LTV: валовая прибыль | B16: =IF('Вводные'!B21>0,'Вводные'!B21*'Вводные'!B22/100*'Вводные'!B23,"") -> 66300 | C16: Месячная выручка на клиента × валовая маржа × срок жизни. До привлечения, без дисконтирования.
A17: CAC: стоимость нового клиента | B17: =IF(AND(OR('Модель'!N16=0,'Вводные'!B61>0)),IF('Модель'!N23>0,('Модель'!N21+'Вводные'!B24)/'Модель'!N23,""),"") -> 7500 | C17: Маркетинг и прочие затраты на привлечение / новые клиенты воронки. Прочие затраты уже должны быть в расходах.
A18: LTV / CAC, раз | B18: =IF(AND(ISNUMBER(B16),ISNUMBER(B17),B17>0),B16/B17,"") -> 8.84 | C18: Валовая прибыль за жизнь клиента / стоимость привлечения.
A20: Месячная ставка дисконтирования | B20: =(1+'Вводные'!B17/100)^(1/12)-1 -> 0.0094887929 | C20: Эквивалент эффективной годовой ставки.
A23: Сложные проценты: отдельный калькулятор
A24: Месячная ставка накоплений | B24: =(1+'Вводные'!B26/100)^(1/12)-1 -> 0.0094887929 | C24: Эквивалент эффективной годовой ставки.
A25: Будущая сумма | B25: ='Вводные'!B25*(1+B24)^'Вводные'!B27+'Вводные'!B28*IF(B24=0,'Вводные'!B27,((1+B24)^'Вводные'!B27-1)/B24) -> 140492.8 | C25: Начальная сумма с капитализацией плюс пополнения в конце каждого месяца. Не включено в модель бизнеса.
A26: Всего внесено | B26: ='Вводные'!B25+'Вводные'!B28*'Вводные'!B27 -> 100000 | C26: Начальная сумма + все пополнения.
A27: Начислено процентов | B27: =B25-B26 -> 40492.8 | C27: Будущая сумма − внесённые средства.
A30: NPV: https://corporatefinanceinstitute.com/resources/valuation/net-present-value-npv/
A31: IRR: https://corporatefinanceinstitute.com/resources/valuation/internal-rate-return-irr/
A34: Потоки и проверка окупаемости | B34: М0 | C34: М1 | D34: М2 | E34: М3 | F34: М4 | G34: М5 | H34: М6 | I34: М7 | J34: М8 | K34: М9 | L34: М10 | M34: М11 | N34: М12
A35: Свободный денежный поток | B35: =-'Вводные'!B12 -> -3000000 | C35: ='Модель'!B50 -> 825083.33 | D35: ='Модель'!C50 -> 884753.33 | E35: ='Модель'!D50 -> 946810.13 | F35: ='Модель'!E50 -> 1011349.2 | G35: ='Модель'!F50 -> 1078469.8 | H35: ='Модель'!G50 -> 1148275.3 | I35: ='Модель'!H50 -> 1220873 | J35: ='Модель'!I50 -> 1296374.6 | ... N35: ='Модель'!M50 -> 1629813.9
A36: Дисконтированный поток | B36: =B35/(1+$B$20)^0 -> -3000000 | C36: =C35/(1+$B$20)^1 -> 817327.88 | D36: =D35/(1+$B$20)^2 -> 868198.85 | E36: =E35/(1+$B$20)^3 -> 920361.39 | F36: =F35/(1+$B$20)^4 -> 973856.86 | G36: =G35/(1+$B$20)^5 -> 1028727.8 | H36: =H35/(1+$B$20)^6 -> 1085018.2 | I36: =I35/(1+$B$20)^7 -> 1142773 | J36: =J35/(1+$B$20)^8 -> 1202038.8 | K36: =K35/(1+$B$20)^9 -> 1262863.5 | L36: =L35/(1+$B$20)^10 -> 1325296.3 | M36: =M35/(1+$B$20)^11 -> 1389388 | N36: =N35/(1+$B$20)^12 -> 1455191
A37: Поток накопленно | B37: =B35 -> -3000000 | C37: =B37+C35 -> -2174916.7 | D37: =C37+D35 -> -1290163.3 | E37: =D37+E35 -> -343353.2 | F37: =E37+F35 -> 667996.01 | G37: =F37+G35 -> 1746465.8 | H37: =G37+H35 -> 2894741.1 | I37: =H37+I35 -> 4115614.1 | J37: =I37+J35 -> 5411988.7 | ... N37: =M37+N35 -> 11414745
A38: Дисконтированный накопленно | B38: =B36 -> -3000000 | C38: =B38+C36 -> -2182672.1 | D38: =C38+D36 -> -1314473.3 | E38: =D38+E36 -> -394111.89 | F38: =E38+F36 -> 579744.98 | G38: =F38+G36 -> 1608472.8 | H38: =G38+H36 -> 2693491 | I38: =H38+I36 -> 3836264 | J38: =I38+J36 -> 5038302.8 | ... N38: =M38+N36 -> 10471042
A39: Последний ненулевой знак | B39: =SIGN(B35) -> -1 | C39: =IF(C35=0,B39,SIGN(C35)) -> 1 | D39: =IF(D35=0,C39,SIGN(D35)) -> 1 | E39: =IF(E35=0,D39,SIGN(E35)) -> 1 | F39: =IF(F35=0,E39,SIGN(F35)) -> 1 | G39: =IF(G35=0,F39,SIGN(G35)) -> 1 | H39: =IF(H35=0,G39,SIGN(H35)) -> 1 | I39: =IF(I35=0,H39,SIGN(I35)) -> 1 | J39: =IF(J35=0,I39,SIGN(J35)) -> 1 | ... N39: =IF(N35=0,M39,SIGN(N35)) -> 1
A40: Смена знака | B40: =0 -> 0 | C40: =IF(AND(B39<>0,C35<>0,B39<>SIGN(C35)),1,0) -> 1 | D40: =IF(AND(C39<>0,D35<>0,C39<>SIGN(D35)),1,0) -> 0 | E40: =IF(AND(D39<>0,E35<>0,D39<>SIGN(E35)),1,0) -> 0 | F40: =IF(AND(E39<>0,F35<>0,E39<>SIGN(F35)),1,0) -> 0 | G40: =IF(AND(F39<>0,G35<>0,F39<>SIGN(G35)),1,0) -> 0 | H40: =IF(AND(G39<>0,H35<>0,G39<>SIGN(H35)),1,0) -> 0 | I40: =IF(AND(H39<>0,I35<>0,H39<>SIGN(I35)),1,0) -> 0 | J40: =IF(AND(I39<>0,J35<>0,I39<>SIGN(J35)),1,0) -> 0 | ... N40: =IF(AND(M39<>0,N35<>0,M39<>SIGN(N35)),1,0) -> 0
A41: Кандидат срока, 1e9 = нет | B41: =1000000000 -> 1000000000 | C41: =IF(AND(B37<0,C37>=0,C35>0),0-B37/C35,1000000000) -> 1000000000 | D41: =IF(AND(C37<0,D37>=0,D35>0),1-C37/D35,1000000000) -> 1000000000 | E41: =IF(AND(D37<0,E37>=0,E35>0),2-D37/E35,1000000000) -> 1000000000 | F41: =IF(AND(E37<0,F37>=0,F35>0),3-E37/F35,1000000000) -> 3.3395001 | G41: =IF(AND(F37<0,G37>=0,G35>0),4-F37/G35,1000000000) -> 1000000000 | H41: =IF(AND(G37<0,H37>=0,H35>0),5-G37/H35,1000000000) -> 1000000000 | I41: =IF(AND(H37<0,I37>=0,I35>0),6-H37/I35,1000000000) -> 1000000000 | J41: =IF(AND(I37<0,J37>=0,J35>0),7-I37/J35,1000000000) -> 1000000000 | K41: =IF(AND(J37<0,K37>=0,K35>0),8-J37/K35,1000000000) -> 1000000000 | L41: =IF(AND(K37<0,L37>=0,L35>0),9-K37/L35,1000000000) -> 1000000000 | M41: =IF(AND(L37<0,M37>=0,M35>0),10-L37/M35,1000000000) -> 1000000000 | N41: =IF(AND(M37<0,N37>=0,N35>0),11-M37/N35,1000000000) -> 1000000000
A42: Дисконт. кандидат, 1e9 = нет | B42: =1000000000 -> 1000000000 | C42: =IF(AND(B38<0,C38>=0,C36>0),0-B38/C36,1000000000) -> 1000000000 | D42: =IF(AND(C38<0,D38>=0,D36>0),1-C38/D36,1000000000) -> 1000000000 | E42: =IF(AND(D38<0,E38>=0,E36>0),2-D38/E36,1000000000) -> 1000000000 | F42: =IF(AND(E38<0,F38>=0,F36>0),3-E38/F36,1000000000) -> 3.4046918 | G42: =IF(AND(F38<0,G38>=0,G36>0),4-F38/G36,1000000000) -> 1000000000 | H42: =IF(AND(G38<0,H38>=0,H36>0),5-G38/H36,1000000000) -> 1000000000 | I42: =IF(AND(H38<0,I38>=0,I36>0),6-H38/I36,1000000000) -> 1000000000 | J42: =IF(AND(I38<0,J38>=0,J36>0),7-I38/J36,1000000000) -> 1000000000 | K42: =IF(AND(J38<0,K38>=0,K36>0),8-J38/K36,1000000000) -> 1000000000 | L42: =IF(AND(K38<0,L38>=0,L36>0),9-K38/L36,1000000000) -> 1000000000 | M42: =IF(AND(L38<0,M38>=0,M36>0),10-L38/M36,1000000000) -> 1000000000 | N42: =IF(AND(M38<0,N38>=0,N36>0),11-M38/N36,1000000000) -> 1000000000
